Workbook
Name MY_FUNCTION1: _xludf.lambda(((#REF!-#REF!)/#REF!)+1)
Name MY_FUNCTION1: _xludf.lambda(((#REF!-#REF!)/#REF!)+1)

Sheet DC JuntoSep
A1: Sr No | B1: Department | C1: Project Name | D1: Module | E1: Name of Sub Modules | F1: Features-Functionality | G1: CR | H1: Size USP_FP | I1: Hours Consumed | J1: Planned Effort (Person Hours) | K1: Actual Effort (Person Hours) | L1: Planned Start Date (module) | M1: Planned End Date (module) | N1: Actual Start Date (module) | O1: Actual End Date (module) | P1: Requirement Analysis Start Date (module) | Q1: Requirement Analysis End Date (module) | R1: Design Start Date (module) | S1: Design End Date (module) | T1: Coding Start Date (module) | U1: Coding End Date (module) | V1: Testing Start Date (module) | W1: Testing End Date (module) | X1: Requirement Efforts | Y1: Design Actual Efforts | Z1: Coding Actual Effort | AA1: Code Review Actual Effort | AB1: Testing Actual Effort | AC1: Testing Review Efforts | AD1: Requirement Review Efforts | AE1: Design Review Effort | AF1: Requirement Review Defects | AG1: Design Review Defects | AH1: Code Review Defects | AI1: Internal Testing Defects | AJ1: UAT Defects | AK1: Production Defects | AM1: Productivity | AN1: Req_Rate | AO1: Des_Rate | AP1: Code_Rate | AQ1: Test_Rate | AR1: Cycle Time | AS1: Req_CT | AT1: Des_CT | AU1: Code_CT | AV1: Test_CT | AW1: DRE | AX1: Code Review Per Size | AY1: Total Review Defects | AZ1: Internal Testing
A2: 1 | B2: Public Health Engineering Department | C2: Jal Rekha | D2: Anusharavan | E2: RFI New Stages & Reports | F2: 1. Stage Updation 2. NEW Stage changes 3. Testing 4. Report creation/ Modification Ref: US-ANS-C5-001/002/003; Jun-Aug PSR (new stage, stage updation, report modification) | H2: =ROUNDUP(I2/Notes!$B$5,0) -> 12 | I2: 63 | J2: 63 | K2: =I2 -> 63 | L2: 46188 | M2: 46266 | N2: 46188 | O2: 46266 | T2: 46188 | U2: 46266 | V2: 46197 | W2: 46244 | X2: 0 | Y2: 0 | Z2: 56 | AB2: 7 | AM2: =IFERROR(H2/I2,"") -> 0.19047619 | AN2: =IFERROR(H2/(X2+AD2),"") | AO2: =IFERROR(H2/(Y2+AE2),"") | AP2: =IFERROR(H2/(Z2+AA2),"") -> 0.21428571 | AQ2: =IFERROR(H2/(AB2+AC2),"") -> 1.7142857 | AR2: =IF(COUNT(P2:W2)=0,"",(MAX(P2:W2)-MIN(P2:W2))/H2) -> 6.5 | AS2: =IF(COUNT(P2:Q2)=2,(Q2-P2)/H2,"") | AT2: =IF(COUNT(R2:S2)=2,(S2-R2)/H2,"") | AU2: =IF(COUNT(T2:U2)=2,(U2-T2)/H2,"") -> 6.5 | AV2: =IF(COUNT(V2:W2)=2,(W2-V2)/H2,"") -> 3.9166667 | AW2: =IFERROR(AY2/(AY2+AZ2),"") | AX2: =IF(AH2="","",AH2/H2) | AY2: =IF(COUNT(AF2:AH2)=0,"",(AF2+AH2+AG2)/H2) | AZ2: =IF(AI2="","",AI2/H2)
E3: CR - Save as Draft, Survey Fix & Optimisation | F3: 1. Anusharavan Survey Bug fix and optimization 2. FE login - Save as Draft Functionality 3. Internal Testing Ref: US-SEP-24; Sep PSR (survey bug fix and optimisation) | G3: Yes | H3: =ROUNDUP(I3/Notes!$B$5,0) -> 10 | I3: 52 | J3: 52 | K3: =I3 -> 52 | L3: 46191 | M3: 46267 | N3: 46191 | O3: 46267 | T3: 46191 | U3: 46267 | V3: 46253 | W3: 46253 | X3: 0 | Y3: 0 | Z3: 48 | AB3: 4 | AM3: =IFERROR(H3/I3,"") -> 0.19230769 | AN3: =IFERROR(H3/(X3+AD3),"") | AO3: =IFERROR(H3/(Y3+AE3),"") | AP3: =IFERROR(H3/(Z3+AA3),"") -> 0.20833333 | AQ3: =IFERROR(H3/(AB3+AC3),"") -> 2.5 | AR3: =IF(COUNT(P3:W3)=0,"",(MAX(P3:W3)-MIN(P3:W3))/H3) -> 7.6 | AS3: =IF(COUNT(P3:Q3)=2,(Q3-P3)/H3,"") | AT3: =IF(COUNT(R3:S3)=2,(S3-R3)/H3,"") | AU3: =IF(COUNT(T3:U3)=2,(U3-T3)/H3,"") -> 7.6 | AV3: =IF(COUNT(V3:W3)=2,(W3-V3)/H3,"") -> 0 | AW3: =IFERROR(AY3/(AY3+AZ3),"") | AX3: =IF(AH3="","",AH3/H3) | AY3: =IF(COUNT(AF3:AH3)=0,"",(AF3+AH3+AG3)/H3) | AZ3: =IF(AI3="","",AI3/H3)
A4: 2 | B4: Public Health Engineering Department | C4: Jal Rekha | D4: Asset Mapping | E4: Asset Data Map, BISAC / Sujalam Bharat API | F4: 1. Bug Fixing from Frontend 2. API Integration 3. Sujalam Bharat API Mapping & Survey Asset data Ref: US-AST-C5-001/002, US-BISAC-C5-001/002, US-AUG-31/32 | H4: =ROUNDUP(I4/Notes!$B$5,0) -> 9 | I4: 44 | J4: 48 | K4: =I4 -> 44 | L4: 46202 | M4: 46265 | N4: 46202 | O4: 46265 | T4: 46202 | U4: 46265 | X4: 0 | Y4: 0 | Z4: 44 | AB4: 0 | AM4: =IFERROR(H4/I4,"") -> 0.20454545 | AN4: =IFERROR(H4/(X4+AD4),"") | AO4: =IFERROR(H4/(Y4+AE4),"") | AP4: =IFERROR(H4/(Z4+AA4),"") -> 0.20454545 | AQ4: =IFERROR(H4/(AB4+AC4),"") | AR4: =IF(COUNT(P4:W4)=0,"",(MAX(P4:W4)-MIN(P4:W4))/H4) -> 7 | AS4: =IF(COUNT(P4:Q4)=2,(Q4-P4)/H4,"") | AT4: =IF(COUNT(R4:S4)=2,(S4-R4)/H4,"") | AU4: =IF(COUNT(T4:U4)=2,(U4-T4)/H4,"") -> 7 | AV4: =IF(COUNT(V4:W4)=2,(W4-V4)/H4,"") | AW4: =IFERROR(AY4/(AY4+AZ4),"") | AX4: =IF(AH4="","",AH4/H4) | AY4: =IF(COUNT(AF4:AH4)=0,"",(AF4+AH4+AG4)/H4) | AZ4: =IF(AI4="","",AI4/H4)
A5: 3 | B5: Public Health Engineering Department | C5: Jal Rekha | D5: Bharosa CR | E5: Factory Testing Web | F5: 1. Bug Fixing from Frontend Ref: US-BHR-C5-001; Jul MoM (item master duplicate fix) | H5: =ROUNDUP(I5/Notes!$B$5,0) -> 1 | I5: 3 | J5: 3 | K5: =I5 -> 3 | L5: 46232 | M5: 46232 | N5: 46232 | O5: 46232 | T5: 46232 | U5: 46232 | X5: 0 | Y5: 0 | Z5: 3 | AB5: 0 | AM5: =IFERROR(H5/I5,"") -> 0.33333333 | AN5: =IFERROR(H5/(X5+AD5),"") | AO5: =IFERROR(H5/(Y5+AE5),"") | AP5: =IFERROR(H5/(Z5+AA5),"") -> 0.33333333 | AQ5: =IFERROR(H5/(AB5+AC5),"") | AR5: =IF(COUNT(P5:W5)=0,"",(MAX(P5:W5)-MIN(P5:W5))/H5) -> 0 | AS5: =IF(COUNT(P5:Q5)=2,(Q5-P5)/H5,"") | AT5: =IF(COUNT(R5:S5)=2,(S5-R5)/H5,"") | AU5: =IF(COUNT(T5:U5)=2,(U5-T5)/H5,"") -> 0 | AV5: =IF(COUNT(V5:W5)=2,(W5-V5)/H5,"") | AW5: =IFERROR(AY5/(AY5+AZ5),"") | AX5: =IF(AH5="","",AH5/H5) | AY5: =IF(COUNT(AF5:AH5)=0,"",(AF5+AH5+AG5)/H5) | AZ5: =IF(AI5="","",AI5/H5)
E6: CR - Factory Testing Mobile | F6: 1. Internal Testing Ref: US-BHR-C5-002; Jul MoM (factory testing mobile bug fixes) | G6: Yes | H6: =ROUNDUP(I6/Notes!$B$5,0) -> 1 | I6: 4 | J6: 4 | K6: =I6 -> 4 | L6: 46231 | M6: 46231 | N6: 46231 | O6: 46231 | V6: 46231 | W6: 46231 | X6: 0 | Y6: 0 | Z6: 0 | AB6: 4 | AM6: =IFERROR(H6/I6,"") -> 0.25 | AN6: =IFERROR(H6/(X6+AD6),"") | AO6: =IFERROR(H6/(Y6+AE6),"") | AP6: =IFERROR(H6/(Z6+AA6),"") | AQ6: =IFERROR(H6/(AB6+AC6),"") -> 0.25 | AR6: =IF(COUNT(P6:W6)=0,"",(MAX(P6:W6)-MIN(P6:W6))/H6) -> 0 | AS6: =IF(COUNT(P6:Q6)=2,(Q6-P6)/H6,"") | AT6: =IF(COUNT(R6:S6)=2,(S6-R6)/H6,"") | AU6: =IF(COUNT(T6:U6)=2,(U6-T6)/H6,"") | AV6: =IF(COUNT(V6:W6)=2,(W6-V6)/H6,"") -> 0 | AW6: =IFERROR(AY6/(AY6+AZ6),"") | AX6: =IF(AH6="","",AH6/H6) | AY6: =IF(COUNT(AF6:AH6)=0,"",(AF6+AH6+AG6)/H6) | AZ6: =IF(AI6="","",AI6/H6)
A7: 4 | B7: Public Health Engineering Department | C7: Jal Rekha | D7: Cube Testing | E7: Contractor Login | F7: 1. Prod/CR/UAT Testing (Including prod issue validation) 2. Creation of Cube Inspection by Contractor 3. Internal Testing Ref: US-CUBE-C5-001/002/003; Jun-Jul MoM | H7: =ROUNDUP(I7/Notes!$B$5,0) -> 10 | I7: 52 | J7: 52 | K7: =I7 -> 52 | L7: 46184 | M7: 46294 | N7: 46184 | O7: 46294 | T7: 46184 | U7: 46203 | V7: 46216 | W7: 46294 | X7: 0 | Y7: 0 | Z7: 24 | AB7: 28 | AM7: =IFERROR(H7/I7,"") -> 0.19230769 | AN7: =IFERROR(H7/(X7+AD7),"") | AO7: =IFERROR(H7/(Y7+AE7),"") | AP7: =IFERROR(H7/(Z7+AA7),"") -> 0.41666667 | AQ7: =IFERROR(H7/(AB7+AC7),"") -> 0.35714286 | AR7: =IF(COUNT(P7:W7)=0,"",(MAX(P7:W7)-MIN(P7:W7))/H7) -> 11 | AS7: =IF(COUNT(P7:Q7)=2,(Q7-P7)/H7,"") | AT7: =IF(COUNT(R7:S7)=2,(S7-R7)/H7,"") | AU7: =IF(COUNT(T7:U7)=2,(U7-T7)/H7,"") -> 1.9 | AV7: =IF(COUNT(V7:W7)=2,(W7-V7)/H7,"") -> 7.8 | AW7: =IFERROR(AY7/(AY7+AZ7),"") | AX7: =IF(AH7="","",AH7/H7) | AY7: =IF(COUNT(AF7:AH7)=0,"",(AF7+AH7+AG7)/H7) | AZ7: =IF(AI7="","",AI7/H7)
E8: FE Login | F8: 1. Internal Testing 2. Cube inspection carried out by FE 3. Prod/CR/UAT Testing (Including prod issue validation) 4. Save as Draft functionality for FE Login 5. Test Case and Test Scenario Creation Ref: US-CUBE-C5-004; Jul PSR (FE re-inspection, loop testing) | H8: =ROUNDUP(I8/Notes!$B$5,0) -> 13 | I8: 68 | J8: 68 | K8: =I8 -> 68 | L8: 46182 | M8: 46248 | N8: 46182 | O8: 46251 | T8: 46182 | U8: 46213 | V8: 46210 | W8: 46251 | X8: 0 | Y8: 0 | Z8: 40 | AB8: 28 | AM8: =IFERROR(H8/I8,"") -> 0.19117647 | AN8: =IFERROR(H8/(X8+AD8),"") | AO8: =IFERROR(H8/(Y8+AE8),"") | AP8: =IFERROR(H8/(Z8+AA8),"") -> 0.325 | AQ8: =IFERROR(H8/(AB8+AC8),"") -> 0.46428571 | AR8: =IF(COUNT(P8:W8)=0,"",(MAX(P8:W8)-MIN(P8:W8))/H8) -> 5.3076923 | AS8: =IF(COUNT(P8:Q8)=2,(Q8-P8)/H8,"") | AT8: =IF(COUNT(R8:S8)=2,(S8-R8)/H8,"") | AU8: =IF(COUNT(T8:U8)=2,(U8-T8)/H8,"") -> 2.3846154 | AV8: =IF(COUNT(V8:W8)=2,(W8-V8)/H8,"") -> 3.1538462 | AW8: =IFERROR(AY8/(AY8+AZ8),"") | AX8: =IF(AH8="","",AH8/H8) | AY8: =IF(COUNT(AF8:AH8)=0,"",(AF8+AH8+AG8)/H8) | AZ8: =IF(AI8="","",AI8/H8)
E9: GM - SQC - TPIA | F9: 1. Prod/CR/UAT Testing (Including prod issue validation) 2. Bug Fixing from Frontend Ref: US-CUBE-C5-001; Jun/Jul PSR (GM login rejected-RFI, prod validation) | H9: =ROUNDUP(I9/Notes!$B$5,0) -> 6 | I9: 30 | J9: 30 | K9: =I9 -> 30 | L9: 46175 | M9: 46204 | N9: 46175 | O9: 46204 | T9: 46175 | U9: 46204 | V9: 46184 | W9: 46203 | X9: 0 | Y9: 0 | Z9: 12 | AB9: 18 | AM9: =IFERROR(H9/I9,"") -> 0.2 | AN9: =IFERROR(H9/(X9+AD9),"") | AO9: =IFERROR(H9/(Y9+AE9),"") | AP9: =IFERROR(H9/(Z9+AA9),"") -> 0.5 | AQ9: =IFERROR(H9/(AB9+AC9),"") -> 0.33333333 | AR9: =IF(COUNT(P9:W9)=0,"",(MAX(P9:W9)-MIN(P9:W9))/H9) -> 4.8333333 | AS9: =IF(COUNT(P9:Q9)=2,(Q9-P9)/H9,"") | AT9: =IF(COUNT(R9:S9)=2,(S9-R9)/H9,"") | AU9: =IF(COUNT(T9:U9)=2,(U9-T9)/H9,"") -> 4.8333333 | AV9: =IF(COUNT(V9:W9)=2,(W9-V9)/H9,"") -> 3.1666667 | AW9: =IFERROR(AY9/(AY9+AZ9),"") | AX9: =IF(AH9="","",AH9/H9) | AY9: =IF(COUNT(AF9:AH9)=0,"",(AF9+AH9+AG9)/H9) | AZ9: =IF(AI9="","",AI9/H9)
E10: CR - Re-Inspection Loop, RFI Details & New Stages | F10: 1. Mandatory Mulitple Image Upload functionality 2. Complete Loop run again till FE (Cube Testing Approval) 3. New Stage Changes - Mobile App, DB, API & Web level 4. New Feature creation & Modification - RFI details Updation with UI Change 5. UAT/Prod/CR-- Validation including bugs Ref: US-CUBE-C5-004/005, US-SEP-20/21; Jul-Sep PSR | G10: Yes | H10: =ROUNDUP(I10/Notes!$B$5,0) -> 50 | I10: 261 | J10: 262 | K10: =I10 -> 261 | L10: 46188 | M10: 46293 | N10: 46188 | O10: 46293 | T10: 46188 | U10: 46275 | V10: 46210 | W10: 46293 | X10: 0 | Y10: 0 | Z10: 129 | AB10: 132 | AM10: =IFERROR(H10/I10,"") -> 0.19157088 | AN10: =IFERROR(H10/(X10+AD10),"") | AO10: =IFERROR(H10/(Y10+AE10),"") | AP10: =IFERROR(H10/(Z10+AA10),"") -> 0.3875969 | AQ10: =IFERROR(H10/(AB10+AC10),"") -> 0.37878788 | AR10: =IF(COUNT(P10:W10)=0,"",(MAX(P10:W10)-MIN(P10:W10))/H10) -> 2.1 | AS10: =IF(COUNT(P10:Q10)=2,(Q10-P10)/H10,"") | AT10: =IF(COUNT(R10:S10)=2,(S10-R10)/H10,"") | AU10: =IF(COUNT(T10:U10)=2,(U10-T10)/H10,"") -> 1.74 | AV10: =IF(COUNT(V10:W10)=2,(W10-V10)/H10,"") -> 1.66 | AW10: =IFERROR(AY10/(AY10+AZ10),"") | AX10: =IF(AH10="","",AH10/H10) | AY10: =IF(COUNT(AF10:AH10)=0,"",(AF10+AH10+AG10)/H10) | AZ10: =IF(AI10="","",AI10/H10)
E11: Requirement - Web Pages & Queries | F11: 1. New web page creation/ Modification 2. Query/SP creation/Modification Ref: Jul PSR (rejected RFI re-inspection, UI update) | H11: =ROUNDUP(I11/Notes!$B$5,0) -> 5 | I11: 24 | J11: 24 | K11: =I11 -> 24 | L11: 46209 | M11: 46219 | N11: 46209 | O11: 46219 | T11: 46209 | U11: 46219 | X11: 0 | Y11: 0 | Z11: 24 | AB11: 0 | AM11: =IFERROR(H11/I11,"") -> 0.20833333 | AN11: =IFERROR(H11/(X11+AD11),"") | AO11: =IFERROR(H11/(Y11+AE11),"") | AP11: =IFERROR(H11/(Z11+AA11),"") -> 0.20833333 | AQ11: =IFERROR(H11/(AB11+AC11),"") | AR11: =IF(COUNT(P11:W11)=0,"",(MAX(P11:W11)-MIN(P11:W11))/H11) -> 2 | AS11: =IF(COUNT(P11:Q11)=2,(Q11-P11)/H11,"") | AT11: =IF(COUNT(R11:S11)=2,(S11-R11)/H11,"") | AU11: =IF(COUNT(T11:U11)=2,(U11-T11)/H11,"") -> 2 | AV11: =IF(COUNT(V11:W11)=2,(W11-V11)/H11,"") | AW11: =IFERROR(AY11/(AY11+AZ11),"") | AX11: =IF(AH11="","",AH11/H11) | AY11: =IF(COUNT(AF11:AH11)=0,"",(AF11+AH11+AG11)/H11) | AZ11: =IF(AI11="","",AI11/H11)
A12: 5 | B12: Public Health Engineering Department | C12: Jal Rekha | D12: Dhara | E12: Dhara - Reports, UI & Bug Fixes | F12: 1. UI update in existing page 2. Bug fixing from Dhara Report 3. UAT/Prod/CR Testing 4. New web page creation/ Modification Ref: US-DHR-C5-001/002/004/006; US-SEP-15/16 | H12: =ROUNDUP(I12/Notes!$B$5,0) -> 18 | I12: 94 | J12: 94 | K12: =I12 -> 94 | L12: 46174 | M12: 46289 | N12: 46174 | O12: 46289 | T12: 46174 | U12: 46289 | V12: 46281 | W12: 46283 | X12: 0 | Y12: 0 | Z12: 88 | AB12: 6 | AM12: =IFERROR(H12/I12,"") -> 0.19148936 | AN12: =IFERROR(H12/(X12+AD12),"") | AO12: =IFERROR(H12/(Y12+AE12),"") | AP12: =IFERROR(H12/(Z12+AA12),"") -> 0.20454545 | AQ12: =IFERROR(H12/(AB12+AC12),"") -> 3 | AR12: =IF(COUNT(P12:W12)=0,"",(MAX(P12:W12)-MIN(P12:W12))/H12) -> 6.3888889 | AS12: =IF(COUNT(P12:Q12)=2,(Q12-P12)/H12,"") | AT12: =IF(COUNT(R12:S12)=2,(S12-R12)/H12,"") | AU12: =IF(COUNT(T12:U12)=2,(U12-T12)/H12,"") -> 6.3888889 | AV12: =IF(COUNT(V12:W12)=2,(W12-V12)/H12,"") -> 0.11111111 | AW12: =IFERROR(AY12/(AY12+AZ12),"") | AX12: =IF(AH12="","",AH12/H12) | AY12: =IF(COUNT(AF12:AH12)=0,"",(AF12+AH12+AG12)/H12) | AZ12: =IF(AI12="","",AI12/H12)
E13: Dhara CR - Reports (MWSR, DWSR, UFW) | F13: 1. Updation and recreate fetch - DWSR, MWSR, Bulk Consumer, Approved Reports, and UFW Ref: US-DHR-C5-001/002/007; Jun-Jul PSR | G13: Yes | H13: =ROUNDUP(I13/Notes!$B$5,0) -> 7 | I13: 32 | J13: 32 | K13: =I13 -> 32 | L13: 46183 | M13: 46205 | N13: 46183 | O13: 46205 | T13: 46183 | U13: 46205 | X13: 0 | Y13: 0 | Z13: 32 | AB13: 0 | AM13: =IFERROR(H13/I13,"") -> 0.21875 | AN13: =IFERROR(H13/(X13+AD13),"") | AO13: =IFERROR(H13/(Y13+AE13),"") | AP13: =IFERROR(H13/(Z13+AA13),"") -> 0.21875 | AQ13: =IFERROR(H13/(AB13+AC13),"") | AR13: =IF(COUNT(P13:W13)=0,"",(MAX(P13:W13)-MIN(P13:W13))/H13) -> 3.1428571 | AS13: =IF(COUNT(P13:Q13)=2,(Q13-P13)/H13,"") | AT13: =IF(COUNT(R13:S13)=2,(S13-R13)/H13,"") | AU13: =IF(COUNT(T13:U13)=2,(U13-T13)/H13,"") -> 3.1428571 | AV13: =IF(COUNT(V13:W13)=2,(W13-V13)/H13,"") | AW13: =IFERROR(AY13/(AY13+AZ13),"") | AX13: =IF(AH13="","",AH13/H13) | AY13: =IF(COUNT(AF13:AH13)=0,"",(AF13+AH13+AG13)/H13) | AZ13: =IF(AI13="","",AI13/H13)
E14: Dhara Change Request - GM PIU User/TL | F14: 1. Meter reading survey for intake, wtp, oht, bulk both for web & mobile view 2. Dhara - Habitation Updation Ref: US-SEP-16/17; Sep PSR (meter reading survey, 16-Sep working session) | G14: Yes | H14: =ROUNDUP(I14/Notes!$B$5,0) -> 12 | I14: 63 | J14: 64 | K14: =I14 -> 63 | L14: 46178 | M14: 46283 | N14: 46178 | O14: 46286 | T14: 46178 | U14: 46286 | X14: 0 | Y14: 0 | Z14: 63 | AB14: 0 | AM14: =IFERROR(H14/I14,"") -> 0.19047619 | AN14: =IFERROR(H14/(X14+AD14),"") | AO14: =IFERROR(H14/(Y14+AE14),"") | AP14: =IFERROR(H14/(Z14+AA14),"") -> 0.19047619 | AQ14: =IFERROR(H14/(AB14+AC14),"") | AR14: =IF(COUNT(P14:W14)=0,"",(MAX(P14:W14)-MIN(P14:W14))/H14) -> 9 | AS14: =IF(COUNT(P14:Q14)=2,(Q14-P14)/H14,"") | AT14: =IF(COUNT(R14:S14)=2,(S14-R14)/H14,"") | AU14: =IF(COUNT(T14:U14)=2,(U14-T14)/H14,"") -> 9 | AV14: =IF(COUNT(V14:W14)=2,(W14-V14)/H14,"") | AW14: =IFERROR(AY14/(AY14+AZ14),"") | AX14: =IF(AH14="","",AH14/H14) | AY14: =IF(COUNT(AF14:AH14)=0,"",(AF14+AH14+AG14)/H14) | AZ14: =IF(AI14="","",AI14/H14)
A15: 6 | B15: Public Health Engineering Department | C15: Jal Rekha | D15: Dashboard | E15: Dashboard Redesign & Public Reports | F15: 1. Wireframing 2. BUg Fixing / Modification of Public DWSR 3. Requirement Gathering 4. CR/Prod/UAT Bug testing Ref: Jul PSR (dashboard redesign, public reports); Sep PSR (login/forgot-password UI) | H15: =ROUNDUP(I15/Notes!$B$5,0) -> 12 | I15: 58 | J15: 58 | K15: =I15 -> 58 | L15: 46206 | M15: 46286 | N15: 46206 | O15: 46286 | P15: 46283 | Q15: 46286 | R15: 46206 | S15: 46209 | T15: 46225 | U15: 46231 | V15: 46219 | W15: 46219 | X15: 16 | Y15: 16 | Z15: 22 | AB15: 4 | AM15: =IFERROR(H15/I15,"") -> 0.20689655 | AN15: =IFERROR(H15/(X15+AD15),"") -> 0.75 | AO15: =IFERROR(H15/(Y15+AE15),"") -> 0.75 | AP15: =IFERROR(H15/(Z15+AA15),"") -> 0.54545455 | AQ15: =IFERROR(H15/(AB15+AC15),"") -> 3 | AR15: =IF(COUNT(P15:W15)=0,"",(MAX(P15:W15)-MIN(P15:W15))/H15) -> 6.6666667 | AS15: =IF(COUNT(P15:Q15)=2,(Q15-P15)/H15,"") -> 0.25 | AT15: =IF(COUNT(R15:S15)=2,(S15-R15)/H15,"") -> 0.25 | AU15: =IF(COUNT(T15:U15)=2,(U15-T15)/H15,"") -> 0.5 | AV15: =IF(COUNT(V15:W15)=2,(W15-V15)/H15,"") -> 0 | AW15: =IFERROR(AY15/(AY15+AZ15),"") | AX15: =IF(AH15="","",AH15/H15) | AY15: =IF(COUNT(AF15:AH15)=0,"",(AF15+AH15+AG15)/H15) | AZ15: =IF(AI15="","",AI15/H15)
A16: 7 | B16: Public Health Engineering Department | C16: Jal Rekha | D16: FHTC | E16: Change Request FHTC - Loop, Reports & API | F16: 1. FHTC Loop functionality implementation 2. Database functions to be Implemented & modified 3. Report Filter issues at column level 4. API Service and External API Functionality updations 5. Customized and Summary report changes Ref: US-FHTC-C5-001/004/005; Jul MoM (Samagra multi-survey) | G16: Yes | H16: =ROUNDUP(I16/Notes!$B$5,0) -> 33 | I16: 169 | J16: 169 | K16: =I16 -> 169 | L16: 46203 | M16: 46287 | N16: 46203 | O16: 46287 | T16: 46203 | U16: 46287 | X16: 0 | Y16: 0 | Z16: 169 | AB16: 0 | AM16: =IFERROR(H16/I16,"") -> 0.19526627 | AN16: =IFERROR(H16/(X16+AD16),"") | AO16: =IFERROR(H16/(Y16+AE16),"") | AP16: =IFERROR(H16/(Z16+AA16),"") -> 0.19526627 | AQ16: =IFERROR(H16/(AB16+AC16),"") | AR16: =IF(COUNT(P16:W16)=0,"",(MAX(P16:W16)-MIN(P16:W16))/H16) -> 2.5454545 | AS16: =IF(COUNT(P16:Q16)=2,(Q16-P16)/H16,"") | AT16: =IF(COUNT(R16:S16)=2,(S16-R16)/H16,"") | AU16: =IF(COUNT(T16:U16)=2,(U16-T16)/H16,"") -> 2.5454545 | AV16: =IF(COUNT(V16:W16)=2,(W16-V16)/H16,"") | AW16: =IFERROR(AY16/(AY16+AZ16),"") | AX16: =IF(AH16="","",AH16/H16) | AY16: =IF(COUNT(AF16:AH16)=0,"",(AF16+AH16+AG16)/H16) | AZ16: =IF(AI16="","",AI16/H16)
E17: FE Reports - Bug Fixing, Pages & Test Cases | F17: 1. Query/SP creation/Modification 2. Test Case Creation 3. Bug Fixing from Frontend or Database end 4. New web page creation/ Modification Ref: US-FHTC-C5-002/003; Jul-Aug PSR | H17: =ROUNDUP(I17/Notes!$B$5,0) -> 9 | I17: 44 | J17: 44 | K17: =I17 -> 44 | L17: 46225 | M17: 46295 | N17: 46225 | O17: 46295 | T17: 46225 | U17: 46295 | V17: 46265 | W17: 46265 | X17: 0 | Y17: 0 | Z17: 40 | AB17: 4 | AM17: =IFERROR(H17/I17,"") -> 0.20454545 | AN17: =IFERROR(H17/(X17+AD17),"") | AO17: =IFERROR(H17/(Y17+AE17),"") | AP17: =IFERROR(H17/(Z17+AA17),"") -> 0.225 | AQ17: =IFERROR(H17/(AB17+AC17),"") -> 2.25 | AR17: =IF(COUNT(P17:W17)=0,"",(MAX(P17:W17)-MIN(P17:W17))/H17) -> 7.7777778 | AS17: =IF(COUNT(P17:Q17)=2,(Q17-P17)/H17,"") | AT17: =IF(COUNT(R17:S17)=2,(S17-R17)/H17,"") | AU17: =IF(COUNT(T17:U17)=2,(U17-T17)/H17,"") -> 7.7777778 | AV17: =IF(COUNT(V17:W17)=2,(W17-V17)/H17,"") -> 0 | AW17: =IFERROR(AY17/(AY17+AZ17),"") | AX17: =IF(AH17="","",AH17/H17) | AY17: =IF(COUNT(AF17:AH17)=0,"",(AF17+AH17+AG17)/H17) | AZ17: =IF(AI17="","",AI17/H17)
E18: Parinam Enhancements - Dashboard | F18: 1. Parinam Dashboard Ref: US-AUG-27, US-SEP-26 | H18: =ROUNDUP(I18/Notes!$B$5,0) -> 3 | I18: 12 | J18: 12 | K18: =I18 -> 12 | L18: 46254 | M18: 46283 | N18: 46260 | O18: 46283 | T18: 46260 | U18: 46283 | X18: 0 | Y18: 0 | Z18: 12 | AB18: 0 | AM18: =IFERROR(H18/I18,"") -> 0.25 | AN18: =IFERROR(H18/(X18+AD18),"") | AO18: =IFERROR(H18/(Y18+AE18),"") | AP18: =IFERROR(H18/(Z18+AA18),"") -> 0.25 | AQ18: =IFERROR(H18/(AB18+AC18),"") | AR18: =IF(COUNT(P18:W18)=0,"",(MAX(P18:W18)-MIN(P18:W18))/H18) -> 7.6666667 | AS18: =IF(COUNT(P18:Q18)=2,(Q18-P18)/H18,"") | AT18: =IF(COUNT(R18:S18)=2,(S18-R18)/H18,"") | AU18: =IF(COUNT(T18:U18)=2,(U18-T18)/H18,"") -> 7.6666667 | AV18: =IF(COUNT(V18:W18)=2,(W18-V18)/H18,"") | AW18: =IFERROR(AY18/(AY18+AZ18),"") | AX18: =IF(AH18="","",AH18/H18) | AY18: =IF(COUNT(AF18:AH18)=0,"",(AF18+AH18+AG18)/H18) | AZ18: =IF(AI18="","",AI18/H18)
A19: 8 | B19: Public Health Engineering Department | C19: Jal Rekha | D19: Master | E19: Change Request - Mapping & Reports | F19: 1. Dhara Mapped Summary report - Changes in Abstract report 2. Scheme Village OHT Mapping & Report Updations Ref: US-VST-C5-001..005, US-MSTR-C5-001/002/003 | G19: Yes | H19: =ROUNDUP(I19/Notes!$B$5,0) -> 5 | I19: 24 | J19: 24 | K19: =I19 -> 24 | L19: 46182 | M19: 46283 | N19: 46182 | O19: 46283 | T19: 46182 | U19: 46283 | X19: 0 | Y19: 0 | Z19: 24 | AB19: 0 | AM19: =IFERROR(H19/I19,"") -> 0.20833333 | AN19: =IFERROR(H19/(X19+AD19),"") | AO19: =IFERROR(H19/(Y19+AE19),"") | AP19: =IFERROR(H19/(Z19+AA19),"") -> 0.20833333 | AQ19: =IFERROR(H19/(AB19+AC19),"") | AR19: =IF(COUNT(P19:W19)=0,"",(MAX(P19:W19)-MIN(P19:W19))/H19) -> 20.2 | AS19: =IF(COUNT(P19:Q19)=2,(Q19-P19)/H19,"") | AT19: =IF(COUNT(R19:S19)=2,(S19-R19)/H19,"") | AU19: =IF(COUNT(T19:U19)=2,(U19-T19)/H19,"") -> 20.2 | AV19: =IF(COUNT(V19:W19)=2,(W19-V19)/H19,"") | AW19: =IFERROR(AY19/(AY19+AZ19),"") | AX19: =IF(AH19="","",AH19/H19) | AY19: =IF(COUNT(AF19:AH19)=0,"",(AF19+AH19+AG19)/H19) | AZ19: =IF(AI19="","",AI19/H19)
E20: Survey Intake / WTP / OHT Master | F20: 1. Survey data of Intake Master 2. Survey data of OHT Master 3. Survey data of WTP Master Ref: US-SEP-25; Sep PSR (delivered 16-Sep working session) | H20: =ROUNDUP(I20/Notes!$B$5,0) -> 7 | I20: 32 | J20: 32 | K20: =I20 -> 32 | L20: 46286 | M20: 46289 | N20: 46286 | O20: 46289 | T20: 46286 | U20: 46289 | X20: 0 | Y20: 0 | Z20: 32 | AB20: 0 | AM20: =IFERROR(H20/I20,"") -> 0.21875 | AN20: =IFERROR(H20/(X20+AD20),"") | AO20: =IFERROR(H20/(Y20+AE20),"") | AP20: =IFERROR(H20/(Z20+AA20),"") -> 0.21875 | AQ20: =IFERROR(H20/(AB20+AC20),"") | AR20: =IF(COUNT(P20:W20)=0,"",(MAX(P20:W20)-MIN(P20:W20))/H20) -> 0.42857143 | AS20: =IF(COUNT(P20:Q20)=2,(Q20-P20)/H20,"") | AT20: =IF(COUNT(R20:S20)=2,(S20-R20)/H20,"") | AU20: =IF(COUNT(T20:U20)=2,(U20-T20)/H20,"") -> 0.42857143 | AV20: =IF(COUNT(V20:W20)=2,(W20-V20)/H20,"") | AW20: =IFERROR(AY20/(AY20+AZ20),"") | AX20: =IF(AH20="","",AH20/H20) | AY20: =IF(COUNT(AF20:AH20)=0,"",(AF20+AH20+AG20)/H20) | AZ20: =IF(AI20="","",AI20/H20)
A21: 9 | B21: Public Health Engineering Department | C21: Jal Rekha | D21: Material Testing | E21: FE Login | F21: 1. UAT/Prod/CR Testing Ref: Aug PSR (UAT/prod checks) | H21: =ROUNDUP(I21/Notes!$B$5,0) -> 1 | I21: 1 | J21: 1 | K21: =I21 -> 1 | L21: 46240 | M21: 46240 | N21: 46240 | O21: 46240 | V21: 46240 | W21: 46240 | X21: 0 | Y21: 0 | Z21: 0 | AB21: 1 | AM21: =IFERROR(H21/I21,"") -> 1 | AN21: =IFERROR(H21/(X21+AD21),"") | AO21: =IFERROR(H21/(Y21+AE21),"") | AP21: =IFERROR(H21/(Z21+AA21),"") | AQ21: =IFERROR(H21/(AB21+AC21),"") -> 1 | AR21: =IF(COUNT(P21:W21)=0,"",(MAX(P21:W21)-MIN(P21:W21))/H21) -> 0 | AS21: =IF(COUNT(P21:Q21)=2,(Q21-P21)/H21,"") | AT21: =IF(COUNT(R21:S21)=2,(S21-R21)/H21,"") | AU21: =IF(COUNT(T21:U21)=2,(U21-T21)/H21,"") | AV21: =IF(COUNT(V21:W21)=2,(W21-V21)/H21,"") -> 0 | AW21: =IFERROR(AY21/(AY21+AZ21),"") | AX21: =IF(AH21="","",AH21/H21) | AY21: =IF(COUNT(AF21:AH21)=0,"",(AF21+AH21+AG21)/H21) | AZ21: =IF(AI21="","",AI21/H21)
E22: GM / Contractor Login | F22: 1. Bug Fixing from Frontend 2. Business Logic APIs creation/Changes 3. Requirement Gathering Ref: US-MAT-C5-003; Jun-Jul PSR | H22: =ROUNDUP(I22/Notes!$B$5,0) -> 5 | I22: 25 | J22: 25 | K22: =I22 -> 25 | L22: 46185 | M22: 46218 | N22: 46185 | O22: 46218 | P22: 46217 | Q22: 46217 | T22: 46185 | U22: 46218 | X22: 4 | Y22: 0 | Z22: 21 | AB22: 0 | AM22: =IFERROR(H22/I22,"") -> 0.2 | AN22: =IFERROR(H22/(X22+AD22),"") -> 1.25 | AO22: =IFERROR(H22/(Y22+AE22),"") | AP22: =IFERROR(H22/(Z22+AA22),"") -> 0.23809524 | AQ22: =IFERROR(H22/(AB22+AC22),"") | AR22: =IF(COUNT(P22:W22)=0,"",(MAX(P22:W22)-MIN(P22:W22))/H22) -> 6.6 | AS22: =IF(COUNT(P22:Q22)=2,(Q22-P22)/H22,"") -> 0 | AT22: =IF(COUNT(R22:S22)=2,(S22-R22)/H22,"") | AU22: =IF(COUNT(T22:U22)=2,(U22-T22)/H22,"") -> 6.6 | AV22: =IF(COUNT(V22:W22)=2,(W22-V22)/H22,"") | AW22: =IFERROR(AY22/(AY22+AZ22),"") | AX22: =IF(AH22="","",AH22/H22) | AY22: =IF(COUNT(AF22:AH22)=0,"",(AF22+AH22+AG22)/H22) | AZ22: =IF(AI22="","",AI22/H22)
E23: CR - Re-Inspection Loop, DB/API & New Stages | F23: 1. Database functions Updation & API Web and Mobile Services 2. Loop Functionality 3. Test Case/Scenario Creation 4. New Stage Changes - Mobile App, DB, API & Web level Ref: US-MAT-C5-001/002/003, US-AUG-25, US-SEP-22 | G23: Yes | H23: =ROUNDUP(I23/Notes!$B$5,0) -> 42 | I23: 221 | J23: 223 | K23: =I23 -> 221 | L23: 46218 | M23: 46288 | N23: 46218 | O23: 46288 | T23: 46218 | U23: 46288 | V23: 46247 | W23: 46248 | X23: 0 | Y23: 0 | Z23: 213 | AB23: 8 | AM23: =IFERROR(H23/I23,"") -> 0.19004525 | AN23: =IFERROR(H23/(X23+AD23),"") | AO23: =IFERROR(H23/(Y23+AE23),"") | AP23: =IFERROR(H23/(Z23+AA23),"") -> 0.1971831 | AQ23: =IFERROR(H23/(AB23+AC23),"") -> 5.25 | AR23: =IF(COUNT(P23:W23)=0,"",(MAX(P23:W23)-MIN(P23:W23))/H23) -> 1.6666667 | AS23: =IF(COUNT(P23:Q23)=2,(Q23-P23)/H23,"") | AT23: =IF(COUNT(R23:S23)=2,(S23-R23)/H23,"") | AU23: =IF(COUNT(T23:U23)=2,(U23-T23)/H23,"") -> 1.6666667 | AV23: =IF(COUNT(V23:W23)=2,(W23-V23)/H23,"") -> 0.023809524 | AW23: =IFERROR(AY23/(AY23+AZ23),"") | AX23: =IF(AH23="","",AH23/H23) | AY23: =IF(COUNT(AF23:AH23)=0,"",(AF23+AH23+AG23)/H23) | AZ23: =IF(AI23="","",AI23/H23)
A24: 10 | B24: Public Health Engineering Department | C24: Jal Rekha | D24: Nirmal | E24: CR - Reports (Beneficiary, WTP, OHT) | F24: 1. Report Issue 2. Production Bug Fix 3. Test Scenario and Test Case Creation 4. Nirmal Issues of reading Ref: US-NRM-C5-001/002/004 | G24: Yes | H24: =ROUNDUP(I24/Notes!$B$5,0) -> 10 | I24: 48 | J24: 48 | K24: =I24 -> 48 | L24: 46192 | M24: 46259 | N24: 46192 | O24: 46259 | T24: 46192 | U24: 46259 | V24: 46192 | W24: 46192 | X24: 0 | Y24: 0 | Z24: 43 | AB24: 5 | AM24: =IFERROR(H24/I24,"") -> 0.20833333 | AN24: =IFERROR(H24/(X24+AD24),"") | AO24: =IFERROR(H24/(Y24+AE24),"") | AP24: =IFERROR(H24/(Z24+AA24),"") -> 0.23255814 | AQ24: =IFERROR(H24/(AB24+AC24),"") -> 2 | AR24: =IF(COUNT(P24:W24)=0,"",(MAX(P24:W24)-MIN(P24:W24))/H24) -> 6.7 | AS24: =IF(COUNT(P24:Q24)=2,(Q24-P24)/H24,"") | AT24: =IF(COUNT(R24:S24)=2,(S24-R24)/H24,"") | AU24: =IF(COUNT(T24:U24)=2,(U24-T24)/H24,"") -> 6.7 | AV24: =IF(COUNT(V24:W24)=2,(W24-V24)/H24,"") -> 0 | AW24: =IFERROR(AY24/(AY24+AZ24),"") | AX24: =IF(AH24="","",AH24/H24) | AY24: =IF(COUNT(AF24:AH24)=0,"",(AF24+AH24+AG24)/H24) | AZ24: =IF(AI24="","",AI24/H24)
E25: FE Mobile Reports | F25: 1. Nirmal Reports Ref: US-NRM-C5-003 | H25: =ROUNDUP(I25/Notes!$B$5,0) -> 2 | I25: 9 | J25: 9 | K25: =I25 -> 9 | L25: 46177 | M25: 46198 | N25: 46177 | O25: 46198 | T25: 46177 | U25: 46198 | X25: 0 | Y25: 0 | Z25: 9 | AB25: 0 | AM25: =IFERROR(H25/I25,"") -> 0.22222222 | AN25: =IFERROR(H25/(X25+AD25),"") | AO25: =IFERROR(H25/(Y25+AE25),"") | AP25: =IFERROR(H25/(Z25+AA25),"") -> 0.22222222 | AQ25: =IFERROR(H25/(AB25+AC25),"") | AR25: =IF(COUNT(P25:W25)=0,"",(MAX(P25:W25)-MIN(P25:W25))/H25) -> 10.5 | AS25: =IF(COUNT(P25:Q25)=2,(Q25-P25)/H25,"") | AT25: =IF(COUNT(R25:S25)=2,(S25-R25)/H25,"") | AU25: =IF(COUNT(T25:U25)=2,(U25-T25)/H25,"") -> 10.5 | AV25: =IF(COUNT(V25:W25)=2,(W25-V25)/H25,"") | AW25: =IFERROR(AY25/(AY25+AZ25),"") | AX25: =IF(AH25="","",AH25/H25) | AY25: =IF(COUNT(AF25:AH25)=0,"",(AF25+AH25+AG25)/H25) | AZ25: =IF(AI25="","",AI25/H25)
A26: 11 | B26: Public Health Engineering Department | C26: Jal Rekha | D26: O&M | E26: CR - GM | F26: 1. Bug Fixing from Frontend 2. UI update in existing page 3. New web page creation/ Modification Ref: US-OM-C5-013/015/016; PSR-SEP-03 | G26: Yes | H26: =ROUNDUP(I26/Notes!$B$5,0) -> 12 | I26: 60 | J26: 60 | K26: =I26 -> 60 | L26: 46174 | M26: 46293 | N26: 46174 | O26: 46293 | T26: 46174 | U26: 46293 | X26: 0 | Y26: 0 | Z26: 60 | AB26: 0 | AM26: =IFERROR(H26/I26,"") -> 0.2 | AN26: =IFERROR(H26/(X26+AD26),"") | AO26: =IFERROR(H26/(Y26+AE26),"") | AP26: =IFERROR(H26/(Z26+AA26),"") -> 0.2 | AQ26: =IFERROR(H26/(AB26+AC26),"") | AR26: =IF(COUNT(P26:W26)=0,"",(MAX(P26:W26)-MIN(P26:W26))/H26) -> 9.9166667 | AS26: =IF(COUNT(P26:Q26)=2,(Q26-P26)/H26,"") | AT26: =IF(COUNT(R26:S26)=2,(S26-R26)/H26,"") | AU26: =IF(COUNT(T26:U26)=2,(U26-T26)/H26,"") -> 9.9166667 | AV26: =IF(COUNT(V26:W26)=2,(W26-V26)/H26,"") | AW26: =IFERROR(AY26/(AY26+AZ26),"") | AX26: =IF(AH26="","",AH26/H26) | AY26: =IF(COUNT(AF26:AH26)=0,"",(AF26+AH26+AG26)/H26) | AZ26: =IF(AI26="","",AI26/H26)
E27: CR - Contractor | F27: 1. O&M Billing Contractor Summary Page changes 2. Contractor Bill generation flow and update Approved Reports 3. CR in Contractor - Summary page Abstract Report 4. "Generate Abstract Page(Pressure Redressal Sheet)" After Save & Submit – Contractor Side 5. Updation & Validation addition in Dhara Reports Ref: US-OM-C5-001/008; PSR-SEP-02 (Bill Tracking UI overhaul) | G27: Yes | H27: =ROUNDUP(I27/Notes!$B$5,0) -> 24 | I27: 122 | J27: 131 | K27: =I27 -> 122 | L27: 46177 | M27: 46290 | N27: 46177 | O27: 46290 | T27: 46177 | U27: 46290 | X27: 0 | Y27: 0 | Z27: 122 | AB27: 0 | AM27: =IFERROR(H27/I27,"") -> 0.19672131 | AN27: =IFERROR(H27/(X27+AD27),"") | AO27: =IFERROR(H27/(Y27+AE27),"") | AP27: =IFERROR(H27/(Z27+AA27),"") -> 0.19672131 | AQ27: =IFERROR(H27/(AB27+AC27),"") | AR27: =IF(COUNT(P27:W27)=0,"",(MAX(P27:W27)-MIN(P27:W27))/H27) -> 4.7083333 | AS27: =IF(COUNT(P27:Q27)=2,(Q27-P27)/H27,"") | AT27: =IF(COUNT(R27:S27)=2,(S27-R27)/H27,"") | AU27: =IF(COUNT(T27:U27)=2,(U27-T27)/H27,"") -> 4.7083333 | AV27: =IF(COUNT(V27:W27)=2,(W27-V27)/H27,"") | AW27: =IFERROR(AY27/(AY27+AZ27),"") | AX27: =IF(AH27="","",AH27/H27) | AY27: =IF(COUNT(AF27:AH27)=0,"",(AF27+AH27+AG27)/H27) | AZ27: =IF(AI27="","",AI27/H27)
E28: Enhancements - Bill Generation, WSDCP & Workflow Requirements | F28: 1. Contractor/GM Login O&M BIll Generation Enhancements 2. O&M Workflow Implementation and WSDCP and TRR Phase requirement gathering Ref: US-AUG-01..14, US-AUG-18, US-SEP-02..14 | G28: Yes | H28: =ROUNDUP(I28/Notes!$B$5,0) -> 93 | I28: 485 | J28: 496 | K28: =I28 -> 485 | L28: 46204 | M28: 46288 | N28: 46204 | O28: 46288 | P28: 46238 | Q28: 46265 | T28: 46204 | U28: 46288 | X28: 36 | Y28: 0 | Z28: 449 | AB28: 0 | AM28: =IFERROR(H28/I28,"") -> 0.19175258 | AN28: =IFERROR(H28/(X28+AD28),"") -> 2.5833333 | AO28: =IFERROR(H28/(Y28+AE28),"") | AP28: =IFERROR(H28/(Z28+AA28),"") -> 0.20712695 | AQ28: =IFERROR(H28/(AB28+AC28),"") | AR28: =IF(COUNT(P28:W28)=0,"",(MAX(P28:W28)-MIN(P28:W28))/H28) -> 0.90322581 | AS28: =IF(COUNT(P28:Q28)=2,(Q28-P28)/H28,"") -> 0.29032258 | AT28: =IF(COUNT(R28:S28)=2,(S28-R28)/H28,"") | AU28: =IF(COUNT(T28:U28)=2,(U28-T28)/H28,"") -> 0.90322581 | AV28: =IF(COUNT(V28:W28)=2,(W28-V28)/H28,"") | AW28: =IFERROR(AY28/(AY28+AZ28),"") | AX28: =IF(AH28="","",AH28/H28) | AY28: =IF(COUNT(AF28:AH28)=0,"",(AF28+AH28+AG28)/H28) | AZ28: =IF(AI28="","",AI28/H28)
E29: Workflow between GM (O&M) & Higher Officials | F29: 1. Worflow Functionality at each login for O&M Billing 2. O&M Billing Workflow preparation & requirement gathering Ref: US-AUG-07/09/10; Sep PSR (quarter filter, open bill access) | H29: =ROUNDUP(I29/Notes!$B$5,0) -> 9 | I29: 46 | J29: 51 | K29: =I29 -> 46 | L29: 46188 | M29: 46289 | N29: 46185 | O29: 46289 | P29: 46185 | Q29: 46233 | T29: 46204 | U29: 46289 | X29: 18 | Y29: 0 | Z29: 28 | AB29: 0 | AM29: =IFERROR(H29/I29,"") -> 0.19565217 | AN29: =IFERROR(H29/(X29+AD29),"") -> 0.5 | AO29: =IFERROR(H29/(Y29+AE29),"") | AP29: =IFERROR(H29/(Z29+AA29),"") -> 0.32142857 | AQ29: =IFERROR(H29/(AB29+AC29),"") | AR29: =IF(COUNT(P29:W29)=0,"",(MAX(P29:W29)-MIN(P29:W29))/H29) -> 11.555556 | AS29: =IF(COUNT(P29:Q29)=2,(Q29-P29)/H29,"") -> 5.3333333 | AT29: =IF(COUNT(R29:S29)=2,(S29-R29)/H29,"") | AU29: =IF(COUNT(T29:U29)=2,(U29-T29)/H29,"") -> 9.4444444 | AV29: =IF(COUNT(V29:W29)=2,(W29-V29)/H29,"") | AW29: =IFERROR(AY29/(AY29+AZ29),"") | AX29: =IF(AH29="","",AH29/H29) | AY29: =IF(COUNT(AF29:AH29)=0,"",(AF29+AH29+AG29)/H29) | AZ29: =IF(AI29="","",AI29/H29)
A30: 12 | B30: Public Health Engineering Department | C30: Jal Rekha | D30: Sahbhagita | E30: Change Request - RA Bill, Activities & Abstract Report | F30: 1. Sahbhagita Activities Addition & Abstract Report Creation 2. RA Bill Functionlaity on CP Manager 3. Test Case Creation 4. New web page creation/ Modification Ref: US-SAH-C5-001/002/003/006/007; US-AUG-26 | G30: Yes | H30: =ROUNDUP(I30/Notes!$B$5,0) -> 30 | I30: 155 | J30: 159 | K30: =I30 -> 155 | L30: 46174 | M30: 46231 | N30: 46174 | O30: 46232 | T30: 46174 | U30: 46232 | V30: 46230 | W30: 46232 | X30: 0 | Y30: 0 | Z30: 143 | AB30: 12 | AM30: =IFERROR(H30/I30,"") -> 0.19354839 | AN30: =IFERROR(H30/(X30+AD30),"") | AO30: =IFERROR(H30/(Y30+AE30),"") | AP30: =IFERROR(H30/(Z30+AA30),"") -> 0.20979021 | AQ30: =IFERROR(H30/(AB30+AC30),"") -> 2.5 | AR30: =IF(COUNT(P30:W30)=0,"",(MAX(P30:W30)-MIN(P30:W30))/H30) -> 1.9333333 | AS30: =IF(COUNT(P30:Q30)=2,(Q30-P30)/H30,"") | AT30: =IF(COUNT(R30:S30)=2,(S30-R30)/H30,"") | AU30: =IF(COUNT(T30:U30)=2,(U30-T30)/H30,"") -> 1.9333333 | AV30: =IF(COUNT(V30:W30)=2,(W30-V30)/H30,"") -> 0.066666667 | AW30: =IFERROR(AY30/(AY30+AZ30),"") | AX30: =IF(AH30="","",AH30/H30) | AY30: =IF(COUNT(AF30:AH30)=0,"",(AF30+AH30+AG30)/H30) | AZ30: =IF(AI30="","",AI30/H30)
E31: Change Request - GM / PM / Reports | F31: 1. Bug Fixing from Frontend or Database end 2. Add Save as Draft Functionality Ref: US-SAH-C5-008; Jun-Aug PSR | G31: Yes | H31: =ROUNDUP(I31/Notes!$B$5,0) -> 8 | I31: 42 | J31: 44 | K31: =I31 -> 42 | L31: 46178 | M31: 46252 | N31: 46178 | O31: 46253 | T31: 46178 | U31: 46253 | X31: 0 | Y31: 0 | Z31: 42 | AB31: 0 | AM31: =IFERROR(H31/I31,"") -> 0.19047619 | AN31: =IFERROR(H31/(X31+AD31),"") | AO31: =IFERROR(H31/(Y31+AE31),"") | AP31: =IFERROR(H31/(Z31+AA31),"") -> 0.19047619 | AQ31: =IFERROR(H31/(AB31+AC31),"") | AR31: =IF(COUNT(P31:W31)=0,"",(MAX(P31:W31)-MIN(P31:W31))/H31) -> 9.375 | AS31: =IF(COUNT(P31:Q31)=2,(Q31-P31)/H31,"") | AT31: =IF(COUNT(R31:S31)=2,(S31-R31)/H31,"") | AU31: =IF(COUNT(T31:U31)=2,(U31-T31)/H31,"") -> 9.375 | AV31: =IF(COUNT(V31:W31)=2,(W31-V31)/H31,"") | AW31: =IFERROR(AY31/(AY31+AZ31),"") | AX31: =IF(AH31="","",AH31/H31) | AY31: =IF(COUNT(AF31:AH31)=0,"",(AF31+AH31+AG31)/H31) | AZ31: =IF(AI31="","",AI31/H31)
E32: GM - Production Support, SIT & UAT | F32: 1. Bug Fixing from Frontend 2. Bug Fixing from Frontend or Database end 3. UAT/Prod/CR Testing 4. SIT Testing Ref: US-SAH-C5-005/009/010/011; Jun-Sep PSR | H32: =ROUNDUP(I32/Notes!$B$5,0) -> 23 | I32: 117 | J32: 117 | K32: =I32 -> 117 | L32: 46188 | M32: 46281 | N32: 46188 | O32: 46281 | T32: 46188 | U32: 46259 | V32: 46189 | W32: 46281 | X32: 0 | Y32: 0 | Z32: 70 | AB32: 47 | AM32: =IFERROR(H32/I32,"") -> 0.1965812 | AN32: =IFERROR(H32/(X32+AD32),"") | AO32: =IFERROR(H32/(Y32+AE32),"") | AP32: =IFERROR(H32/(Z32+AA32),"") -> 0.32857143 | AQ32: =IFERROR(H32/(AB32+AC32),"") -> 0.4893617 | AR32: =IF(COUNT(P32:W32)=0,"",(MAX(P32:W32)-MIN(P32:W32))/H32) -> 4.0434783 | AS32: =IF(COUNT(P32:Q32)=2,(Q32-P32)/H32,"") | AT32: =IF(COUNT(R32:S32)=2,(S32-R32)/H32,"") | AU32: =IF(COUNT(T32:U32)=2,(U32-T32)/H32,"") -> 3.0869565 | AV32: =IF(COUNT(V32:W32)=2,(W32-V32)/H32,"") -> 4 | AW32: =IFERROR(AY32/(AY32+AZ32),"") | AX32: =IF(AH32="","",AH32/H32) | AY32: =IF(COUNT(AF32:AH32)=0,"",(AF32+AH32+AG32)/H32) | AZ32: =IF(AI32="","",AI32/H32)
A33: 13 | B33: Public Health Engineering Department | C33: Jal Rekha | D33: SVS | E33: Water Supply Monitoring | F33: 1. Development of Web pages and Database functions 2. SVS Daily Water Supply Wireframe 3. SVS dashboard Creation 4. Database functionality to add specific fields into the required tables 5. Test Case/Scenario Creation 6. Test Plan Document 7. Internal Testing Ref: US-SVS-C5-001..004, US-AUG-19/20/21 | H33: =ROUNDUP(I33/Notes!$B$5,0) -> 33 | I33: 171 | J33: 177 | K33: =I33 -> 171 | L33: 46183 | M33: 46276 | N33: 46182 | O33: 46276 | R33: 46183 | S33: 46234 | T33: 46182 | U33: 46276 | V33: 46188 | W33: 46248 | X33: 0 | Y33: 10 | Z33: 147 | AB33: 14 | AM33: =IFERROR(H33/I33,"") -> 0.19298246 | AN33: =IFERROR(H33/(X33+AD33),"") | AO33: =IFERROR(H33/(Y33+AE33),"") -> 3.3 | AP33: =IFERROR(H33/(Z33+AA33),"") -> 0.2244898 | AQ33: =IFERROR(H33/(AB33+AC33),"") -> 2.3571429 | AR33: =IF(COUNT(P33:W33)=0,"",(MAX(P33:W33)-MIN(P33:W33))/H33) -> 2.8484848 | AS33: =IF(COUNT(P33:Q33)=2,(Q33-P33)/H33,"") | AT33: =IF(COUNT(R33:S33)=2,(S33-R33)/H33,"") -> 1.5454545 | AU33: =IF(COUNT(T33:U33)=2,(U33-T33)/H33,"") -> 2.8484848 | AV33: =IF(COUNT(V33:W33)=2,(W33-V33)/H33,"") -> 1.8181818 | AW33: =IFERROR(AY33/(AY33+AZ33),"") | AX33: =IF(AH33="","",AH33/H33) | AY33: =IF(COUNT(AF33:AH33)=0,"",(AF33+AH33+AG33)/H33) | AZ33: =IF(AI33="","",AI33/H33)
E34: SVS Nirmal - FTK Kit & Nirmal GP | F34: 1. SVS Nirmal Water Supply details FTK kit requirements 2. Requirement gathering, meetings and wireframe 3. Internal Testing Ref: US-SEP-28; Sep PSR (FTK kit wireframe, SVS Nirmal GP) | H34: =ROUNDUP(I34/Notes!$B$5,0) -> 14 | I34: 70 | J34: 70 | K34: =I34 -> 70 | L34: 46238 | M34: 46273 | N34: 46238 | O34: 46283 | P34: 46238 | Q34: 46283 | V34: 46272 | W34: 46273 | X34: 62 | Y34: 0 | Z34: 0 | AB34: 8 | AM34: =IFERROR(H34/I34,"") -> 0.2 | AN34: =IFERROR(H34/(X34+AD34),"") -> 0.22580645 | AO34: =IFERROR(H34/(Y34+AE34),"") | AP34: =IFERROR(H34/(Z34+AA34),"") | AQ34: =IFERROR(H34/(AB34+AC34),"") -> 1.75 | AR34: =IF(COUNT(P34:W34)=0,"",(MAX(P34:W34)-MIN(P34:W34))/H34) -> 3.2142857 | AS34: =IF(COUNT(P34:Q34)=2,(Q34-P34)/H34,"") -> 3.2142857 | AT34: =IF(COUNT(R34:S34)=2,(S34-R34)/H34,"") | AU34: =IF(COUNT(T34:U34)=2,(U34-T34)/H34,"") | AV34: =IF(COUNT(V34:W34)=2,(W34-V34)/H34,"") -> 0.071428571 | AW34: =IFERROR(AY34/(AY34+AZ34),"") | AX34: =IF(AH34="","",AH34/H34) | AY34: =IF(COUNT(AF34:AH34)=0,"",(AF34+AH34+AG34)/H34) | AZ34: =IF(AI34="","",AI34/H34)
E35: SVS Anusharavan GP - Master, Mobile & RFI | F35: 1. Project Module Initiation Meeting and Requirement gathering 2. Anusharavan at Gram Panchanyat level 3. Mobile Development 4. Requirement gathering, meetings and Wireframe 5. Web Development, API & Database Functions Ref: US-SEP-29/30/31/32/33/34, US-AUG-35 | H35: =ROUNDUP(I35/Notes!$B$5,0) -> 32 | I35: 168 | J35: 170 | K35: =I35 -> 168 | L35: 46232 | M35: 46289 | N35: 46234 | O35: 46295 | P35: 46234 | Q35: 46295 | T35: 46266 | U35: 46289 | X35: 30 | Y35: 0 | Z35: 138 | AB35: 0 | AM35: =IFERROR(H35/I35,"") -> 0.19047619 | AN35: =IFERROR(H35/(X35+AD35),"") -> 1.0666667 | AO35: =IFERROR(H35/(Y35+AE35),"") | AP35: =IFERROR(H35/(Z35+AA35),"") -> 0.23188406 | AQ35: =IFERROR(H35/(AB35+AC35),"") | AR35: =IF(COUNT(P35:W35)=0,"",(MAX(P35:W35)-MIN(P35:W35))/H35) -> 1.90625 | AS35: =IF(COUNT(P35:Q35)=2,(Q35-P35)/H35,"") -> 1.90625 | AT35: =IF(COUNT(R35:S35)=2,(S35-R35)/H35,"") | AU35: =IF(COUNT(T35:U35)=2,(U35-T35)/H35,"") -> 0.71875 | AV35: =IF(COUNT(V35:W35)=2,(W35-V35)/H35,"") | AW35: =IFERROR(AY35/(AY35+AZ35),"") | AX35: =IF(AH35="","",AH35/H35) | AY35: =IF(COUNT(AF35:AH35)=0,"",(AF35+AH35+AG35)/H35) | AZ35: =IF(AI35="","",AI35/H35)
A36: 14 | B36: Public Health Engineering Department | C36: Jal Rekha | D36: Sopan | E36: CR - Contractor Calendar (Web / Mobile) | F36: 1. Adding Calendar functionality for 2026-27 year option Ref: US-SOP-C5-001; Jul MoM | G36: Yes | H36: =ROUNDUP(I36/Notes!$B$5,0) -> 2 | I36: 10 | J36: 10 | K36: =I36 -> 10 | L36: 46224 | M36: 46246 | N36: 46224 | O36: 46245 | T36: 46224 | U36: 46245 | X36: 0 | Y36: 0 | Z36: 10 | AB36: 0 | AM36: =IFERROR(H36/I36,"") -> 0.2 | AN36: =IFERROR(H36/(X36+AD36),"") | AO36: =IFERROR(H36/(Y36+AE36),"") | AP36: =IFERROR(H36/(Z36+AA36),"") -> 0.2 | AQ36: =IFERROR(H36/(AB36+AC36),"") | AR36: =IF(COUNT(P36:W36)=0,"",(MAX(P36:W36)-MIN(P36:W36))/H36) -> 10.5 | AS36: =IF(COUNT(P36:Q36)=2,(Q36-P36)/H36,"") | AT36: =IF(COUNT(R36:S36)=2,(S36-R36)/H36,"") | AU36: =IF(COUNT(T36:U36)=2,(U36-T36)/H36,"") -> 10.5 | AV36: =IF(COUNT(V36:W36)=2,(W36-V36)/H36,"") | AW36: =IFERROR(AY36/(AY36+AZ36),"") | AX36: =IF(AH36="","",AH36/H36) | AY36: =IF(COUNT(AF36:AH36)=0,"",(AF36+AH36+AG36)/H36) | AZ36: =IF(AI36="","",AI36/H36)
A37: 15 | B37: Public Health Engineering Department | C37: Jal Rekha | D37: Daily Inspection | E37: Role-based Reports & Mobile Fixes | F37: 1. Production deployment 2. New web page creation/ Modification 3. Bug Fixing Mobile APP Ref: US-DIN-C5-001/002 | H37: =ROUNDUP(I37/Notes!$B$5,0) -> 6 | I37: 28 | J37: 28 | K37: =I37 -> 28 | L37: 46176 | M37: 46254 | N37: 46176 | O37: 46254 | T37: 46176 | U37: 46254 | X37: 0 | Y37: 0 | Z37: 28 | AB37: 0 | AM37: =IFERROR(H37/I37,"") -> 0.21428571 | AN37: =IFERROR(H37/(X37+AD37),"") | AO37: =IFERROR(H37/(Y37+AE37),"") | AP37: =IFERROR(H37/(Z37+AA37),"") -> 0.21428571 | AQ37: =IFERROR(H37/(AB37+AC37),"") | AR37: =IF(COUNT(P37:W37)=0,"",(MAX(P37:W37)-MIN(P37:W37))/H37) -> 13 | AS37: =IF(COUNT(P37:Q37)=2,(Q37-P37)/H37,"") | AT37: =IF(COUNT(R37:S37)=2,(S37-R37)/H37,"") | AU37: =IF(COUNT(T37:U37)=2,(U37-T37)/H37,"") -> 13 | AV37: =IF(COUNT(V37:W37)=2,(W37-V37)/H37,"") | AW37: =IFERROR(AY37/(AY37+AZ37),"") | AX37: =IF(AH37="","",AH37/H37) | AY37: =IF(COUNT(AF37:AH37)=0,"",(AF37+AH37+AG37)/H37) | AZ37: =IF(AI37="","",AI37/H37)
A38: 16 | B38: Public Health Engineering Department | C38: Jal Rekha | D38: User & Role Management | E38: Selenium Automation (Login, Registration, Assign Work) | F38: 1. Automation with Selenium Ref: US-QA-C5-001/002, PSR-SEP-04 | H38: =ROUNDUP(I38/Notes!$B$5,0) -> 7 | I38: 32 | J38: 32 | K38: =I38 -> 32 | L38: 46178 | M38: 46274 | N38: 46181 | O38: 46274 | V38: 46181 | W38: 46274 | X38: 0 | Y38: 0 | Z38: 0 | AB38: 32 | AM38: =IFERROR(H38/I38,"") -> 0.21875 | AN38: =IFERROR(H38/(X38+AD38),"") | AO38: =IFERROR(H38/(Y38+AE38),"") | AP38: =IFERROR(H38/(Z38+AA38),"") | AQ38: =IFERROR(H38/(AB38+AC38),"") -> 0.21875 | AR38: =IF(COUNT(P38:W38)=0,"",(MAX(P38:W38)-MIN(P38:W38))/H38) -> 13.285714 | AS38: =IF(COUNT(P38:Q38)=2,(Q38-P38)/H38,"") | AT38: =IF(COUNT(R38:S38)=2,(S38-R38)/H38,"") | AU38: =IF(COUNT(T38:U38)=2,(U38-T38)/H38,"") | AV38: =IF(COUNT(V38:W38)=2,(W38-V38)/H38,"") -> 13.285714 | AW38: =IFERROR(AY38/(AY38+AZ38),"") | AX38: =IF(AH38="","",AH38/H38) | AY38: =IF(COUNT(AF38:AH38)=0,"",(AF38+AH38+AG38)/H38) | AZ38: =IF(AI38="","",AI38/H38)
A41: 17 | B41: Public Health Engineering Department | C41: Jal Rekha | D41: CI/CD | E41: Azure DevOps Android Pipeline | F41: 1. CI/CD Pipeline Implementation Ref: Jun PSR (CI/CD pipeline implementation) | H41: =ROUNDUP(I41/Notes!$B$5,0) -> 4 | I41: 16 | J41: 16 | K41: =I41 -> 16 | L41: 46202 | M41: 46203 | N41: 46202 | O41: 46203 | T41: 46202 | U41: 46203 | X41: 0 | Y41: 0 | Z41: 16 | AB41: 0 | AM41: =IFERROR(H41/I41,"") -> 0.25 | AN41: =IFERROR(H41/(X41+AD41),"") | AO41: =IFERROR(H41/(Y41+AE41),"") | AP41: =IFERROR(H41/(Z41+AA41),"") -> 0.25 | AQ41: =IFERROR(H41/(AB41+AC41),"") | AR41: =IF(COUNT(P41:W41)=0,"",(MAX(P41:W41)-MIN(P41:W41))/H41) -> 0.25 | AS41: =IF(COUNT(P41:Q41)=2,(Q41-P41)/H41,"") | AT41: =IF(COUNT(R41:S41)=2,(S41-R41)/H41,"") | AU41: =IF(COUNT(T41:U41)=2,(U41-T41)/H41,"") -> 0.25 | AV41: =IF(COUNT(V41:W41)=2,(W41-V41)/H41,"") | AW41: =IFERROR(AY41/(AY41+AZ41),"") | AX41: =IF(AH41="","",AH41/H41) | AY41: =IF(COUNT(AF41:AH41)=0,"",(AF41+AH41+AG41)/H41) | AZ41: =IF(AI41="","",AI41/H41)
A42: 18 | B42: Public Health Engineering Department | C42: Jal Rekha | D42: Adhoc | E42: Two-Factor Authentication Implementation | F42: 1. 2 Factor Authentication Implementation Ref: US-SEP-36; Sep PSR (Adhoc) | H42: =ROUNDUP(I42/Notes!$B$5,0) -> 5 | I42: 24 | J42: 24 | K42: =I42 -> 24 | L42: 46268 | M42: 46275 | N42: 46268 | O42: 46275 | T42: 46268 | U42: 46275 | X42: 0 | Y42: 0 | Z42: 24 | AB42: 0 | AM42: =IFERROR(H42/I42,"") -> 0.20833333 | AN42: =IFERROR(H42/(X42+AD42),"") | AO42: =IFERROR(H42/(Y42+AE42),"") | AP42: =IFERROR(H42/(Z42+AA42),"") -> 0.20833333 | AQ42: =IFERROR(H42/(AB42+AC42),"") | AR42: =IF(COUNT(P42:W42)=0,"",(MAX(P42:W42)-MIN(P42:W42))/H42) -> 1.4 | AS42: =IF(COUNT(P42:Q42)=2,(Q42-P42)/H42,"") | AT42: =IF(COUNT(R42:S42)=2,(S42-R42)/H42,"") | AU42: =IF(COUNT(T42:U42)=2,(U42-T42)/H42,"") -> 1.4 | AV42: =IF(COUNT(V42:W42)=2,(W42-V42)/H42,"") | AW42: =IFERROR(AY42/(AY42+AZ42),"") | AX42: =IF(AH42="","",AH42/H42) | AY42: =IF(COUNT(AF42:AH42)=0,"",(AF42+AH42+AG42)/H42) | AZ42: =IF(AI42="","",AI42/H42)
...

Sheet Notes
A1: Jal Rekha - Data Collection Cycle 5 (Jun-Sep 2026): parameters and method
A3: Parameter | B3: Value | C3: Note
A4: Targeted productivity (pt/hr) | B4: 0.19 | C4: Raised from 0.179 (Cycle 4) to 0.19 as instructed; same value as Baseline Productivity in the Cycle 5 estimation workbook.
A5: Hours per story point | B5: =1/B4 -> 5.2631579 | C5: About 5.26 hrs (Cycle 4 used 5.6). Size (col H) = ROUNDUP(Hours Consumed / B5), the same rule as Cycle 4 with the new divisor.
A8: Source of hours / dates | C8: Date-Wise Time Sheet Jun-Sep 2026 (622 entries, 3,442 hrs). Hours Consumed = sum of consumed hours for the sub-module; Actual Effort = Hours Consumed.
A9: Planned Effort | C9: Sum of Assign Hours of unique tasks (resource, module, activity, task, assign date) in the sub-module. Planned Start = earliest Task Assign Date; Planned End = latest (Task Assign Date + assigned hours / 8 working days).
A10: Actual Start / End | C10: Earliest and latest timesheet entry dates for the sub-module.
A11: Phase dates and efforts | C11: Timesheet entries classified by Activity Name: requirement / meeting / initiation = Requirement; wireframe = Design; test / UAT / SIT / Selenium = Testing; everything else = Coding. Phases with no entries are left blank (not estimated).
A12: Cycle Time (col AR) | C12: Calendar days from earliest to latest phase date divided by Size; phase cycle times are blank when a phase has no dates. Cycle 4 used Requirement start to Testing end, which fails when a phase is absent.
A13: Not available in any source | C13: Review efforts (AA, AC, AD, AE) and all defect counts (AF-AK) are not in the timesheet, MoMs, PSRs or user stories, so they are left blank (yellow). DRE, Code Review Per Size, Total Review Defects and Internal Testing density stay blank until entered. Code_Rate and Test_Rate exclude review effort until AA/AC are filled.
A14: CMMI Doc rows | C14: Hours and size only, as in Cycle 4.
A15: Excluded timesheet hours | C15: Department Meetings (34 hrs) and Adhoc Training/Walkthrough (3 hrs) = 37 hrs; all other 3,405 hrs are in the DC sheet.
A16: Cycle 4 baseline | C16: PPM Prod C4 / PPM CT C4 / PPM DRE C4 are carried over unchanged from Cycle 4 V6 for comparison. PPM C5 sheets are live formulas on the DC sheet.
A17: PPM C5 statistics | C17: Mean = AVERAGE; UCL / LCL = Mean +/- 3 SD (sample SD); regression coefficients from LINEST. Cycle 4 values were produced in Minitab, so small differences are expected; re-run Minitab for the audit record.

Sheet PPM Prod C5
A1: Productivity | B1: Code_Rate | C1: Test_Rate
A2: ='DC JuntoSep'!AM2 -> 0.19047619 | B2: ='DC JuntoSep'!AP2 -> 0.21428571 | C2: ='DC JuntoSep'!AQ2 -> 1.7142857
A3: ='DC JuntoSep'!AM3 -> 0.19230769 | B3: ='DC JuntoSep'!AP3 -> 0.20833333 | C3: ='DC JuntoSep'!AQ3 -> 2.5
A4: ='DC JuntoSep'!AM7 -> 0.19230769 | B4: ='DC JuntoSep'!AP7 -> 0.41666667 | C4: ='DC JuntoSep'!AQ7 -> 0.35714286
A5: ='DC JuntoSep'!AM8 -> 0.19117647 | B5: ='DC JuntoSep'!AP8 -> 0.325 | C5: ='DC JuntoSep'!AQ8 -> 0.46428571
A6: ='DC JuntoSep'!AM9 -> 0.2 | B6: ='DC JuntoSep'!AP9 -> 0.5 | C6: ='DC JuntoSep'!AQ9 -> 0.33333333
A7: ='DC JuntoSep'!AM10 -> 0.19157088 | B7: ='DC JuntoSep'!AP10 -> 0.3875969 | C7: ='DC JuntoSep'!AQ10 -> 0.37878788
A8: ='DC JuntoSep'!AM12 -> 0.19148936 | B8: ='DC JuntoSep'!AP12 -> 0.20454545 | C8: ='DC JuntoSep'!AQ12 -> 3
A9: ='DC JuntoSep'!AM15 -> 0.20689655 | B9: ='DC JuntoSep'!AP15 -> 0.54545455 | C9: ='DC JuntoSep'!AQ15 -> 3
A10: ='DC JuntoSep'!AM17 -> 0.20454545 | B10: ='DC JuntoSep'!AP17 -> 0.225 | C10: ='DC JuntoSep'!AQ17 -> 2.25
A11: ='DC JuntoSep'!AM23 -> 0.19004525 | B11: ='DC JuntoSep'!AP23 -> 0.1971831 | C11: ='DC JuntoSep'!AQ23 -> 5.25
A12: ='DC JuntoSep'!AM24 -> 0.20833333 | B12: ='DC JuntoSep'!AP24 -> 0.23255814 | C12: ='DC JuntoSep'!AQ24 -> 2
A13: ='DC JuntoSep'!AM30 -> 0.19354839 | B13: ='DC JuntoSep'!AP30 -> 0.20979021 | C13: ='DC JuntoSep'!AQ30 -> 2.5
A14: ='DC JuntoSep'!AM32 -> 0.1965812 | B14: ='DC JuntoSep'!AP32 -> 0.32857143 | C14: ='DC JuntoSep'!AQ32 -> 0.4893617
A15: ='DC JuntoSep'!AM33 -> 0.19298246 | B15: ='DC JuntoSep'!AP33 -> 0.2244898 | C15: ='DC JuntoSep'!AQ33 -> 2.3571429
A16: ='DC JuntoSep'!AM43 -> 0.19642857 | B16: ='DC JuntoSep'!AP43 -> 0.6875 | C16: ='DC JuntoSep'!AQ43 -> 0.275
M28: Regression Equation
M29: Productivity | N29: = | O29: =TEXT(INDEX(LINEST(A2:A16,B2:C16),1,3),"0.0000")&" + "&TEXT(INDEX(LINEST(A2:A16,B2:C16),1,2),"0.0000")&" Code_Rate + "&TEXT(INDEX(LINEST(A2:A16,B2:C16),1,1),"0.0000")&" Test_Rate" -> 0.1894 + 0.0154 Code_Rate + 0.0008 Test_Rate
O35: AS-IS | P35: Productivity | Q35: Code_Rate | R35: Test_Rate
O36: Mean | P36: =AVERAGE(A2:A16) -> 0.19591263 | Q36: =AVERAGE(B2:B16) -> 0.32713169 | R36: =AVERAGE(C2:C16) -> 1.7912893
O37: SD | P37: =(P38-P39)/6 -> 0.0061636079 | Q37: =(Q38-Q39)/6 -> 0.15154762 | R37: =(R38-R39)/6 -> 1.4243279
O38: UCL | P38: =P36+3*STDEV(A2:A16) -> 0.21440346 | Q38: =Q36+3*STDEV(B2:B16) -> 0.78177453 | R38: =R36+3*STDEV(C2:C16) -> 6.064273
O39: LCL | P39: =P36-3*STDEV(A2:A16) -> 0.17742181 | Q39: =Q36-3*STDEV(B2:B16) -> -0.12751116 | R39: =R36-3*STDEV(C2:C16) -> -2.4816943
O41: Target | P41: Productivity
O42: Mean | P42: =P36+R42 -> 0.2155039 | R42: =P36*10% -> 0.019591263
O43: SD | P43: 0.05
O45: What if | P45: Productivity | Q45: Code_Rate | R45: Test_Rate
O46: Mean | P46: =INDEX(LINEST(A2:A16,B2:C16),1,3)+INDEX(LINEST(A2:A16,B2:C16),1,2)*Q46+INDEX(LINEST(A2:A16,B2:C16),1,1)*R46 -> 0.19624663 | Q46: 0.4 | R46: 0.85
O47: SD | P47: 0.05 | Q47: 0.05 | R47: 0.05
O48: USL | P48: =P46+(3*P47) -> 0.34624663 | Q48: =Q46+(3*Q47) -> 0.55 | R48: =R46+(3*R47) -> 1
O49: LSL | P49: =P46-(3*P47) -> 0.046246629 | Q49: =Q46-(3*Q47) -> 0.25 | R49: =R46-(3*R47) -> 0.7

Sheet PPM CT C5
A1: Cycle Time | B1: Code_CT | C1: Test_CT
A2: ='DC JuntoSep'!AR2 -> 6.5 | B2: ='DC JuntoSep'!AU2 -> 6.5 | C2: ='DC JuntoSep'!AV2 -> 3.9166667
A3: ='DC JuntoSep'!AR3 -> 7.6 | B3: ='DC JuntoSep'!AU3 -> 7.6 | C3: ='DC JuntoSep'!AV3 -> 0
A4: ='DC JuntoSep'!AR7 -> 11 | B4: ='DC JuntoSep'!AU7 -> 1.9 | C4: ='DC JuntoSep'!AV7 -> 7.8
A5: ='DC JuntoSep'!AR8 -> 5.3076923 | B5: ='DC JuntoSep'!AU8 -> 2.3846154 | C5: ='DC JuntoSep'!AV8 -> 3.1538462
A6: ='DC JuntoSep'!AR9 -> 4.8333333 | B6: ='DC JuntoSep'!AU9 -> 4.8333333 | C6: ='DC JuntoSep'!AV9 -> 3.1666667
A7: ='DC JuntoSep'!AR10 -> 2.1 | B7: ='DC JuntoSep'!AU10 -> 1.74 | C7: ='DC JuntoSep'!AV10 -> 1.66
A8: ='DC JuntoSep'!AR12 -> 6.3888889 | B8: ='DC JuntoSep'!AU12 -> 6.3888889 | C8: ='DC JuntoSep'!AV12 -> 0.11111111
A9: ='DC JuntoSep'!AR15 -> 6.6666667 | B9: ='DC JuntoSep'!AU15 -> 0.5 | C9: ='DC JuntoSep'!AV15 -> 0
A10: ='DC JuntoSep'!AR17 -> 7.7777778 | B10: ='DC JuntoSep'!AU17 -> 7.7777778 | C10: ='DC JuntoSep'!AV17 -> 0
A11: ='DC JuntoSep'!AR23 -> 1.6666667 | B11: ='DC JuntoSep'!AU23 -> 1.6666667 | C11: ='DC JuntoSep'!AV23 -> 0.023809524
A12: ='DC JuntoSep'!AR24 -> 6.7 | B12: ='DC JuntoSep'!AU24 -> 6.7 | C12: ='DC JuntoSep'!AV24 -> 0
A13: ='DC JuntoSep'!AR30 -> 1.9333333 | B13: ='DC JuntoSep'!AU30 -> 1.9333333 | C13: ='DC JuntoSep'!AV30 -> 0.066666667
A14: ='DC JuntoSep'!AR32 -> 4.0434783 | B14: ='DC JuntoSep'!AU32 -> 3.0869565 | C14: ='DC JuntoSep'!AV32 -> 4
A15: ='DC JuntoSep'!AR33 -> 2.8484848 | B15: ='DC JuntoSep'!AU33 -> 2.8484848 | C15: ='DC JuntoSep'!AV33 -> 1.8181818
A16: ='DC JuntoSep'!AR43 -> 1.8181818 | B16: ='DC JuntoSep'!AU43 -> 0.090909091 | C16: ='DC JuntoSep'!AV43 -> 0.18181818
O29: Regression Equation
O30: Cycle Time | P30: = | Q30: =TEXT(INDEX(LINEST(A2:A16,B2:C16),1,3),"0.0000")&" + "&TEXT(INDEX(LINEST(A2:A16,B2:C16),1,2),"0.0000")&" Code_CT + "&TEXT(INDEX(LINEST(A2:A16,B2:C16),1,1),"0.0000")&" Test_CT" -> 1.9680 + 0.5803 Code_CT + 0.5868 Test_CT
P35: AS-IS | Q35: Cycle time | R35: Code_CT | S35: Test_CT
P36: Mean | Q36: =AVERAGE(A2:A16) -> 5.1456336 | R36: =AVERAGE(B2:B16) -> 3.7300644 | S36: =AVERAGE(C2:C16) -> 1.7265845
P37: SD | Q37: =(Q38-Q39)/6 -> 2.7349671 | R37: =(R38-R39)/6 -> 2.6405236 | S37: =(S38-S39)/6 -> 2.2920701
P38: UCL | Q38: =Q36+3*STDEV(A2:A16) -> 13.350535 | R38: =R36+3*STDEV(B2:B16) -> 11.651635 | S38: =S36+3*STDEV(C2:C16) -> 8.6027947
P39: LCL | Q39: =Q36-3*STDEV(A2:A16) -> -3.0592676 | R39: =R36-3*STDEV(B2:B16) -> -4.1915065 | S39: =S36-3*STDEV(C2:C16) -> -5.1496258
P43: Target | Q43: Cycle time
P44: Mean | Q44: =Q36-S44 -> 4.6310702 | S44: =Q36*10% -> 0.51456336
P45: SD | Q45: 0.25
P48: What if | Q48: Cycle time | R48: Code_CT | S48: Test_CT
P49: Mean | Q49: =INDEX(LINEST(A2:A16,B2:C16),1,3)+INDEX(LINEST(A2:A16,B2:C16),1,2)*R49+INDEX(LINEST(A2:A16,B2:C16),1,1)*S49 -> 5.1456336 | R49: =R36 -> 3.7300644 | S49: =S36 -> 1.7265845
P50: SD | Q50: 0.25 | R50: 0.1 | S50: 0.5
P51: USL | Q51: =Q49+(3*Q50) -> 5.8956336 | R51: =R49+(3*R50) -> 4.0300644 | S51: =S49+(3*S50) -> 3.2265845
P52: LSL | Q52: =Q49-(3*Q50) -> 4.3956336 | R52: =R49-(3*R50) -> 3.4300644 | S52: =S49-(3*S50) -> 0.22658445

Sheet PPM DRE C5
A1: DRE | B1: Code Review Per Size
A3: Pending: enter review and defect counts in DC JuntoSep (AF-AK); then link rows here as in PPM DRE C4.
N30: DRE | O30: = | P30: Regression to be run once defect data is available (Cycle 4: 0.5959 + 1.215 Code Review Per Size)
N41: Target | O41: DRE
N42: Mean | O42: 0.8
N43: SD | O43: 0.1

Sheet PPM Prod C4
A1: Productivity | B1: Code_Rate | C1: Test_Rate
A2: 0.18333333 | B2: 0.32835821 | C2: 0.64705882
A3: 0.19047619 | B3: 0.33333333 | C3: 1
A4: 0.2 | B4: 0.32142857 | C4: 1
A5: 0.17948718 | B5: 0.31818182 | C5: 0.63636364
A6: 0.18367347 | B6: 0.33333333 | C6: 0.64285714
A7: 0.1875 | B7: 0.32432432 | C7: 0.85714286
A8: 0.18235294 | B8: 0.2952381 | C8: 0.81578947
A9: 0.17948718 | B9: 0.33333333 | C9: 0.58333333
A10: 0.17910448 | B10: 0.30769231 | C10: 0.70588235
A11: 0.18681319 | B11: 0.30909091 | C11: 0.65384615
A12: 0.18404908 | B12: 0.3030303 | C12: 0.81081081
A13: 0.18220339 | B13: 0.31386861 | C13: 0.62318841
... A23: 0.18032787 | B23: 0.25581395 | C23: 0.84615385
M28: Regression Equation
M29: Productivity | N29: = | O29: 0.1199 + 0.1236 Code_Rate + 0.03540 Test_Rate
O35: AS-IS | P35: Productivity | Q35: Code_Rate | R35: Test_Rate
O36: Mean | P36: 0.184521 | Q36: 0.314479 | R36: 0.729052
O37: SD | P37: =(P38-P39)/6 -> 0.030056167 | Q37: =(Q38-Q39)/6 -> 0.012762333 | R37: =(R38-R39)/6 -> 0.13390567
O38: UCL | P38: 0.202833 | Q38: 0.352766 | R38: 1.13077
O39: LCL | P39: 0.022496 | Q39: 0.276192 | R39: 0.327336
O41: Target | P41: Productivity
O42: Mean | P42: =P36+R42 -> 0.2029731 | R42: =P36*10% -> 0.0184521
O43: SD | P43: 0.05
O45: What if | P45: Productivity | Q45: Code_Rate | R45: Test_Rate
O46: Mean | P46: =0.1199 + (0.1236*Q46) + (0.0354*R46) -> 0.19943 | Q46: 0.4 | R46: 0.85
O47: SD | P47: 0.05 | Q47: 0.05 | R47: 0.05
O48: USL | P48: =P46+(3*P47) -> 0.34943 | Q48: =Q46+(3*Q47) -> 0.55 | R48: =R46+(3*R47) -> 1
O49: LSL | P49: =P46-(3*P47) -> 0.04943 | Q49: =Q46-(3*Q47) -> 0.25 | R49: =R46-(3*R47) -> 0.7

Sheet PPM CT C4
A1: Cycle Time | B1: Code_CT | C1: Test_CT
A2: 0.54545455 | B2: 0.18181818 | C2: 0.13636364
A3: 0.5 | B3: 0.25 | C3: 0.25
A4: 0.55555556 | B4: 0.22222222 | C4: 0.22222222
A5: 0.64285714 | B5: 0.21428571 | C5: 0.21428571
A6: 0.66666667 | B6: 0.22222222 | C6: 0.11111111
A7: 1 | B7: 0.25 | C7: 0.25
A8: 1 | B8: 0.41935484 | C8: 0.22580645
A9: 0.64285714 | B9: 0.28571429 | C9: 0.14285714
A10: 0.58333333 | B10: 0.25 | C10: 0.16666667
A11: 0.94117647 | B11: 0.35294118 | C11: 0.17647059
A12: 0.56666667 | B12: 0.23333333 | C12: 0.16666667
A13: 0.3255814 | B13: 0.13953488 | C13: 0.069767442
... A23: 0.81818182 | B23: 0.36363636 | C23: 0.18181818
O29: Regression Equation
O30: Cycle Time | P30: = | Q30: 0.1055 + 1.585 Code_CT + 0.805 Test_CT
P35: AS-IS | Q35: Cycle time | R35: Code_CT | S35: Test_CT
P36: Mean | Q36: 0.682516 | R36: 0.276037 | S36: 0.173363
P37: SD | Q37: =(Q38-Q39)/6 -> 0.17127733 | R37: =(R38-R39)/6 -> 0.095626667 | S37: =(S38-S39)/6 -> 0.0743905
P38: UCL | Q38: 1.19635 | R38: 0.562917 | S38: 0.396534
P39: LCL | Q39: 0.168686 | R39: -0.010843 | S39: -0.049809
P43: Target | Q43: Cycle time
P44: Mean | Q44: =Q36-S44 -> 0.6142644 | S44: =Q36*10% -> 0.0682516
P45: SD | Q45: 0.25
P48: What if | Q48: Cycle time | R48: Code_CT | S48: Test_CT
P49: Mean | Q49: =0.1055 + (1.585*R49) + (0.805*S49) -> 0.6141725 | R49: 0.245 | S49: 0.1495
P50: SD | Q50: 0.25 | R50: 0.1 | S50: 0.5
P51: USL | Q51: =Q49+(3*Q50) -> 1.3641725 | R51: =R49+(3*R50) -> 0.545 | S51: =S49+(3*S50) -> 1.6495
P52: LSL | Q52: =Q49-(3*Q50) -> -0.1358275 | R52: =R49-(3*R50) -> -0.055 | S52: =S49-(3*S50) -> -1.3505

Sheet PPM DRE C4
A1: DRE | B1: Code Review Per Size
A2: 0.66666667 | B2: 0.045454545
A3: 1 | B3: 0.25
A4: 0.5 | B4: 0.11111111
A5: 0.66666667 | B5: 0.071428571
A6: 1 | B6: 0.11111111
A7: 0.625 | B7: 0.16666667
A8: 0.72727273 | B8: 0.096774194
A9: 0.66666667 | B9: 0.14285714
A10: 0.66666667 | B10: 0.083333333
A11: 0.5 | B11: 0.058823529
A12: 0.66666667 | B12: 0.033333333
A13: 0.66666667 | B13: 0.023255814
... A23: 1 | B23: 0.090909091
N29: Regression Equation
N30: DRE | O30: = | P30: 0.5959 + 1.215 Code Review Per Size
N35: AS-IS | O35: DRE | P35: Code Review Per Size
N36: Mean | O36: 0.716409 | P36: 0.09916
N37: SD | O37: =(O38-O39)/6 -> 0.17984283 | P37: =(P38-P39)/6 -> 0.0330535
N38: UCL | O38: 1.25594 | P38: 0.259628
N39: LCL | O39: 0.176883 | P39: 0.061307
N41: Target | O41: DRE
N42: Mean | O42: 0.8
N43: SD | O43: 0.1
N45: What if | O45: DRE | P45: Code Review Per Size
N46: Mean | O46: =0.5959 + (1.215*P46) -> 0.80245 | P46: 0.17
N47: SD | O47: 0.1 | P47: 0.05
N48: USL | O48: =O46+(3*O47) -> 1.10245 | P48: =P46+(3*P47) -> 0.32
N49: LSL | O49: =O46-3*O47 -> 0.50245 | P49: =P46-3*P47 -> 0.02
