Workbook

Sheet Version History
A5: Date | B5: Version | C5: Description | D5: Prepared by | E5: Reviewed & approved by
A6: 45660 | B6: 1 | C6: Size base Estimation Model First baseline | D6: SEPG Team | E6: SEPG Head
A7: 46174 | B7: 1.4 | C7: Cycle 4 (Jan-May 2026) Size based Estimation - All modules updated | D7: SEPG Team | E7: SEPG Head
A8: 46190 | B8: 2.0 | C8: Cycle 4 Estimation corrected – All module Size and Effort values updated per CMMI L5 size-based estimation guidelines. Productivity=0.18 pt/hr; VAF=1.01; Risk=5%; PM=10%. Sizes: ANS=26, AST=9, BHR=23, CUBE=69, DHR=89, FHTC=53, MST=38, MAT=51, NRM=22, O&M=96, SAH=10, SVS=11. All hardcoded Size/TotalCount cells converted to Excel formulas. Complexity distributions recalibrated per Guidelines sheet. | D8: SEPG Team | E8: SEPG Head
A9: 46245 | B9: 1.0 | C9: Cycle 5 (June-July 2026) Size based Estimation - New workbook covering all 22 modules per the Consolidated User Story Register (107 stories) and CR Log. Methodology inherited from Cycle 4 V2.0: Productivity=0.18 pt/hr, VAF=1.01 (Total rating=36, retained from Cycle 4 baseline, not re-scored), Risk=5%, PM=10%. Complexity per story derived from its logged Effort (hrs) in the User Story Register: <=8 hrs=Low(1), 9-16 hrs=Medium(3), >16 hrs=High(5). Actual Consumed Hrs per module sourced from the Date-Wise Time Sheet (Cycle 5, Jun-Jul 2026) via Module Name mapping; unmapped generic timesheet entries (Dashboard/DevOps/Meetings, 59 hrs) are shown separately and excluded from module actuals. | D9: Mr. Dheeraj Motiyani | E9: Mr. Tapan Khandelwal

Sheet Cycle 5 Summary
A1: JAL REKHA - CYCLE 5 (JUNE-JULY 2026) SIZE-BASED ESTIMATION SUMMARY
A2: Prepared by: Mr. Dheeraj Motiyani, Sr. Business Analyst | Basis: Consolidated User Story Register + Date-Wise Time Sheet (Cycle 5)
A4: Sr. No. | B4: Module | C4: User Stories | D4: Total Size (Points) | E4: Planned Effort (Man-hrs) | F4: Actual Consumed Hrs (Timesheet) | G4: Variance (Man-hrs) | H4: US Register Effort (hrs)
A5: 1 | B5: O&M Billing – Aaklan | C5: 17 | D5: ='OM Billing Est C5'!G25 -> 37 | E5: ='OM Billing Est C5'!C35 -> 238.75278 | F5: ='OM Billing Est C5'!C38 -> 325 | G5: ='OM Billing Est C5'!C39 -> -86.247222 | H5: ='OM Billing Est C5'!C40 -> 218
A6: 2 | B6: Sahbhagita | C6: 11 | D6: ='Sahbhagita Est C5'!G19 -> 19 | E6: ='Sahbhagita Est C5'!C29 -> 122.60278 | F6: ='Sahbhagita Est C5'!C32 -> 271 | G6: ='Sahbhagita Est C5'!C33 -> -148.39722 | H6: ='Sahbhagita Est C5'!C34 -> 104
A7: 3 | B7: Dhara (Reports, Corrections, Disputes) | C7: 8 | D7: ='Dhara Est C5'!G16 -> 14 | E7: ='Dhara Est C5'!C26 -> 90.338889 | F7: ='Dhara Est C5'!C29 -> 112 | G7: ='Dhara Est C5'!C30 -> -21.661111 | H7: ='Dhara Est C5'!C31 -> 82
A8: 4 | B8: Vistrit (Master Module) | C8: 5 | D8: ='Vistrit Est C5'!G13 -> 5 | E8: ='Vistrit Est C5'!C23 -> 32.263889 | F8: ='Vistrit Est C5'!C26 -> 0 | G8: ='Vistrit Est C5'!C27 -> 32.263889 | H8: ='Vistrit Est C5'!C28 -> 34
A9: 5 | B9: FHTC Parinam | C9: 5 | D9: ='FHTC Parinam Est C5'!G13 -> 11 | E9: ='FHTC Parinam Est C5'!C23 -> 70.980556 | F9: ='FHTC Parinam Est C5'!C26 -> 108 | G9: ='FHTC Parinam Est C5'!C27 -> -37.019444 | H9: ='FHTC Parinam Est C5'!C28 -> 56
A10: 6 | B10: BISAC / NIC Asset Integration | C10: 3 | D10: ='BISAC Integration Est C5'!G11 -> 11 | E10: ='BISAC Integration Est C5'!C21 -> 70.980556 | F10: ='BISAC Integration Est C5'!C24 -> 0 | G10: ='BISAC Integration Est C5'!C25 -> 70.980556 | H10: ='BISAC Integration Est C5'!C26 -> 52
A11: 7 | B11: e-Sign via CDAC (Aadhaar) | C11: 4 | D11: ='eSign CDAC Est C5'!G12 -> 16 | E11: ='eSign CDAC Est C5'!C22 -> 103.24444 | F11: ='eSign CDAC Est C5'!C25 -> 0 | G11: ='eSign CDAC Est C5'!C26 -> 103.24444 | H11: ='eSign CDAC Est C5'!C27 -> 82
A12: 8 | B12: Anusharavan (June CR) | C12: 3 | D12: ='Anusharavan Est C5'!G11 -> 3 | E12: ='Anusharavan Est C5'!C21 -> 19.358333 | F12: ='Anusharavan Est C5'!C24 -> 70 | G12: ='Anusharavan Est C5'!C25 -> -50.641667 | H12: ='Anusharavan Est C5'!C26 -> 18
A13: 9 | B13: Cube Testing (June CR) | C13: 5 | D13: ='Cube Testing Est C5'!G13 -> 7 | E13: ='Cube Testing Est C5'!C23 -> 45.169444 | F13: ='Cube Testing Est C5'!C26 -> 345 | G13: ='Cube Testing Est C5'!C27 -> -299.83056 | H13: ='Cube Testing Est C5'!C28 -> 38
A14: 10 | B14: SVS Water Supply Monitoring (June CR) | C14: 4 | D14: ='SVS Est C5'!G12 -> 4 | E14: ='SVS Est C5'!C22 -> 25.811111 | F14: ='SVS Est C5'!C25 -> 105 | G14: ='SVS Est C5'!C26 -> -79.188889 | H14: ='SVS Est C5'!C27 -> 20
A15: 11 | B15: Vistrit OTP & Validation | C15: 2 | D15: ='Vistrit OTP Est C5'!G10 -> 2 | E15: ='Vistrit OTP Est C5'!C20 -> 12.905556 | F15: ='Vistrit OTP Est C5'!C23 -> 0 | G15: ='Vistrit OTP Est C5'!C24 -> 12.905556 | H15: ='Vistrit OTP Est C5'!C25 -> 12
A16: 12 | B16: CMMI Documentation | C16: 2 | D16: ='CMMI Doc Est C5'!G10 -> 10 | E16: ='CMMI Doc Est C5'!C20 -> 64.527778 | F16: ='CMMI Doc Est C5'!C23 -> 200 | G16: ='CMMI Doc Est C5'!C24 -> -135.47222 | H16: ='CMMI Doc Est C5'!C25 -> 100
A17: 13 | B17: O&M Billing Workflow Module (Multi-Level Approval Chain) | C17: 16 | D17: ='OM Billing Workflow Est C5'!G24 -> 48 | E17: ='OM Billing Workflow Est C5'!C34 -> 309.73333 | F17: ='OM Billing Workflow Est C5'!C37 -> 30 | G17: ='OM Billing Workflow Est C5'!C38 -> 279.73333 | H17: ='OM Billing Workflow Est C5'!C39 -> 0
A18: 14 | B18: Material Testing | C18: 3 | D18: ='Material Testing Est C5'!G11 -> 9 | E18: ='Material Testing Est C5'!C21 -> 58.075 | F18: ='Material Testing Est C5'!C24 -> 141 | G18: ='Material Testing Est C5'!C25 -> -82.925 | H18: ='Material Testing Est C5'!C26 -> 42
A19: 15 | B19: Nirmal Module | C19: 4 | D19: ='Nirmal Est C5'!G12 -> 4 | E19: ='Nirmal Est C5'!C22 -> 25.811111 | F19: ='Nirmal Est C5'!C25 -> 32 | G19: ='Nirmal Est C5'!C26 -> -6.1888889 | H19: ='Nirmal Est C5'!C27 -> 28
A20: 16 | B20: AI Module - FHTC Tap Connection Detection | C20: 3 | D20: ='AI Module FHTC Est C5'!G11 -> 15 | E20: ='AI Module FHTC Est C5'!C21 -> 96.791667 | F20: ='AI Module FHTC Est C5'!C24 -> 147 | G20: ='AI Module FHTC Est C5'!C25 -> -50.208333 | H20: ='AI Module FHTC Est C5'!C26 -> 104
A21: 17 | B21: Master Data Module | C21: 3 | D21: ='Master Data Est C5'!G11 -> 5 | E21: ='Master Data Est C5'!C21 -> 32.263889 | F21: ='Master Data Est C5'!C24 -> 16 | G21: ='Master Data Est C5'!C25 -> 16.263889 | H21: ='Master Data Est C5'!C26 -> 30
A22: 18 | B22: Asset Mapping (BISAC) | C22: 2 | D22: ='Asset Mapping Est C5'!G10 -> 6 | E22: ='Asset Mapping Est C5'!C20 -> 38.716667 | F22: ='Asset Mapping Est C5'!C23 -> 16 | G22: ='Asset Mapping Est C5'!C24 -> 22.716667 | H22: ='Asset Mapping Est C5'!C25 -> 22
A23: 19 | B23: Bharosa (Factory Testing) | C23: 2 | D23: ='Bharosa Est C5'!G10 -> 2 | E23: ='Bharosa Est C5'!C20 -> 12.905556 | F23: ='Bharosa Est C5'!C23 -> 7 | G23: ='Bharosa Est C5'!C24 -> 5.9055556 | H23: ='Bharosa Est C5'!C25 -> 14
A24: 20 | B24: Daily Inspection | C24: 2 | D24: ='Daily Inspection Est C5'!G10 -> 4 | E24: ='Daily Inspection Est C5'!C20 -> 25.811111 | F24: ='Daily Inspection Est C5'!C23 -> 20 | G24: ='Daily Inspection Est C5'!C24 -> 5.8111111 | H24: ='Daily Inspection Est C5'!C25 -> 18
A25: 21 | B25: Sopan | C25: 1 | D25: ='Sopan Est C5'!G9 -> 3 | E25: ='Sopan Est C5'!C19 -> 19.358333 | F25: ='Sopan Est C5'!C22 -> 8 | G25: ='Sopan Est C5'!C23 -> 11.358333 | H25: ='Sopan Est C5'!C24 -> 10
A26: 22 | B26: QA - User & Role Management Automation | C26: 2 | D26: ='QA Automation Est C5'!G10 -> 4 | E26: ='QA Automation Est C5'!C20 -> 25.811111 | F26: ='QA Automation Est C5'!C23 -> 10 | G26: ='QA Automation Est C5'!C24 -> 15.811111 | H26: ='QA Automation Est C5'!C25 -> 20
B27: GRAND TOTAL (Cycle 5, 22 modules) | C27: =SUM(C5:C26) -> 107 | D27: =SUM(D5:D26) -> 239 | E27: =SUM(E5:E26) -> 1542.2139 | F27: =SUM(F5:F26) -> 1963 | G27: =SUM(G5:G26) -> -420.78611 | H27: =SUM(H5:H26) -> 1104
A29: Notes:
A30: 1. Complexity per user story is derived from its logged Effort (hrs) in the Consolidated User Story Register: <=8 hrs = Low (weight 1), 9-16 hrs = Medium (weight 3), >16 hrs = High (weight 5). This is an assumption made to fit story-level data into the CMMI size-based model; it has not been independently re-scored against the Guidelines sheet element-by-element.
A31: 2. Productivity (0.18 pt/hr), VAF (1.01, factor Total=36) and Risk (5%) / PM (10%) loadings are retained unchanged from the Cycle 4 V2.0 baseline per SEPG guidelines.
A32: 3. "Actual Consumed Hrs" is aggregated from the Date-Wise Time Sheet (Cycle 5, Jun-Jul 2026) by Module Name, mapped to each estimation sheet. Timesheet entries logged under generic buckets (Dashboard, AzureDevOps, Department Meetings - 59 hrs total) are not attributable to a single module and are excluded from the module rows above; see the "Unmapped Timesheet Hours" row below.
A33: 4. Vistrit, Vistrit OTP & Validation, BISAC/NIC Asset Integration and e-Sign via CDAC did not have a distinctly labelled Module Name in the Cycle 5 timesheet (their effort is likely embedded within Dhara / O&M Billing Workflow timesheet entries); Actual Consumed Hrs for these four modules is shown as 0 rather than estimated.
A34: 5. "US Register Effort (hrs)" is the sum of the Effort (hrs) column already logged against each story in the Consolidated User Story Register - shown as an independent cross-check against the size-based Planned Effort, not an input to it.
A35: 6. The 16 O&M Billing Workflow stories are carried forward unchanged from the Cycle 4 register and have no logged Cycle 5 Effort (hrs) figure (US Register Effort shows 0); complexity for these was defaulted to Medium. The module nonetheless shows 30 actual timesheet hours in Cycle 5 (workflow discussion/requirement-gathering per the June/July MoM), so its Planned-vs-Actual variance should be read with this in mind.
B37: Unmapped Timesheet Hours (Dashboard/DevOps/Meetings) | F37: 59
B38: Grand Total Timesheet Hours (all entries, Cycle 5) | F38: =F27+F37 -> 2022

Sheet Master
A1: Estimation Elements
A2: New Development | B2: Enhancement and customization
A3: Web Page / Screen with no of input fields | B3: Web Page / Screen with no of input fields
A4: Type of exit scenario | B4: Type of exit scenario
A5: No of Validation on the fields | B5: No of Validation on the fields
A6: No of Prefilled fields | B6: No of Prefilled fields
A7: No of API Integrations | B7: No of API Integrations
A8: No API integrations for saving the data | B8: No API integrations for saving the data
A9: Queries or Business rules for the application | B9: Queries or Business rules for the application
A10: No of Integration | B10: No of Integration
A11: mobile App-UI | B11: mobile App-UI
A12: Data Migration | B12: Data Migration
A13: Reports | B13: Reports
A25: Complexity | B25: Type of work | C25: VAF Rating
A26: Low | B26: New Development | C26: 5 | D26: 5 - Very Strong Influence
A27: Medium | B27: Enhancement and customization | C27: 4 | D27: 4 - Strong Influence
A28: High | C28: 3 | D28: 3 - Average Influence
A29: Complex | C29: 2 | D29: 2 - Moderate Influence
C30: 1 | D30: 1- Slight Influence
C31: 0 | D31: 0 - No Influence
A37: Effort Distribution Guidelines
B38: Effort Distribution | C38: Cost
C39: Min | D39: Max
A40: Business Analyst | B40: 0.15 | C40: 4000 | D40: 6000
A41: Solution Architecht | B41: 0.1 | C41: 6000 | D41: 8000
A42: Developer / Data Scientist | B42: 0.4 | C42: 3000 | D42: 5000
A43: Tester | B43: 0.2 | C43: 2500 | D43: 5000
A44: Project Manager | B44: 0.1 | C44: 8000 | D44: 10000
A45: Infrastructure Setup | B45: 0.05 | C45: 3000 | D45: 5000
A46: Business Analyst | B46: 0.15
A47: Solution Architecht | B47: 0.1
A48: Developer / Data Scientist | B48: 0.4
A49: Tester | B49: 0.2
A50: Project Manager | B50: 0.1
A51: Infrastructure Setup | B51: 0.05

Sheet Baseline Productivity 
A3: Type of work | B3: Calculated Productivity | C3: Targated Productivity | D3: Unit
A4: Development & Enhancement | C4: 0.179 | D4: Point / per hour
C9: 1 Point | D9: =1/C4 -> 5.5865922
D10: ~5.6 hours

Sheet Guidelines
B2: Complexity | C2: 1 | D2: 3 | E2: 5
A3: Work Type | B3: Component | C3: Low | D3: Medium | E3: High
A4: Development | B4: Web Page / Screen with no of input fields | C4: 10 | D4: 10-15 | E4: > 15 | F4: Elements Label Graph Tile Grid Pop-up Drop Down Data Entery Field Button Custom Built element | K4: 1
B5: Type of exit scenario | C5: 1 | D5: 1 to 2 | E5: >3 | H5: label | I5: text box
B6: No of Validation on the fields | C6: 1 to 5 | D6: 5 To 10 | E6: >10 | H6: button
B7: No of Prefilled fields | C7: 10 to 30 | D7: 30 to 50 | E7: >50 | H7: drop down
B8: No of API Integrations | C8: 2 | D8: 2 to 5 | E8: > 5 | H8: checkbox
B9: No API integrations for saving the data | C9: 3 | D9: 3 to 5 | E9: >5 | H9: aadhar
B10: Queries or Business rules for the application | C10: No validation or business rules. One data store | D10: No validation or business rules. Up to 3 data stores | E10: Validation or business rules involved. Multiple data stores | H10: samagra integration
B11: No of Integration | C11: 2 | D11: 2 to 5 | E11: >5 | H11: report
B12: mobile App-UI | C12: Static screen | D12: Screen with 2-4 internal components | E12: Screen with external components | H12: MObile app
B13: Data Migration | C13: Master Table | D13: Table with data errors and involves Data validation and cleansing | E13: Table with relationship with data errors and requires data validation and cleansing | H13: submit
B14: Reports | C14: tabular report. <10 columns. 1 data source Elements( Table, PIE chart, Report count: 1-2 | D14: 2-3 data source. Simple (Pie/Bar) chart Elements( Stack,Line etc.) Report type: 3-5 | E14: >3 data source. Multiple complex graphs Elements( Doughnut, Trend analysis etc.) Report type: More than 5 | H14: clear
H15: reset
F19: Code element Data Tranformation Data Pre-processing Custom Build element API creation for UI\UX API Integration

Sheet OM Billing Est C5
B1: Type Of Work | C1: Development | D1: Enhancement and Customization (CR-driven)
B2: Project Name | C2: Jal Rekha
B3: Remark | C3: O&M Billing – Aaklan - Cycle 5 (June-July 2026)
B4: Basis | C4: Consolidated User Story Register (Cycle 5) + Date-Wise Time Sheet (Cycle 5)
D5: Volume/Count of elements | H5: Guidelines
A6: Module + sub Module | B6: User Story ID | C6: Elements (User Story Description - Refer Guidelines) | D6: Low Complexity | E6: Medium complexity | F6: High Complexity | G6: Size | H6: Priority | I6: Status | J6: Sprint | K6: US Register Effort (hrs)
D7: 1 | E7: 3 | F7: 5
A8: O&M Billing – Abstract Report Generation | B8: US-OM-C5-001 | C8: As a GM and Contractor user, I want the Abstract Report auto-generated and available for download from the O&M Billing module so that billing summaries are formally captured without manual preparation. | D8: 0 | E8: 0 | F8: 1 | G8: =D8*$D$7+E8*$E$7+F8*$F$7 -> 5 | H8: High | I8: Done | J8: Sprint 17 | K8: 20
A9: O&M Billing – Contractor Mistake Correction by SQC/TL → GM | B9: US-OM-C5-002 | C9: As a TL (SQC/CSC), I want the ability to add or edit bill data fields on behalf of the Contractor before forwarding to GM so that contractor data entry mistakes are corrected without returning the full bill. | D9: 0 | E9: 1 | F9: 0 | G9: =D9*$D$7+E9*$E$7+F9*$F$7 -> 3 | H9: High | I9: Done | J9: Sprint 17 | K9: 16
A10: O&M Billing – Show All Records on All IDs (GM, SQC) | B10: US-OM-C5-003 | C10: As a GM (PIU) user, I want all O&M billing records from all contractor/firm submissions visible on GM and SQC login so that I do not miss any bill regardless of which login it was submitted from. | D10: 1 | E10: 0 | F10: 0 | G10: =D10*$D$7+E10*$E$7+F10*$F$7 -> 1 | H10: High | I10: Done | J10: Sprint 17 | K10: 8
A11: O&M Billing – Merge PDF of All O&M Bill Documents | B11: US-OM-C5-004 | C11: As a GM and Contractor user, I want all O&M bill documents (approx. 19–20 documents per bill: GM, SQC, Firm, Form 27A, MB, Abstract, etc.) merged into a single PDF for a 3-month consolidated bill so that submission to higher authorities is a single file. | D11: 0 | E11: 1 | F11: 0 | G11: =D11*$D$7+E11*$E$7+F11*$F$7 -> 3 | H11: High | I11: Done | J11: Sprint 17 | K11: 16
A12: O&M Billing – Power Consumption: Contractor & GM Side Changes | B12: US-OM-C5-005 | C12: As a Contractor and GM user, I want the Power Consumption tab updated to include Contract Details (Basic Detail, Intermediate Raw Water Demand) and correct calculation logic so that electricity cost billing is accurate. | D12: 0 | E12: 0 | F12: 1 | G12: =D12*$D$7+E12*$E$7+F12*$F$7 -> 5 | H12: High | I12: In Progress | J12: Sprint 17-18 | K12: 24
A13: O&M Billing – Two New Columns in Water Supply During Construction Bill | B13: US-OM-C5-006 | C13: As a GM user, I want two new columns added to the Water Supply During Construction Bill so that construction-phase water supply data is captured completely. | D13: 1 | E13: 0 | F13: 0 | G13: =D13*$D$7+E13*$E$7+F13*$F$7 -> 1 | H13: Medium | I13: In Progress | J13: Sprint 17 | K13: 8
A14: O&M Billing – O&M Villages: Construction Approval Status | B14: US-OM-C5-007 | C14: As a GM user, I want O&M Villages to include villages where Water Supply During Construction is under consideration or approved so that construction-phase billing is inclusive and accurate. | D14: 1 | E14: 0 | F14: 0 | G14: =D14*$D$7+E14*$E$7+F14*$F$7 -> 1 | H14: Medium | I14: In Progress | J14: Sprint 18 | K14: 8
A15: O&M Billing – Aaklan Contractor Dispute: Dhara Data Discrepancy Window | B15: US-OM-C5-008 | C15: As a Contractor, I want a time-bound window to check Dhara meter reading data and raise a discrepancy before the O&M bill is finalised so that billing disputes are pre-empted and Dhara data is used as the authoritative source. | D15: 0 | E15: 1 | F15: 0 | G15: =D15*$D$7+E15*$E$7+F15*$F$7 -> 3 | H15: High | I15: In Progress | J15: Sprint 18 | K15: 16
A16: O&M Billing – GM: Pump Transformer 10% Deduction Logic | B16: US-OM-C5-009 | C16: As a GM user, I want the consolidated bill to automatically apply a 10% deduction on the total amount when the Pump Transformer column is marked YES so that penalty deductions are system-enforced. | D16: 1 | E16: 0 | F16: 0 | G16: =D16*$D$7+E16*$E$7+F16*$F$7 -> 1 | H16: High | I16: In Progress | J16: Sprint 18 | K16: 8
A17: O&M Billing Workflow – e-Sign via CDAC (Contractor & GM) | B17: US-OM-C5-010 | C17: As a Contractor and GM user, I want all O&M Bill documents digitally signed using e-Sign via CDAC (Aadhaar-based) so that the bill submission process is legally compliant and paperless. | D17: 0 | E17: 0 | F17: 1 | G17: =D17*$D$7+E17*$E$7+F17*$F$7 -> 5 | H17: High | I17: In Progress | J17: Sprint 17-18 | K17: 40
A18: O&M Billing – GM (PIU) Login: Bill PDF (19–20 Docs) & 3-Month Consolidation | B18: US-OM-C5-011 | C18: As a GM (PIU) user, I want to view and download a consolidated Bill PDF comprising 19–20 documents for a 3-month bill cycle so that I can submit a single complete document package to GM (O&M). | D18: 0 | E18: 1 | F18: 0 | G18: =D18*$D$7+E18*$E$7+F18*$F$7 -> 3 | H18: High | I18: Done | J18: Sprint 17 | K18: 12
A19: O&M Billing – Sahbhagita Generate Abstract: Select RA Bill & Tag All | B19: US-OM-C5-012 | C19: As a Sahbhagita PM user, I want to generate an Abstract report by selecting a specific RA Bill number and tagging all activities to that bill so that Sahbhagita billing is linked to O&M billing cycles. | D19: 1 | E19: 0 | F19: 0 | G19: =D19*$D$7+E19*$E$7+F19*$F$7 -> 1 | H19: Medium | I19: Done | J19: Sprint 17 | K19: 8
... A24: O&M Billing - GST Number Integration | B24: US-OM-C5-017 | C24: As a Contractor and GM (PIU) user, I want my GST number captured at the firm/contractor level and reflected on the bill PDF and abstract, so that generated bills are GST-compliant. | D24: 1 | E24: 0 | F24: 0 | G24: =D24*$D$7+E24*$E$7+F24*$F$7 -> 1 | H24: Medium | I24: Open | J24: Sprint 18 | K24: 8
A25: TOTAL O&M BILLING – AAKLAN ESTIMATION (CYCLE 5) | G25: =SUM(G8:G24) -> 37 | K25: =SUM(K8:K24) -> 218
B28: Total Count | G28: =G25 -> 37 | J28: Value added factors
B29: Productivity | C29: 0.18 | J29: Factor | L29: Rating
B30: Size | C30: =G25 -> 37 | D30: Point | J30: Data Communications | L30: 0
B31: Effort | C31: =C30/C29 -> 205.55556 | D31: Man hours | J31: Distributed Data Processing | L31: 0
B32: VAF | C32: =0.65+0.01*$L$44 -> 1.01 | J32: Performance | L32: 0
B33: Risk contingency | C33: 0.05 | J33: Heavily used Configuration | L33: 3
B34: Project Management | C34: 0.1 | J34: Transaction Rate | L34: 4
B35: Total Planned Effort | C35: =C31*C32*(1+C33+C34) -> 238.75278 | D35: Man hours | J35: Online Data Entry | L35: 3
J36: End-User Efficiency | L36: 2
B37: Permissible Range (Man hours) | C37: =C35*1.05 -> 250.69042 | D37: =C35*0.95 -> 226.81514 | J37: Online Update | L37: 1
B38: Actual Consumed Hrs (Timesheet, Cycle 5) | C38: 325 | D38: Man hours | J38: Complex Processing | L38: 3
B39: Variance (Planned - Actual) | C39: =C35-C38 -> -86.247222 | D39: Man hours | J39: Reusability | L39: 4
B40: US Register Total Effort (hrs, cross-check) | C40: =K25 -> 218 | D40: Man hours | J40: Installation Ease | L40: 4
J41: Operational Ease | L41: 4
J42: Multiple Sites | L42: 4
J43: Facilitate Change | L43: 4
J44: Total | L44: =SUM(L30:L43) -> 36

Sheet Sahbhagita Est C5
B1: Type Of Work | C1: Development | D1: Enhancement and Customization (CR-driven)
B2: Project Name | C2: Jal Rekha
B3: Remark | C3: Sahbhagita - Cycle 5 (June-July 2026)
B4: Basis | C4: Consolidated User Story Register (Cycle 5) + Date-Wise Time Sheet (Cycle 5)
D5: Volume/Count of elements | H5: Guidelines
A6: Module + sub Module | B6: User Story ID | C6: Elements (User Story Description - Refer Guidelines) | D6: Low Complexity | E6: Medium complexity | F6: High Complexity | G6: Size | H6: Priority | I6: Status | J6: Sprint | K6: US Register Effort (hrs)
D7: 1 | E7: 3 | F7: 5
A8: Sahbhagita – RA Bill for ISA (replacing CP Manager) | B8: US-SAH-C5-001 | C8: As an ISA Manager user, I want RA Bill functionality moved from CP Manager to ISA Manager login so that ISA-specific billing is role-accurate and ISA can raise bills independently. | D8: 0 | E8: 1 | F8: 0 | G8: =D8*$D$7+E8*$E$7+F8*$F$7 -> 3 | H8: High | I8: Done | J8: Sprint 17 | K8: 12
A9: Sahbhagita – Village-wise & Combined Activity Report | B9: US-SAH-C5-002 | C9: As a GM and ISA user, I want Sahbhagita reports available in both Village-wise and Combined Activity views so that activity tracking is possible at both individual village and aggregate levels. | D9: 0 | E9: 1 | F9: 0 | G9: =D9*$D$7+E9*$E$7+F9*$F$7 -> 3 | H9: High | I9: Done | J9: Sprint 17 | K9: 16
A10: Sahbhagita – Master Activity List Update (22 Combined + 32 Village-wise) | B10: US-SAH-C5-003 | C10: As a system admin, I want the Sahbhagita master activity list updated to the finalised 22 Combined Activities and 32 Village-wise Activities so that all ISA submissions are mapped to the correct master. | D10: 1 | E10: 0 | F10: 0 | G10: =D10*$D$7+E10*$E$7+F10*$F$7 -> 1 | H10: High | I10: Done | J10: Sprint 17 | K10: 8
A11: Sahbhagita – Photo Scan AI: Face & Background Detection (CP Manager Review) | B11: US-SAH-C5-004 | C11: As a CP Manager, I want an AI-based photo scan to detect duplicate face and background at the time of CP Manager review so that fraudulent or repeated activity submissions are flagged automatically. | D11: 0 | E11: 0 | F11: 1 | G11: =D11*$D$7+E11*$E$7+F11*$F$7 -> 5 | H11: Medium | I11: In Progress | J11: Sprint 18 | K11: 20
A12: Sahbhagita – Hyperlink: Village Name → Village Activity → Document Preview | B12: US-SAH-C5-005 | C12: As a GM and ISA user, I want a hyperlink on Village Name in the Sahbhagita report that drills down to Village Activity list and then opens Document Preview popup so that I can review all field evidence without leaving the report. | D12: 1 | E12: 0 | F12: 0 | G12: =D12*$D$7+E12*$E$7+F12*$F$7 -> 1 | H12: Medium | I12: Done | J12: Sprint 17 | K12: 8
A13: Sahbhagita – RA Bill: RA(1) till RA(12) Withhold Bills | B13: US-SAH-C5-006 | C13: As a PM user, I want RA Bill numbers from RA(1) to RA(12) to be supported, with the ability to withhold specific RA Bills so that billing cycles are properly managed per ISA contract. | D13: 1 | E13: 0 | F13: 0 | G13: =D13*$D$7+E13*$E$7+F13*$F$7 -> 1 | H13: Medium | I13: Done | J13: Sprint 17 | K13: 8
A14: Sahbhagita – Customised Report (ISA – Mainly Contractor Convention) | B14: US-SAH-C5-007 | C14: As an ISA user, I want a customised Sahbhagita report primarily aligned to the contractor-convention billing structure so that ISA RA bills are correctly mapped to MPJN billing norms. | D14: 1 | E14: 0 | F14: 0 | G14: =D14*$D$7+E14*$E$7+F14*$F$7 -> 1 | H14: Medium | I14: Done | J14: Sprint 17 | K14: 8
A15: Sahbhagita – Save as Draft for Video, Image & Document (Mobile CR) | B15: US-SAH-C5-008 | C15: As an FE mobile user, I want Save as Draft functionality for activity submissions that include video, image, and document uploads so that field evidence can be captured in stages without losing partial submissions. | D15: 1 | E15: 0 | F15: 0 | G15: =D15*$D$7+E15*$E$7+F15*$F$7 -> 1 | H15: Medium | I15: Done | J15: Sprint 17 | K15: 8
A16: Sahbhagita - Pagination on Approval Pages | B16: US-SAH-C5-009 | C16: As an ISA Manager/CP Manager, I want the Sahbhagita approval listing pages paginated, so that I can review and approve activity records in manageable batches instead of one long scrolling page. | D16: 1 | E16: 0 | F16: 0 | G16: =D16*$D$7+E16*$E$7+F16*$F$7 -> 1 | H16: Medium | I16: Done | J16: Sprint 17 | K16: 6
A17: Sahbhagita - FE Visibility Scoped to Assigned ISA | B17: US-SAH-C5-010 | C17: As an ISA user, I want to see only the Field Executives (FE) specifically mapped to my ISA, so that I don't have to sift through FE records belonging to other ISAs. | D17: 1 | E17: 0 | F17: 0 | G17: =D17*$D$7+E17*$E$7+F17*$F$7 -> 1 | H17: Medium | I17: Done | J17: Sprint 17 | K17: 6
A18: Sahbhagita - Self-Service Password Reset for ISA Login | B18: US-SAH-C5-011 | C18: As an ISA user, I want a self-service password reset option on my login, so that I can regain access without waiting on the admin team. | D18: 1 | E18: 0 | F18: 0 | G18: =D18*$D$7+E18*$E$7+F18*$F$7 -> 1 | H18: Low | I18: Done | J18: Sprint 17 | K18: 4
A19: TOTAL SAHBHAGITA ESTIMATION (CYCLE 5) | G19: =SUM(G8:G18) -> 19 | K19: =SUM(K8:K18) -> 104
B22: Total Count | G22: =G19 -> 19 | J22: Value added factors
B23: Productivity | C23: 0.18 | J23: Factor | L23: Rating
B24: Size | C24: =G19 -> 19 | D24: Point | J24: Data Communications | L24: 0
B25: Effort | C25: =C24/C23 -> 105.55556 | D25: Man hours | J25: Distributed Data Processing | L25: 0
B26: VAF | C26: =0.65+0.01*$L$38 -> 1.01 | J26: Performance | L26: 0
B27: Risk contingency | C27: 0.05 | J27: Heavily used Configuration | L27: 3
B28: Project Management | C28: 0.1 | J28: Transaction Rate | L28: 4
B29: Total Planned Effort | C29: =C25*C26*(1+C27+C28) -> 122.60278 | D29: Man hours | J29: Online Data Entry | L29: 3
J30: End-User Efficiency | L30: 2
B31: Permissible Range (Man hours) | C31: =C29*1.05 -> 128.73292 | D31: =C29*0.95 -> 116.47264 | J31: Online Update | L31: 1
B32: Actual Consumed Hrs (Timesheet, Cycle 5) | C32: 271 | D32: Man hours | J32: Complex Processing | L32: 3
B33: Variance (Planned - Actual) | C33: =C29-C32 -> -148.39722 | D33: Man hours | J33: Reusability | L33: 4
B34: US Register Total Effort (hrs, cross-check) | C34: =K19 -> 104 | D34: Man hours | J34: Installation Ease | L34: 4
J35: Operational Ease | L35: 4
J36: Multiple Sites | L36: 4
J37: Facilitate Change | L37: 4
J38: Total | L38: =SUM(L24:L37) -> 36

Sheet Dhara Est C5
B1: Type Of Work | C1: Development | D1: Enhancement and Customization (CR-driven)
B2: Project Name | C2: Jal Rekha
B3: Remark | C3: Dhara (Reports, Corrections, Disputes) - Cycle 5 (June-July 2026)
B4: Basis | C4: Consolidated User Story Register (Cycle 5) + Date-Wise Time Sheet (Cycle 5)
D5: Volume/Count of elements | H5: Guidelines
A6: Module + sub Module | B6: User Story ID | C6: Elements (User Story Description - Refer Guidelines) | D6: Low Complexity | E6: Medium complexity | F6: High Complexity | G6: Size | H6: Priority | I6: Status | J6: Sprint | K6: US Register Effort (hrs)
D7: 1 | E7: 3 | F7: 5
A8: Dhara – Report Corrections (Approved Village MWSR, DWSR, OHT) | B8: US-DHR-C5-001 | C8: As a GM user, I want Dhara report corrections applied to Approved Village MWSR, DWSR, and OHT report pages so that report data is accurate and error-free for O&M billing purposes. | D8: 0 | E8: 1 | F8: 0 | G8: =D8*$D$7+E8*$E$7+F8*$F$7 -> 3 | H8: High | I8: Done | J8: Sprint 17 | K8: 16
A9: Dhara – Report Format Standardisation (27 May 2026 Format) | B9: US-DHR-C5-002 | C9: As a GM user, I want Dhara reports standardised to the approved format of 27 May 2026 so that all Dhara reports across all logins have consistent column layout, headers, and data ordering. | D9: 0 | E9: 1 | F9: 0 | G9: =D9*$D$7+E9*$E$7+F9*$F$7 -> 3 | H9: High | I9: Done | J9: Sprint 17 | K9: 12
A10: Dhara – Approved Reports & Contractor Dispute Window | B10: US-DHR-C5-003 | C10: As a Contractor user, I want to view GM-approved Dhara meter reading reports and raise a dispute within a defined time window so that incorrect meter data is challenged before O&M billing is finalised. | D10: 0 | E10: 1 | F10: 0 | G10: =D10*$D$7+E10*$E$7+F10*$F$7 -> 3 | H10: High | I10: In Progress | J10: Sprint 17-18 | K10: 16
A11: Dhara – New Dhara Reports Visible on All Jal Rekha Logins | B11: US-DHR-C5-004 | C11: As a CGM, PMU, and higher official user, I want the new Dhara reports (MWSR, DWSR, OHT, UFW) visible on all Jal Rekha logins (not just GM) so that scheme water supply data is accessible at all governance levels. | D11: 1 | E11: 0 | F11: 0 | G11: =D11*$D$7+E11*$E$7+F11*$F$7 -> 1 | H11: High | I11: Done | J11: Sprint 17 | K11: 8
A12: Dhara – Dhara Entry Lock (Approved Data Should Not Change) | B12: US-DHR-C5-005 | C12: As a GM user, I want approved Dhara meter reading entries locked from further changes so that billing data integrity is maintained after GM approval. | D12: 1 | E12: 0 | F12: 0 | G12: =D12*$D$7+E12*$E$7+F12*$F$7 -> 1 | H12: High | I12: Done | J12: Sprint 17 | K12: 8
A13: Dhara – OHT/WTP/Intake Base Capacity Column in Report | B13: US-DHR-C5-006 | C13: As a GM user, I want OHT, WTP, and Intake Base Capacity columns added to the relevant Dhara reports so that water supply adequacy can be assessed against infrastructure capacity. | D13: 1 | E13: 0 | F13: 0 | G13: =D13*$D$7+E13*$E$7+F13*$F$7 -> 1 | H13: Medium | I13: In Progress | J13: Sprint 18 | K13: 8
A14: Dhara - Approved Report Data Correction (Agreed with Kapil Sir) | B14: US-DHR-C5-007 | C14: As a GM (PIU) user, I want the previously identified data discrepancies in the Approved Report corrected as agreed with Kapil Sir, so that approved data accurately reflects the correct figures before it is used downstream for O&M billing. | D14: 1 | E14: 0 | F14: 0 | G14: =D14*$D$7+E14*$E$7+F14*$F$7 -> 1 | H14: High | I14: Done | J14: Sprint 18 | K14: 8
A15: Dhara - Non-Mandatory Remark, Photo Upload, Forward & Backward Options | B15: US-DHR-C5-008 | C15: As a user on any Jal Rekha login, I want the Remark, Photo Upload, Forward and Backward options in Dhara to be available but not mandatory, so that I can use them when relevant without being blocked from submitting. | D15: 1 | E15: 0 | F15: 0 | G15: =D15*$D$7+E15*$E$7+F15*$F$7 -> 1 | H15: High | I15: Done | J15: Sprint 17 | K15: 6
A16: TOTAL DHARA (REPORTS, CORRECTIONS, DISPUTES) ESTIMATION (CYCLE 5) | G16: =SUM(G8:G15) -> 14 | K16: =SUM(K8:K15) -> 82
B19: Total Count | G19: =G16 -> 14 | J19: Value added factors
B20: Productivity | C20: 0.18 | J20: Factor | L20: Rating
B21: Size | C21: =G16 -> 14 | D21: Point | J21: Data Communications | L21: 0
B22: Effort | C22: =C21/C20 -> 77.777778 | D22: Man hours | J22: Distributed Data Processing | L22: 0
B23: VAF | C23: =0.65+0.01*$L$35 -> 1.01 | J23: Performance | L23: 0
B24: Risk contingency | C24: 0.05 | J24: Heavily used Configuration | L24: 3
B25: Project Management | C25: 0.1 | J25: Transaction Rate | L25: 4
B26: Total Planned Effort | C26: =C22*C23*(1+C24+C25) -> 90.338889 | D26: Man hours | J26: Online Data Entry | L26: 3
J27: End-User Efficiency | L27: 2
B28: Permissible Range (Man hours) | C28: =C26*1.05 -> 94.855833 | D28: =C26*0.95 -> 85.821944 | J28: Online Update | L28: 1
B29: Actual Consumed Hrs (Timesheet, Cycle 5) | C29: 112 | D29: Man hours | J29: Complex Processing | L29: 3
B30: Variance (Planned - Actual) | C30: =C26-C29 -> -21.661111 | D30: Man hours | J30: Reusability | L30: 4
B31: US Register Total Effort (hrs, cross-check) | C31: =K16 -> 82 | D31: Man hours | J31: Installation Ease | L31: 4
J32: Operational Ease | L32: 4
J33: Multiple Sites | L33: 4
J34: Facilitate Change | L34: 4
J35: Total | L35: =SUM(L21:L34) -> 36

Sheet Vistrit Est C5
B1: Type Of Work | C1: Development | D1: Enhancement and Customization (CR-driven)
B2: Project Name | C2: Jal Rekha
B3: Remark | C3: Vistrit (Master Module) - Cycle 5 (June-July 2026)
B4: Basis | C4: Consolidated User Story Register (Cycle 5) + Date-Wise Time Sheet (Cycle 5)
D5: Volume/Count of elements | H5: Guidelines
A6: Module + sub Module | B6: User Story ID | C6: Elements (User Story Description - Refer Guidelines) | D6: Low Complexity | E6: Medium complexity | F6: High Complexity | G6: Size | H6: Priority | I6: Status | J6: Sprint | K6: US Register Effort (hrs)
D7: 1 | E7: 3 | F7: 5
A8: Vistrit – WTP Meter Mapping: New Columns (Date, Scheme, PIU, Meter Name) | B8: US-VST-C5-001 | C8: As a GM user, I want new columns – Date, Scheme, PIU, and Meter Name (e.g., Narela-WTP-01) – added to WTP Meter Mapping and Intake Mapping so that asset identification is standardised. | D8: 1 | E8: 0 | F8: 0 | G8: =D8*$D$7+E8*$E$7+F8*$F$7 -> 1 | H8: High | I8: Done | J8: Sprint 17 | K8: 8
A9: Vistrit – OTP Verification for GM Edit/Delete on Scheme, OHT, Bulk Master | B9: US-VST-C5-002 | C9: As a system admin, I want OTP verification applied to GM login when performing Edit or Delete operations on Scheme Village Mapping, OHT Mapping, and Bulk Consumer Mapping so that master data changes are authenticated. | D9: 1 | E9: 0 | F9: 0 | G9: =D9*$D$7+E9*$E$7+F9*$F$7 -> 1 | H9: High | I9: Done | J9: Sprint 17 | K9: 8
A10: Vistrit – Scheme Village Mapping: Testing/Permitted Field Validation & Census Population | B10: US-VST-C5-003 | C10: As a data admin, I want validation applied to Testing and Permitted fields in Scheme Village Mapping and Census Population left open at all levels so that mapping data quality is enforced without blocking census entries. | D10: 1 | E10: 0 | F10: 0 | G10: =D10*$D$7+E10*$E$7+F10*$F$7 -> 1 | H10: Medium | I10: Done | J10: Sprint 17 | K10: 6
A11: Vistrit – OHT Deactivate Bug Fix (OHT Not Visible in FE Login) | B11: US-VST-C5-004 | C11: As an FE user, I want OHTs that are deactivated in Vistrit but active in FE login to be correctly displayed so that field engineers do not miss active OHTs due to a master data deactivation bug. | D11: 1 | E11: 0 | F11: 0 | G11: =D11*$D$7+E11*$E$7+F11*$F$7 -> 1 | H11: High | I11: Done | J11: Sprint 17 | K11: 8
A12: Vistrit – WTP Meter Naming Convention Standardisation | B12: US-VST-C5-005 | C12: As a system admin, I want WTP Meter names standardised to a consistent naming convention (e.g., Narela-WTP-01) across the Vistrit Master module so that meter asset identification is uniform. | D12: 1 | E12: 0 | F12: 0 | G12: =D12*$D$7+E12*$E$7+F12*$F$7 -> 1 | H12: Low | I12: Done | J12: Sprint 17 | K12: 4
A13: TOTAL VISTRIT (MASTER MODULE) ESTIMATION (CYCLE 5) | G13: =SUM(G8:G12) -> 5 | K13: =SUM(K8:K12) -> 34
B16: Total Count | G16: =G13 -> 5 | J16: Value added factors
B17: Productivity | C17: 0.18 | J17: Factor | L17: Rating
B18: Size | C18: =G13 -> 5 | D18: Point | J18: Data Communications | L18: 0
B19: Effort | C19: =C18/C17 -> 27.777778 | D19: Man hours | J19: Distributed Data Processing | L19: 0
B20: VAF | C20: =0.65+0.01*$L$32 -> 1.01 | J20: Performance | L20: 0
B21: Risk contingency | C21: 0.05 | J21: Heavily used Configuration | L21: 3
B22: Project Management | C22: 0.1 | J22: Transaction Rate | L22: 4
B23: Total Planned Effort | C23: =C19*C20*(1+C21+C22) -> 32.263889 | D23: Man hours | J23: Online Data Entry | L23: 3
J24: End-User Efficiency | L24: 2
B25: Permissible Range (Man hours) | C25: =C23*1.05 -> 33.877083 | D25: =C23*0.95 -> 30.650694 | J25: Online Update | L25: 1
B26: Actual Consumed Hrs (Timesheet, Cycle 5) | C26: 0 | D26: Man hours | J26: Complex Processing | L26: 3
B27: Variance (Planned - Actual) | C27: =C23-C26 -> 32.263889 | D27: Man hours | J27: Reusability | L27: 4
B28: US Register Total Effort (hrs, cross-check) | C28: =K13 -> 34 | D28: Man hours | J28: Installation Ease | L28: 4
J29: Operational Ease | L29: 4
J30: Multiple Sites | L30: 4
J31: Facilitate Change | L31: 4
J32: Total | L32: =SUM(L18:L31) -> 36

Sheet FHTC Parinam Est C5
B1: Type Of Work | C1: Development | D1: Enhancement and Customization (CR-driven)
B2: Project Name | C2: Jal Rekha
B3: Remark | C3: FHTC Parinam - Cycle 5 (June-July 2026)
B4: Basis | C4: Consolidated User Story Register (Cycle 5) + Date-Wise Time Sheet (Cycle 5)
D5: Volume/Count of elements | H5: Guidelines
A6: Module + sub Module | B6: User Story ID | C6: Elements (User Story Description - Refer Guidelines) | D6: Low Complexity | E6: Medium complexity | F6: High Complexity | G6: Size | H6: Priority | I6: Status | J6: Sprint | K6: US Register Effort (hrs)
D7: 1 | E7: 3 | F7: 5
A8: FHTC Parinam – Nasamajh Family Head ID & Add Connection | B8: US-FHTC-C5-001 | C8: As a Contractor user, I want to access Family Head ID for Nasamajh (uncategorised) families with an upper cap of 3 household connections per family and add tap connections for them so that all eligible households including uncategorised families are covered. | D8: 0 | E8: 1 | F8: 0 | G8: =D8*$D$7+E8*$E$7+F8*$F$7 -> 3 | H8: High | I8: In Progress | J8: Sprint 17 | K8: 16
A9: FHTC Parinam – FE Name Shown in Reports | B9: US-FHTC-C5-002 | C9: As a GM user, I want the FE (Field Engineer) name to appear in FHTC Parinam reports so that inspection accountability is traceable at the individual FE level. | D9: 1 | E9: 0 | F9: 0 | G9: =D9*$D$7+E9*$E$7+F9*$F$7 -> 1 | H9: Medium | I9: Done | J9: Sprint 17 | K9: 4
A10: FHTC Parinam – Contractor Search Option | B10: US-FHTC-C5-003 | C10: As a Contractor user, I want a search option on the FHTC Parinam Contractor login page so that I can locate specific tap connection records quickly across large datasets. | D10: 1 | E10: 0 | F10: 0 | G10: =D10*$D$7+E10*$E$7+F10*$F$7 -> 1 | H10: Medium | I10: Done | J10: Sprint 17 | K10: 4
A11: FHTC Parinam – Samagra API Integration for Household Data | B11: US-FHTC-C5-004 | C11: As a system developer, I want Samagra API integrated with FHTC Parinam so that household data (Family Head ID, Member ID, address) is auto-fetched from the state Samagra citizen database without manual entry. | D11: 0 | E11: 0 | F11: 1 | G11: =D11*$D$7+E11*$E$7+F11*$F$7 -> 5 | H11: High | I11: In Progress | J11: Sprint 17-18 | K11: 24
A12: FHTC Parinam - Multiple Surveys per Samagra ID | B12: US-FHTC-C5-005 | C12: As an FE/GM (PIU) user, I want the system to allow more than one survey to be recorded against the same FHTC Samagra ID, so that genuine repeat/revisit surveys aren't blocked by a false duplicate restriction. | D12: 1 | E12: 0 | F12: 0 | G12: =D12*$D$7+E12*$E$7+F12*$F$7 -> 1 | H12: Medium | I12: UAT Done | J12: Sprint 18 | K12: 8
A13: TOTAL FHTC PARINAM ESTIMATION (CYCLE 5) | G13: =SUM(G8:G12) -> 11 | K13: =SUM(K8:K12) -> 56
B16: Total Count | G16: =G13 -> 11 | J16: Value added factors
B17: Productivity | C17: 0.18 | J17: Factor | L17: Rating
B18: Size | C18: =G13 -> 11 | D18: Point | J18: Data Communications | L18: 0
B19: Effort | C19: =C18/C17 -> 61.111111 | D19: Man hours | J19: Distributed Data Processing | L19: 0
B20: VAF | C20: =0.65+0.01*$L$32 -> 1.01 | J20: Performance | L20: 0
B21: Risk contingency | C21: 0.05 | J21: Heavily used Configuration | L21: 3
B22: Project Management | C22: 0.1 | J22: Transaction Rate | L22: 4
B23: Total Planned Effort | C23: =C19*C20*(1+C21+C22) -> 70.980556 | D23: Man hours | J23: Online Data Entry | L23: 3
J24: End-User Efficiency | L24: 2
B25: Permissible Range (Man hours) | C25: =C23*1.05 -> 74.529583 | D25: =C23*0.95 -> 67.431528 | J25: Online Update | L25: 1
B26: Actual Consumed Hrs (Timesheet, Cycle 5) | C26: 108 | D26: Man hours | J26: Complex Processing | L26: 3
B27: Variance (Planned - Actual) | C27: =C23-C26 -> -37.019444 | D27: Man hours | J27: Reusability | L27: 4
B28: US Register Total Effort (hrs, cross-check) | C28: =K13 -> 56 | D28: Man hours | J28: Installation Ease | L28: 4
J29: Operational Ease | L29: 4
J30: Multiple Sites | L30: 4
J31: Facilitate Change | L31: 4
J32: Total | L32: =SUM(L18:L31) -> 36

Sheet BISAC Integration Est C5
B1: Type Of Work | C1: Development | D1: Enhancement and Customization (CR-driven)
B2: Project Name | C2: Jal Rekha
B3: Remark | C3: BISAC / NIC Asset Integration - Cycle 5 (June-July 2026)
B4: Basis | C4: Consolidated User Story Register (Cycle 5) + Date-Wise Time Sheet (Cycle 5)
D5: Volume/Count of elements | H5: Guidelines
A6: Module + sub Module | B6: User Story ID | C6: Elements (User Story Description - Refer Guidelines) | D6: Low Complexity | E6: Medium complexity | F6: High Complexity | G6: Size | H6: Priority | I6: Status | J6: Sprint | K6: US Register Effort (hrs)
D7: 1 | E7: 3 | F7: 5
A8: BISAC – NIC Asset ID Mapping (Asset & Junction Mapping) | B8: US-BISAC-C5-001 | C8: As a system admin, I want NIC Asset IDs integrated with BISAC for Junction-to-Junction Map, Asset Mapping, and Pipeline Tracking so that Jal Rekha asset data is aligned with the national GIS system. | D8: 0 | E8: 0 | F8: 1 | G8: =D8*$D$7+E8*$E$7+F8*$F$7 -> 5 | H8: High | I8: In Progress | J8: Sprint 18 | K8: 24
A9: BISAC – Pipeline Mapping with BISAC Junction Data | B9: US-BISAC-C5-002 | C9: As a project manager, I want pipeline asset data mapped using BISAC Junction-to-Junction track data so that complete pipeline route and network is visualised on the Jal Rekha GIS portal. | D9: 0 | E9: 0 | F9: 1 | G9: =D9*$D$7+E9*$E$7+F9*$F$7 -> 5 | H9: High | I9: In Progress | J9: Sprint 18 | K9: 20
A10: BISAC – Village LGD Code Integration (Village without LGD = Habitation) | B10: US-BISAC-C5-003 | C10: As a data admin, I want BISAC LGD Code logic applied so that villages without an LGD Code are automatically classified as Habitations so that data quality is maintained across BISAC and LGD master sources. | D10: 1 | E10: 0 | F10: 0 | G10: =D10*$D$7+E10*$E$7+F10*$F$7 -> 1 | H10: Medium | I10: Done | J10: Sprint 17 | K10: 8
A11: TOTAL BISAC / NIC ASSET INTEGRATION ESTIMATION (CYCLE 5) | G11: =SUM(G8:G10) -> 11 | K11: =SUM(K8:K10) -> 52
B14: Total Count | G14: =G11 -> 11 | J14: Value added factors
B15: Productivity | C15: 0.18 | J15: Factor | L15: Rating
B16: Size | C16: =G11 -> 11 | D16: Point | J16: Data Communications | L16: 0
B17: Effort | C17: =C16/C15 -> 61.111111 | D17: Man hours | J17: Distributed Data Processing | L17: 0
B18: VAF | C18: =0.65+0.01*$L$30 -> 1.01 | J18: Performance | L18: 0
B19: Risk contingency | C19: 0.05 | J19: Heavily used Configuration | L19: 3
B20: Project Management | C20: 0.1 | J20: Transaction Rate | L20: 4
B21: Total Planned Effort | C21: =C17*C18*(1+C19+C20) -> 70.980556 | D21: Man hours | J21: Online Data Entry | L21: 3
J22: End-User Efficiency | L22: 2
B23: Permissible Range (Man hours) | C23: =C21*1.05 -> 74.529583 | D23: =C21*0.95 -> 67.431528 | J23: Online Update | L23: 1
B24: Actual Consumed Hrs (Timesheet, Cycle 5) | C24: 0 | D24: Man hours | J24: Complex Processing | L24: 3
B25: Variance (Planned - Actual) | C25: =C21-C24 -> 70.980556 | D25: Man hours | J25: Reusability | L25: 4
B26: US Register Total Effort (hrs, cross-check) | C26: =K11 -> 52 | D26: Man hours | J26: Installation Ease | L26: 4
J27: Operational Ease | L27: 4
J28: Multiple Sites | L28: 4
J29: Facilitate Change | L29: 4
J30: Total | L30: =SUM(L16:L29) -> 36

Sheet eSign CDAC Est C5
B1: Type Of Work | C1: Development | D1: Enhancement and Customization (CR-driven)
B2: Project Name | C2: Jal Rekha
B3: Remark | C3: e-Sign via CDAC (Aadhaar) - Cycle 5 (June-July 2026)
B4: Basis | C4: Consolidated User Story Register (Cycle 5) + Date-Wise Time Sheet (Cycle 5)
D5: Volume/Count of elements | H5: Guidelines
A6: Module + sub Module | B6: User Story ID | C6: Elements (User Story Description - Refer Guidelines) | D6: Low Complexity | E6: Medium complexity | F6: High Complexity | G6: Size | H6: Priority | I6: Status | J6: Sprint | K6: US Register Effort (hrs)
D7: 1 | E7: 3 | F7: 5
A8: e-Sign CDAC – FE e-Sign via Mobile/Web (All Logins) | B8: US-ESIGN-C5-001 | C8: As a Field Engineer, I want to e-Sign inspection records and reports using CDAC Aadhaar-based e-Sign so that digital signatures are legally valid and the system is fully paperless. | D8: 0 | E8: 0 | F8: 1 | G8: =D8*$D$7+E8*$E$7+F8*$F$7 -> 5 | H8: High | I8: In Progress | J8: Sprint 17-18 | K8: 30
A9: e-Sign CDAC – Contractor/Firm e-Sign for O&M Bill Documents | B9: US-ESIGN-C5-002 | C9: As a Contractor user, I want to e-Sign the O&M Bill Submission Letter, Abstract, and Tax Invoice using CDAC e-Sign so that bill submission is legally compliant without physical signatures. | D9: 0 | E9: 0 | F9: 1 | G9: =D9*$D$7+E9*$E$7+F9*$F$7 -> 5 | H9: High | I9: In Progress | J9: Sprint 17-18 | K9: 20
A10: e-Sign CDAC – TL (PMC) Recommendation Letter (E-Office Generated) | B10: US-ESIGN-C5-003 | C10: As a TL (PMC) user, I want to generate and e-Sign the Recommendation Letter as an E-Office generated document via CDAC so that the PMC review is formally certified. | D10: 0 | E10: 1 | F10: 0 | G10: =D10*$D$7+E10*$E$7+F10*$F$7 -> 3 | H10: Medium | I10: In Progress | J10: Sprint 18 | K10: 16
A11: e-Sign CDAC – TL (SQC) & TL (PMC) Account Office Jal Rekha Integration | B11: US-ESIGN-C5-004 | C11: As a TL (SQC) and TL (PMC) user, I want CDAC e-Sign integrated with Jal Rekha Account Office workflow so that billing documents are routed and signed digitally through the Account Office system. | D11: 0 | E11: 1 | F11: 0 | G11: =D11*$D$7+E11*$E$7+F11*$F$7 -> 3 | H11: Medium | I11: In Progress | J11: Sprint 18 | K11: 16
A12: TOTAL E-SIGN VIA CDAC (AADHAAR) ESTIMATION (CYCLE 5) | G12: =SUM(G8:G11) -> 16 | K12: =SUM(K8:K11) -> 82
B15: Total Count | G15: =G12 -> 16 | J15: Value added factors
B16: Productivity | C16: 0.18 | J16: Factor | L16: Rating
B17: Size | C17: =G12 -> 16 | D17: Point | J17: Data Communications | L17: 0
B18: Effort | C18: =C17/C16 -> 88.888889 | D18: Man hours | J18: Distributed Data Processing | L18: 0
B19: VAF | C19: =0.65+0.01*$L$31 -> 1.01 | J19: Performance | L19: 0
B20: Risk contingency | C20: 0.05 | J20: Heavily used Configuration | L20: 3
B21: Project Management | C21: 0.1 | J21: Transaction Rate | L21: 4
B22: Total Planned Effort | C22: =C18*C19*(1+C20+C21) -> 103.24444 | D22: Man hours | J22: Online Data Entry | L22: 3
J23: End-User Efficiency | L23: 2
B24: Permissible Range (Man hours) | C24: =C22*1.05 -> 108.40667 | D24: =C22*0.95 -> 98.082222 | J24: Online Update | L24: 1
B25: Actual Consumed Hrs (Timesheet, Cycle 5) | C25: 0 | D25: Man hours | J25: Complex Processing | L25: 3
B26: Variance (Planned - Actual) | C26: =C22-C25 -> 103.24444 | D26: Man hours | J26: Reusability | L26: 4
B27: US Register Total Effort (hrs, cross-check) | C27: =K12 -> 82 | D27: Man hours | J27: Installation Ease | L27: 4
J28: Operational Ease | L28: 4
J29: Multiple Sites | L29: 4
J30: Facilitate Change | L30: 4
J31: Total | L31: =SUM(L17:L30) -> 36

Sheet Anusharavan Est C5
B1: Type Of Work | C1: Development | D1: Enhancement and Customization (CR-driven)
B2: Project Name | C2: Jal Rekha
B3: Remark | C3: Anusharavan (June CR) - Cycle 5 (June-July 2026)
B4: Basis | C4: Consolidated User Story Register (Cycle 5) + Date-Wise Time Sheet (Cycle 5)
D5: Volume/Count of elements | H5: Guidelines
A6: Module + sub Module | B6: User Story ID | C6: Elements (User Story Description - Refer Guidelines) | D6: Low Complexity | E6: Medium complexity | F6: High Complexity | G6: Size | H6: Priority | I6: Status | J6: Sprint | K6: US Register Effort (hrs)
D7: 1 | E7: 3 | F7: 5
A8: Anusharavan – Multi-Date in Report: FE RFI Submission Date & Block Name | B8: US-ANS-C5-001 | C8: As a GM user, I want the Anusharavan RFI report to include multiple dates (FE RFI Submission Date alongside inspection date) and Block Name column so that inspection traceability is enhanced. | D8: 1 | E8: 0 | F8: 0 | G8: =D8*$D$7+E8*$E$7+F8*$F$7 -> 1 | H8: High | I8: Done | J8: Sprint 17 | K8: 8
A9: Anusharavan – OHT Search Option During RFI | B9: US-ANS-C5-002 | C9: As a Contractor and FE user, I want an OHT search option during the RFI creation process so that the correct OHT can be quickly identified without scrolling through large dropdown lists. | D9: 1 | E9: 0 | F9: 0 | G9: =D9*$D$7+E9*$E$7+F9*$F$7 -> 1 | H9: Medium | I9: Done | J9: Sprint 17 | K9: 6
A10: Anusharavan – Remove Mandatory GPS/Village for Intake, WTP, MBR, RWPM, CWPM | B10: US-ANS-C5-003 | C10: As a Contractor user, I want District, Block, GP, and Village selection to be non-mandatory for Intake, WTP, MBR, RWPM, and CWPM components during RFI creation so that non-site-specific components can be registered without location barrier. | D10: 1 | E10: 0 | F10: 0 | G10: =D10*$D$7+E10*$E$7+F10*$F$7 -> 1 | H10: Medium | I10: Done | J10: Sprint 17 | K10: 4
A11: TOTAL ANUSHARAVAN (JUNE CR) ESTIMATION (CYCLE 5) | G11: =SUM(G8:G10) -> 3 | K11: =SUM(K8:K10) -> 18
B14: Total Count | G14: =G11 -> 3 | J14: Value added factors
B15: Productivity | C15: 0.18 | J15: Factor | L15: Rating
B16: Size | C16: =G11 -> 3 | D16: Point | J16: Data Communications | L16: 0
B17: Effort | C17: =C16/C15 -> 16.666667 | D17: Man hours | J17: Distributed Data Processing | L17: 0
B18: VAF | C18: =0.65+0.01*$L$30 -> 1.01 | J18: Performance | L18: 0
B19: Risk contingency | C19: 0.05 | J19: Heavily used Configuration | L19: 3
B20: Project Management | C20: 0.1 | J20: Transaction Rate | L20: 4
B21: Total Planned Effort | C21: =C17*C18*(1+C19+C20) -> 19.358333 | D21: Man hours | J21: Online Data Entry | L21: 3
J22: End-User Efficiency | L22: 2
B23: Permissible Range (Man hours) | C23: =C21*1.05 -> 20.32625 | D23: =C21*0.95 -> 18.390417 | J23: Online Update | L23: 1
B24: Actual Consumed Hrs (Timesheet, Cycle 5) | C24: 70 | D24: Man hours | J24: Complex Processing | L24: 3
B25: Variance (Planned - Actual) | C25: =C21-C24 -> -50.641667 | D25: Man hours | J25: Reusability | L25: 4
B26: US Register Total Effort (hrs, cross-check) | C26: =K11 -> 18 | D26: Man hours | J26: Installation Ease | L26: 4
J27: Operational Ease | L27: 4
J28: Multiple Sites | L28: 4
J29: Facilitate Change | L29: 4
J30: Total | L30: =SUM(L16:L29) -> 36

Sheet Cube Testing Est C5
B1: Type Of Work | C1: Development | D1: Enhancement and Customization (CR-driven)
B2: Project Name | C2: Jal Rekha
B3: Remark | C3: Cube Testing (June CR) - Cycle 5 (June-July 2026)
B4: Basis | C4: Consolidated User Story Register (Cycle 5) + Date-Wise Time Sheet (Cycle 5)
D5: Volume/Count of elements | H5: Guidelines
A6: Module + sub Module | B6: User Story ID | C6: Elements (User Story Description - Refer Guidelines) | D6: Low Complexity | E6: Medium complexity | F6: High Complexity | G6: Size | H6: Priority | I6: Status | J6: Sprint | K6: US Register Effort (hrs)
D7: 1 | E7: 3 | F7: 5
A8: Cube Testing – Show Rejected Data to Contractor | B8: US-CUBE-C5-001 | C8: As a Contractor user, I want to see rejected cube test records in my login so that I can re-submit or address the rejection reason without contacting GM separately. | D8: 1 | E8: 0 | F8: 0 | G8: =D8*$D$7+E8*$E$7+F8*$F$7 -> 1 | H8: High | I8: Done | J8: Sprint 17 | K8: 6
A9: Cube Testing – Cube ID Generated Before Image Upload | B9: US-CUBE-C5-002 | C9: As a Contractor user, I want the Cube Test ID to be generated first before uploading images so that images are linked to a confirmed Cube ID and cannot be submitted without a valid record. | D9: 1 | E9: 0 | F9: 0 | G9: =D9*$D$7+E9*$E$7+F9*$F$7 -> 1 | H9: High | I9: Done | J9: Sprint 17 | K9: 6
A10: Cube Testing – Filter Bed Sub-Component Under WTP | B10: US-CUBE-C5-003 | C10: As a Contractor user, I want 'Filter Bed' added as a sub-component under the WTP component in the Cube Testing module so that filter bed quality testing is properly recorded. | D10: 1 | E10: 0 | F10: 0 | G10: =D10*$D$7+E10*$E$7+F10*$F$7 -> 1 | H10: Low | I10: Done | J10: Sprint 17 | K10: 4
A11: Cube Testing - Re-Inspection Loop (2nd Loop after GM Rejection) | B11: US-CUBE-C5-004 | C11: As an FE/GM/Contractor/SQC/TPIA user, I want a working re-inspection loop so a rejected cube record cycles back through FE to GM to Contractor, back to GM, then SQC/TPIA, then to a newly assigned FE if applicable, so that corrections are fully re-verified through the quality chain. | D11: 0 | E11: 1 | F11: 0 | G11: =D11*$D$7+E11*$E$7+F11*$F$7 -> 3 | H11: High | I11: Done | J11: Sprint 18 | K11: 16
A12: Cube Testing - Optional Image Upload on Second RFI Loop | B12: US-CUBE-C5-005 | C12: As an FE/Contractor user, I want image upload to be optional (not mandatory) on the second RFI loop pass for Cube Testing, so that minor re-inspection corrections aren't blocked by recapturing images already provided the first time. | D12: 1 | E12: 0 | F12: 0 | G12: =D12*$D$7+E12*$E$7+F12*$F$7 -> 1 | H12: Medium | I12: Done | J12: Sprint 18 | K12: 6
A13: TOTAL CUBE TESTING (JUNE CR) ESTIMATION (CYCLE 5) | G13: =SUM(G8:G12) -> 7 | K13: =SUM(K8:K12) -> 38
B16: Total Count | G16: =G13 -> 7 | J16: Value added factors
B17: Productivity | C17: 0.18 | J17: Factor | L17: Rating
B18: Size | C18: =G13 -> 7 | D18: Point | J18: Data Communications | L18: 0
B19: Effort | C19: =C18/C17 -> 38.888889 | D19: Man hours | J19: Distributed Data Processing | L19: 0
B20: VAF | C20: =0.65+0.01*$L$32 -> 1.01 | J20: Performance | L20: 0
B21: Risk contingency | C21: 0.05 | J21: Heavily used Configuration | L21: 3
B22: Project Management | C22: 0.1 | J22: Transaction Rate | L22: 4
B23: Total Planned Effort | C23: =C19*C20*(1+C21+C22) -> 45.169444 | D23: Man hours | J23: Online Data Entry | L23: 3
J24: End-User Efficiency | L24: 2
B25: Permissible Range (Man hours) | C25: =C23*1.05 -> 47.427917 | D25: =C23*0.95 -> 42.910972 | J25: Online Update | L25: 1
B26: Actual Consumed Hrs (Timesheet, Cycle 5) | C26: 345 | D26: Man hours | J26: Complex Processing | L26: 3
B27: Variance (Planned - Actual) | C27: =C23-C26 -> -299.83056 | D27: Man hours | J27: Reusability | L27: 4
B28: US Register Total Effort (hrs, cross-check) | C28: =K13 -> 38 | D28: Man hours | J28: Installation Ease | L28: 4
J29: Operational Ease | L29: 4
J30: Multiple Sites | L30: 4
J31: Facilitate Change | L31: 4
J32: Total | L32: =SUM(L18:L31) -> 36

Sheet SVS Est C5
B1: Type Of Work | C1: Development | D1: Enhancement and Customization (CR-driven)
B2: Project Name | C2: Jal Rekha
B3: Remark | C3: SVS Water Supply Monitoring (June CR) - Cycle 5 (June-July 2026)
B4: Basis | C4: Consolidated User Story Register (Cycle 5) + Date-Wise Time Sheet (Cycle 5)
D5: Volume/Count of elements | H5: Guidelines
A6: Module + sub Module | B6: User Story ID | C6: Elements (User Story Description - Refer Guidelines) | D6: Low Complexity | E6: Medium complexity | F6: High Complexity | G6: Size | H6: Priority | I6: Status | J6: Sprint | K6: US Register Effort (hrs)
D7: 1 | E7: 3 | F7: 5
A8: SVS – Bilingual Conversion (Hindi/English) for Water Supply Entry Page | B8: US-SVS-C5-001 | C8: As an MP government user, I want the SVS Daily Water Supply entry page to support bilingual labels (Hindi and English) and report column headers to be in Hindi so that GP-level users can operate in their native language. | D8: 1 | E8: 0 | F8: 0 | G8: =D8*$D$7+E8*$E$7+F8*$F$7 -> 1 | H8: High | I8: Done | J8: Sprint 17 | K8: 8
A9: SVS – Login-Specific District, Block, GP Auto-Selection | B9: US-SVS-C5-002 | C9: As a GP or Block-level user, I want District, Block, and GP pre-selected according to my login credentials so that I do not need to manually navigate the location hierarchy on every submission. | D9: 1 | E9: 0 | F9: 0 | G9: =D9*$D$7+E9*$E$7+F9*$F$7 -> 1 | H9: High | I9: Done | J9: Sprint 17 | K9: 4
A10: SVS – Additional Reason for NO Supply & Spelling Correction | B10: US-SVS-C5-003 | C10: As a GP user, I want one additional reason option added to the NO supply dropdown and any spelling errors in existing reason options corrected so that supply failure recording is accurate. | D10: 1 | E10: 0 | F10: 0 | G10: =D10*$D$7+E10*$E$7+F10*$F$7 -> 1 | H10: Medium | I10: Done | J10: Sprint 17 | K10: 4
A11: SVS – Remove JJM ID and Village Status Fields | B11: US-SVS-C5-004 | C11: As a PHE department stakeholder, I want the JJM ID field and Village Status field removed from the SVS Daily Water Supply monitoring form so that the form is simplified to current operational requirements. | D11: 1 | E11: 0 | F11: 0 | G11: =D11*$D$7+E11*$E$7+F11*$F$7 -> 1 | H11: Medium | I11: Done | J11: Sprint 17 | K11: 4
A12: TOTAL SVS WATER SUPPLY MONITORING (JUNE CR) ESTIMATION (CYCLE 5) | G12: =SUM(G8:G11) -> 4 | K12: =SUM(K8:K11) -> 20
B15: Total Count | G15: =G12 -> 4 | J15: Value added factors
B16: Productivity | C16: 0.18 | J16: Factor | L16: Rating
B17: Size | C17: =G12 -> 4 | D17: Point | J17: Data Communications | L17: 0
B18: Effort | C18: =C17/C16 -> 22.222222 | D18: Man hours | J18: Distributed Data Processing | L18: 0
B19: VAF | C19: =0.65+0.01*$L$31 -> 1.01 | J19: Performance | L19: 0
B20: Risk contingency | C20: 0.05 | J20: Heavily used Configuration | L20: 3
B21: Project Management | C21: 0.1 | J21: Transaction Rate | L21: 4
B22: Total Planned Effort | C22: =C18*C19*(1+C20+C21) -> 25.811111 | D22: Man hours | J22: Online Data Entry | L22: 3
J23: End-User Efficiency | L23: 2
B24: Permissible Range (Man hours) | C24: =C22*1.05 -> 27.101667 | D24: =C22*0.95 -> 24.520556 | J24: Online Update | L24: 1
B25: Actual Consumed Hrs (Timesheet, Cycle 5) | C25: 105 | D25: Man hours | J25: Complex Processing | L25: 3
B26: Variance (Planned - Actual) | C26: =C22-C25 -> -79.188889 | D26: Man hours | J26: Reusability | L26: 4
B27: US Register Total Effort (hrs, cross-check) | C27: =K12 -> 20 | D27: Man hours | J27: Installation Ease | L27: 4
J28: Operational Ease | L28: 4
J29: Multiple Sites | L29: 4
J30: Facilitate Change | L30: 4
J31: Total | L31: =SUM(L17:L30) -> 36

Sheet Vistrit OTP Est C5
B1: Type Of Work | C1: Development | D1: Enhancement and Customization (CR-driven)
B2: Project Name | C2: Jal Rekha
B3: Remark | C3: Vistrit OTP & Validation - Cycle 5 (June-July 2026)
B4: Basis | C4: Consolidated User Story Register (Cycle 5) + Date-Wise Time Sheet (Cycle 5)
D5: Volume/Count of elements | H5: Guidelines
A6: Module + sub Module | B6: User Story ID | C6: Elements (User Story Description - Refer Guidelines) | D6: Low Complexity | E6: Medium complexity | F6: High Complexity | G6: Size | H6: Priority | I6: Status | J6: Sprint | K6: US Register Effort (hrs)
D7: 1 | E7: 3 | F7: 5
A8: Vistrit – OTP Verification on Scheme/OHT/Bulk Master (GM Edit/Delete) | B8: US-VST-OTP-C5-001 | C8: As a GM user, I want OTP verification required before performing Edit or Delete on Scheme Village Mapping, OHT Mapping, and Bulk Consumer Master so that unauthorised master data changes are prevented. | D8: 1 | E8: 0 | F8: 0 | G8: =D8*$D$7+E8*$E$7+F8*$F$7 -> 1 | H8: High | I8: Done | J8: Sprint 17 | K8: 8
A9: Vistrit – Scheme Village Mapping: Duplicate Village Validation | B9: US-VST-OTP-C5-002 | C9: As a data admin, I want duplicate village mapping validation applied across schemes so that a village is not accidentally mapped to multiple schemes resulting in data conflicts. | D9: 1 | E9: 0 | F9: 0 | G9: =D9*$D$7+E9*$E$7+F9*$F$7 -> 1 | H9: Medium | I9: Done | J9: Sprint 17 | K9: 4
A10: TOTAL VISTRIT OTP & VALIDATION ESTIMATION (CYCLE 5) | G10: =SUM(G8:G9) -> 2 | K10: =SUM(K8:K9) -> 12
