Workbook

Sheet Version History
A5: Date | B5: Version | C5: Description | D5: Prepared by | E5: Reviewed & approved by
A6: 45660 | B6: 1 | C6: Size base Estimation Model First baseline | D6: SEPG Team | E6: SEPG Head
A7: 46174 | B7: 1.4 | C7: Cycle 4 (Jan-May 2026) Size based Estimation - All modules updated | D7: SEPG Team | E7: SEPG Head
A8: 46190 | B8: 2.0 | C8: Cycle 4 Estimation corrected – All module Size and Effort values updated per CMMI L5 size-based estimation guidelines. Productivity=0.18 pt/hr; VAF=1.01; Risk=5%; PM=10%. Sizes: ANS=26, AST=9, BHR=23, CUBE=69, DHR=89, FHTC=53, MST=38, MAT=51, NRM=22, O&M=96, SAH=10, SVS=11. All hardcoded Size/TotalCount cells converted to Excel formulas. Complexity distributions recalibrated per Guidelines sheet. | D8: SEPG Team | E8: SEPG Head
A9: 46314 | B9: 3.0 | C9: Cycle 5 (Jun-Sep 2026) Size based Estimation - all modules. Productivity=0.19 pt/hr (1 point = ~5.26 hrs, revised from 0.179); VAF=1.01; Risk=5%; PM=10%. Sources: Jun-Sep MoMs, PSRs, Sprint 17-20 user stories, timesheet. Total size=475. Sizes: O&M=136, SAH=30, DHR=46, MST=22, FHTC=15, CUBE=9, MAT=10, NRM=16, SVS=20, SVS-GP=27, ANS=6, AST=7, BHR=5, AI=15, CMMI=15, ESIGN=21, BISAC/BISAG=21, OTH=54. | D9: SEPG Team | E9: SEPG Head

Sheet Master
A1: Estimation Elements
A2: New Development | B2: Enhancement and customization
A3: Web Page / Screen with no of input fields | B3: Web Page / Screen with no of input fields
A4: Type of exit scenario | B4: Type of exit scenario
A5: No of Validation on the fields | B5: No of Validation on the fields
A6: No of Prefilled fields | B6: No of Prefilled fields
A7: No of API Integrations | B7: No of API Integrations
A8: No API integrations for saving the data | B8: No API integrations for saving the data
A9: Queries or Business rules for the application | B9: Queries or Business rules for the application
A10: No of Integration | B10: No of Integration
A11: mobile App-UI | B11: mobile App-UI
A12: Data Migration | B12: Data Migration
A13: Reports | B13: Reports
A25: Complexity | B25: Type of work | C25: VAF Rating
A26: Low | B26: New Development | C26: 5 | D26: 5 - Very Strong Influence
A27: Medium | B27: Enhancement and customization | C27: 4 | D27: 4 - Strong Influence
A28: High | C28: 3 | D28: 3 - Average Influence
A29: Complex | C29: 2 | D29: 2 - Moderate Influence
C30: 1 | D30: 1- Slight Influence
C31: 0 | D31: 0 - No Influence
A37: Effort Distribution Guidelines
B38: Effort Distribution | C38: Cost
C39: Min | D39: Max
A40: Business Analyst | B40: 0.15 | C40: 4000 | D40: 6000
A41: Solution Architecht | B41: 0.1 | C41: 6000 | D41: 8000
A42: Developer / Data Scientist | B42: 0.4 | C42: 3000 | D42: 5000
A43: Tester | B43: 0.2 | C43: 2500 | D43: 5000
A44: Project Manager | B44: 0.1 | C44: 8000 | D44: 10000
A45: Infrastructure Setup | B45: 0.05 | C45: 3000 | D45: 5000
A46: Business Analyst | B46: 0.15
A47: Solution Architecht | B47: 0.1
A48: Developer / Data Scientist | B48: 0.4
A49: Tester | B49: 0.2
A50: Project Manager | B50: 0.1
A51: Infrastructure Setup | B51: 0.05

Sheet Baseline Productivity 
A3: Type of work | B3: Calculated Productivity | C3: Targated Productivity | D3: Unit
A4: Development & Enhancement | C4: 0.19 | D4: Point / per hour
C9: 1 Point | D9: =1/C4 -> 5.2631579
D10: ~5.26 hours
A12: Revision note (Cycle 5, Jun-Sep 2026)
A13: Targeted productivity increased from 0.179 to 0.19 pt/hr: 1 story point = ~5.26 hours (was ~5.6 hours). All module sheets read the value in C4.
A14: Complexity weights unchanged (Low = 1, Medium = 3, High = 5). VAF ratings, 5% risk contingency and 10% project management carried forward from Cycle 4 V2.0.

Sheet Guidelines
B2: Complexity | C2: 1 | D2: 3 | E2: 5
A3: Work Type | B3: Component | C3: Low | D3: Medium | E3: High
A4: Development | B4: Web Page / Screen with no of input fields | C4: 10 | D4: 10-15 | E4: > 15 | F4: Elements Label Graph Tile Grid Pop-up Drop Down Data Entery Field Button Custom Built element | K4: 1
B5: Type of exit scenario | C5: 1 | D5: 1 to 2 | E5: >3 | H5: label | I5: text box
B6: No of Validation on the fields | C6: 1 to 5 | D6: 5 To 10 | E6: >10 | H6: button
B7: No of Prefilled fields | C7: 10 to 30 | D7: 30 to 50 | E7: >50 | H7: drop down
B8: No of API Integrations | C8: 2 | D8: 2 to 5 | E8: > 5 | H8: checkbox
B9: No API integrations for saving the data | C9: 3 | D9: 3 to 5 | E9: >5 | H9: aadhar
B10: Queries or Business rules for the application | C10: No validation or business rules. One data store | D10: No validation or business rules. Up to 3 data stores | E10: Validation or business rules involved. Multiple data stores | H10: samagra integration
B11: No of Integration | C11: 2 | D11: 2 to 5 | E11: >5 | H11: report
B12: mobile App-UI | C12: Static screen | D12: Screen with 2-4 internal components | E12: Screen with external components | H12: MObile app
B13: Data Migration | C13: Master Table | D13: Table with data errors and involves Data validation and cleansing | E13: Table with relationship with data errors and requires data validation and cleansing | H13: submit
B14: Reports | C14: tabular report. <10 columns. 1 data source Elements( Table, PIE chart, Report count: 1-2 | D14: 2-3 data source. Simple (Pie/Bar) chart Elements( Stack,Line etc.) Report type: 3-5 | E14: >3 data source. Multiple complex graphs Elements( Doughnut, Trend analysis etc.) Report type: More than 5 | H14: clear
H15: reset
F19: Code element Data Tranformation Data Pre-processing Custom Build element API creation for UI\UX API Integration

Sheet Summary
A1: Jal Rekha - Cycle 5 (Jun-Sep 2026) Size Based Estimation Summary
A2: All figures link to the module estimation sheets. Productivity is read from Baseline Productivity!C4.
A4: Estimation Sheet | B4: Stories | C4: Low | D4: Medium | E4: High | F4: Size (Points) | G4: Productivity (pt/hr) | H4: Effort (Man hours) | I4: VAF | J4: Total Planned Effort (Man hours) | K4: Range Low (-5%) | L4: Range High (+5%) | M4: Check vs Story Mapping
A5: O&M Estimation | B5: =C5+D5+E5 -> 46 | C5: =SUM('O&M Estimation'!D8:D15) -> 11 | D5: =SUM('O&M Estimation'!E8:E15) -> 25 | E5: =SUM('O&M Estimation'!F8:F15) -> 10 | F5: ='O&M Estimation'!G16 -> 136 | G5: ='O&M Estimation'!C20 -> 0.19 | H5: ='O&M Estimation'!C22 -> 715.78947 | I5: ='O&M Estimation'!C23 -> 1.01 | J5: ='O&M Estimation'!C26 -> 831.38947 | K5: ='O&M Estimation'!D28 -> 789.82 | L5: ='O&M Estimation'!C28 -> 872.95895 | M5: =IF(AND(COUNTIFS('Story Mapping'!$H$9:$H$196,A5,'Story Mapping'!$L$9:$L$196,"Low")=C5,COUNTIFS('Story Mapping'!$H$9:$H$196,A5,'Story Mapping'!$L$9:$L$196,"Medium")=D5,COUNTIFS('Story Mapping'!$H$9:$H$196,A5,'Story Mapping'!$L$9:$L$196,"High")=E5),"OK","MISMATCH") -> OK
A6: Sahbhagita Estimation | B6: =C6+D6+E6 -> 12 | C6: =SUM('Sahbhagita Estimation'!D8:D11) -> 4 | D6: =SUM('Sahbhagita Estimation'!E8:E11) -> 7 | E6: =SUM('Sahbhagita Estimation'!F8:F11) -> 1 | F6: ='Sahbhagita Estimation'!G12 -> 30 | G6: ='Sahbhagita Estimation'!C16 -> 0.19 | H6: ='Sahbhagita Estimation'!C18 -> 157.89474 | I6: ='Sahbhagita Estimation'!C19 -> 1.01 | J6: ='Sahbhagita Estimation'!C22 -> 183.39474 | K6: ='Sahbhagita Estimation'!D24 -> 174.225 | L6: ='Sahbhagita Estimation'!C24 -> 192.56447 | M6: =IF(AND(COUNTIFS('Story Mapping'!$H$9:$H$196,A6,'Story Mapping'!$L$9:$L$196,"Low")=C6,COUNTIFS('Story Mapping'!$H$9:$H$196,A6,'Story Mapping'!$L$9:$L$196,"Medium")=D6,COUNTIFS('Story Mapping'!$H$9:$H$196,A6,'Story Mapping'!$L$9:$L$196,"High")=E6),"OK","MISMATCH") -> OK
A7: Dhara Estimation | B7: =C7+D7+E7 -> 14 | C7: =SUM('Dhara Estimation'!D8:D12) -> 1 | D7: =SUM('Dhara Estimation'!E8:E12) -> 10 | E7: =SUM('Dhara Estimation'!F8:F12) -> 3 | F7: ='Dhara Estimation'!G13 -> 46 | G7: ='Dhara Estimation'!C17 -> 0.19 | H7: ='Dhara Estimation'!C19 -> 242.10526 | I7: ='Dhara Estimation'!C20 -> 1.01 | J7: ='Dhara Estimation'!C23 -> 281.20526 | K7: ='Dhara Estimation'!D25 -> 267.145 | L7: ='Dhara Estimation'!C25 -> 295.26553 | M7: =IF(AND(COUNTIFS('Story Mapping'!$H$9:$H$196,A7,'Story Mapping'!$L$9:$L$196,"Low")=C7,COUNTIFS('Story Mapping'!$H$9:$H$196,A7,'Story Mapping'!$L$9:$L$196,"Medium")=D7,COUNTIFS('Story Mapping'!$H$9:$H$196,A7,'Story Mapping'!$L$9:$L$196,"High")=E7),"OK","MISMATCH") -> OK
A8: Master Estimation | B8: =C8+D8+E8 -> 10 | C8: =SUM('Master Estimation'!D8:D10) -> 4 | D8: =SUM('Master Estimation'!E8:E10) -> 6 | E8: =SUM('Master Estimation'!F8:F10) -> 0 | F8: ='Master Estimation'!G11 -> 22 | G8: ='Master Estimation'!C15 -> 0.19 | H8: ='Master Estimation'!C17 -> 115.78947 | I8: ='Master Estimation'!C18 -> 1.01 | J8: ='Master Estimation'!C21 -> 134.48947 | K8: ='Master Estimation'!D23 -> 127.765 | L8: ='Master Estimation'!C23 -> 141.21395 | M8: =IF(AND(COUNTIFS('Story Mapping'!$H$9:$H$196,A8,'Story Mapping'!$L$9:$L$196,"Low")=C8,COUNTIFS('Story Mapping'!$H$9:$H$196,A8,'Story Mapping'!$L$9:$L$196,"Medium")=D8,COUNTIFS('Story Mapping'!$H$9:$H$196,A8,'Story Mapping'!$L$9:$L$196,"High")=E8),"OK","MISMATCH") -> OK
A9: FHTC Estimation | B9: =C9+D9+E9 -> 7 | C9: =SUM('FHTC Estimation'!D8:D10) -> 4 | D9: =SUM('FHTC Estimation'!E8:E10) -> 2 | E9: =SUM('FHTC Estimation'!F8:F10) -> 1 | F9: ='FHTC Estimation'!G11 -> 15 | G9: ='FHTC Estimation'!C15 -> 0.19 | H9: ='FHTC Estimation'!C17 -> 78.947368 | I9: ='FHTC Estimation'!C18 -> 1.01 | J9: ='FHTC Estimation'!C21 -> 91.697368 | K9: ='FHTC Estimation'!D23 -> 87.1125 | L9: ='FHTC Estimation'!C23 -> 96.282237 | M9: =IF(AND(COUNTIFS('Story Mapping'!$H$9:$H$196,A9,'Story Mapping'!$L$9:$L$196,"Low")=C9,COUNTIFS('Story Mapping'!$H$9:$H$196,A9,'Story Mapping'!$L$9:$L$196,"Medium")=D9,COUNTIFS('Story Mapping'!$H$9:$H$196,A9,'Story Mapping'!$L$9:$L$196,"High")=E9),"OK","MISMATCH") -> OK
A10: Cube Testing Estimation | B10: =C10+D10+E10 -> 7 | C10: =SUM('Cube Testing Estimation'!D8:D10) -> 6 | D10: =SUM('Cube Testing Estimation'!E8:E10) -> 1 | E10: =SUM('Cube Testing Estimation'!F8:F10) -> 0 | F10: ='Cube Testing Estimation'!G11 -> 9 | G10: ='Cube Testing Estimation'!C15 -> 0.19 | H10: ='Cube Testing Estimation'!C17 -> 47.368421 | I10: ='Cube Testing Estimation'!C18 -> 1.01 | J10: ='Cube Testing Estimation'!C21 -> 55.018421 | K10: ='Cube Testing Estimation'!D23 -> 52.2675 | L10: ='Cube Testing Estimation'!C23 -> 57.769342 | M10: =IF(AND(COUNTIFS('Story Mapping'!$H$9:$H$196,A10,'Story Mapping'!$L$9:$L$196,"Low")=C10,COUNTIFS('Story Mapping'!$H$9:$H$196,A10,'Story Mapping'!$L$9:$L$196,"Medium")=D10,COUNTIFS('Story Mapping'!$H$9:$H$196,A10,'Story Mapping'!$L$9:$L$196,"High")=E10),"OK","MISMATCH") -> OK
A11: Material Testing Estimation | B11: =C11+D11+E11 -> 4 | C11: =SUM('Material Testing Estimation'!D8:D10) -> 2 | D11: =SUM('Material Testing Estimation'!E8:E10) -> 1 | E11: =SUM('Material Testing Estimation'!F8:F10) -> 1 | F11: ='Material Testing Estimation'!G11 -> 10 | G11: ='Material Testing Estimation'!C15 -> 0.19 | H11: ='Material Testing Estimation'!C17 -> 52.631579 | I11: ='Material Testing Estimation'!C18 -> 1.01 | J11: ='Material Testing Estimation'!C21 -> 61.131579 | K11: ='Material Testing Estimation'!D23 -> 58.075 | L11: ='Material Testing Estimation'!C23 -> 64.188158 | M11: =IF(AND(COUNTIFS('Story Mapping'!$H$9:$H$196,A11,'Story Mapping'!$L$9:$L$196,"Low")=C11,COUNTIFS('Story Mapping'!$H$9:$H$196,A11,'Story Mapping'!$L$9:$L$196,"Medium")=D11,COUNTIFS('Story Mapping'!$H$9:$H$196,A11,'Story Mapping'!$L$9:$L$196,"High")=E11),"OK","MISMATCH") -> OK
A12: Nirmal Estimation | B12: =C12+D12+E12 -> 6 | C12: =SUM('Nirmal Estimation'!D8:D9) -> 2 | D12: =SUM('Nirmal Estimation'!E8:E9) -> 3 | E12: =SUM('Nirmal Estimation'!F8:F9) -> 1 | F12: ='Nirmal Estimation'!G10 -> 16 | G12: ='Nirmal Estimation'!C14 -> 0.19 | H12: ='Nirmal Estimation'!C16 -> 84.210526 | I12: ='Nirmal Estimation'!C17 -> 1.01 | J12: ='Nirmal Estimation'!C20 -> 97.810526 | K12: ='Nirmal Estimation'!D22 -> 92.92 | L12: ='Nirmal Estimation'!C22 -> 102.70105 | M12: =IF(AND(COUNTIFS('Story Mapping'!$H$9:$H$196,A12,'Story Mapping'!$L$9:$L$196,"Low")=C12,COUNTIFS('Story Mapping'!$H$9:$H$196,A12,'Story Mapping'!$L$9:$L$196,"Medium")=D12,COUNTIFS('Story Mapping'!$H$9:$H$196,A12,'Story Mapping'!$L$9:$L$196,"High")=E12),"OK","MISMATCH") -> OK
A13: SVS Estimation | B13: =C13+D13+E13 -> 8 | C13: =SUM('SVS Estimation'!D8:D11) -> 4 | D13: =SUM('SVS Estimation'!E8:E11) -> 2 | E13: =SUM('SVS Estimation'!F8:F11) -> 2 | F13: ='SVS Estimation'!G12 -> 20 | G13: ='SVS Estimation'!C16 -> 0.19 | H13: ='SVS Estimation'!C18 -> 105.26316 | I13: ='SVS Estimation'!C19 -> 1.01 | J13: ='SVS Estimation'!C22 -> 122.26316 | K13: ='SVS Estimation'!D24 -> 116.15 | L13: ='SVS Estimation'!C24 -> 128.37632 | M13: =IF(AND(COUNTIFS('Story Mapping'!$H$9:$H$196,A13,'Story Mapping'!$L$9:$L$196,"Low")=C13,COUNTIFS('Story Mapping'!$H$9:$H$196,A13,'Story Mapping'!$L$9:$L$196,"Medium")=D13,COUNTIFS('Story Mapping'!$H$9:$H$196,A13,'Story Mapping'!$L$9:$L$196,"High")=E13),"OK","MISMATCH") -> OK
A14: SVS Anusharavan GP Estimation | B14: =C14+D14+E14 -> 7 | C14: =SUM('SVS Anusharavan GP Estimation'!D8:D10) -> 0 | D14: =SUM('SVS Anusharavan GP Estimation'!E8:E10) -> 4 | E14: =SUM('SVS Anusharavan GP Estimation'!F8:F10) -> 3 | F14: ='SVS Anusharavan GP Estimation'!G11 -> 27 | G14: ='SVS Anusharavan GP Estimation'!C15 -> 0.19 | H14: ='SVS Anusharavan GP Estimation'!C17 -> 142.10526 | I14: ='SVS Anusharavan GP Estimation'!C18 -> 1.01 | J14: ='SVS Anusharavan GP Estimation'!C21 -> 165.05526 | K14: ='SVS Anusharavan GP Estimation'!D23 -> 156.8025 | L14: ='SVS Anusharavan GP Estimation'!C23 -> 173.30803 | M14: =IF(AND(COUNTIFS('Story Mapping'!$H$9:$H$196,A14,'Story Mapping'!$L$9:$L$196,"Low")=C14,COUNTIFS('Story Mapping'!$H$9:$H$196,A14,'Story Mapping'!$L$9:$L$196,"Medium")=D14,COUNTIFS('Story Mapping'!$H$9:$H$196,A14,'Story Mapping'!$L$9:$L$196,"High")=E14),"OK","MISMATCH") -> OK
A15: Anusharavan Estimation | B15: =C15+D15+E15 -> 4 | C15: =SUM('Anusharavan Estimation'!D8:D9) -> 3 | D15: =SUM('Anusharavan Estimation'!E8:E9) -> 1 | E15: =SUM('Anusharavan Estimation'!F8:F9) -> 0 | F15: ='Anusharavan Estimation'!G10 -> 6 | G15: ='Anusharavan Estimation'!C14 -> 0.19 | H15: ='Anusharavan Estimation'!C16 -> 31.578947 | I15: ='Anusharavan Estimation'!C17 -> 1.01 | J15: ='Anusharavan Estimation'!C20 -> 36.678947 | K15: ='Anusharavan Estimation'!D22 -> 34.845 | L15: ='Anusharavan Estimation'!C22 -> 38.512895 | M15: =IF(AND(COUNTIFS('Story Mapping'!$H$9:$H$196,A15,'Story Mapping'!$L$9:$L$196,"Low")=C15,COUNTIFS('Story Mapping'!$H$9:$H$196,A15,'Story Mapping'!$L$9:$L$196,"Medium")=D15,COUNTIFS('Story Mapping'!$H$9:$H$196,A15,'Story Mapping'!$L$9:$L$196,"High")=E15),"OK","MISMATCH") -> OK
A16: Asset Mapping Estimation | B16: =C16+D16+E16 -> 3 | C16: =SUM('Asset Mapping Estimation'!D8:D9) -> 1 | D16: =SUM('Asset Mapping Estimation'!E8:E9) -> 2 | E16: =SUM('Asset Mapping Estimation'!F8:F9) -> 0 | F16: ='Asset Mapping Estimation'!G10 -> 7 | G16: ='Asset Mapping Estimation'!C14 -> 0.19 | H16: ='Asset Mapping Estimation'!C16 -> 36.842105 | I16: ='Asset Mapping Estimation'!C17 -> 1.01 | J16: ='Asset Mapping Estimation'!C20 -> 42.792105 | K16: ='Asset Mapping Estimation'!D22 -> 40.6525 | L16: ='Asset Mapping Estimation'!C22 -> 44.931711 | M16: =IF(AND(COUNTIFS('Story Mapping'!$H$9:$H$196,A16,'Story Mapping'!$L$9:$L$196,"Low")=C16,COUNTIFS('Story Mapping'!$H$9:$H$196,A16,'Story Mapping'!$L$9:$L$196,"Medium")=D16,COUNTIFS('Story Mapping'!$H$9:$H$196,A16,'Story Mapping'!$L$9:$L$196,"High")=E16),"OK","MISMATCH") -> OK
A17: Bharosa CR Estimation | B17: =C17+D17+E17 -> 3 | C17: =SUM('Bharosa CR Estimation'!D8:D9) -> 2 | D17: =SUM('Bharosa CR Estimation'!E8:E9) -> 1 | E17: =SUM('Bharosa CR Estimation'!F8:F9) -> 0 | F17: ='Bharosa CR Estimation'!G10 -> 5 | G17: ='Bharosa CR Estimation'!C14 -> 0.19 | H17: ='Bharosa CR Estimation'!C16 -> 26.315789 | I17: ='Bharosa CR Estimation'!C17 -> 1.01 | J17: ='Bharosa CR Estimation'!C20 -> 30.565789 | K17: ='Bharosa CR Estimation'!D22 -> 29.0375 | L17: ='Bharosa CR Estimation'!C22 -> 32.094079 | M17: =IF(AND(COUNTIFS('Story Mapping'!$H$9:$H$196,A17,'Story Mapping'!$L$9:$L$196,"Low")=C17,COUNTIFS('Story Mapping'!$H$9:$H$196,A17,'Story Mapping'!$L$9:$L$196,"Medium")=D17,COUNTIFS('Story Mapping'!$H$9:$H$196,A17,'Story Mapping'!$L$9:$L$196,"High")=E17),"OK","MISMATCH") -> OK
A18: AI Module Estimation | B18: =C18+D18+E18 -> 3 | C18: =SUM('AI Module Estimation'!D8:D8) -> 0 | D18: =SUM('AI Module Estimation'!E8:E8) -> 0 | E18: =SUM('AI Module Estimation'!F8:F8) -> 3 | F18: ='AI Module Estimation'!G9 -> 15 | G18: ='AI Module Estimation'!C13 -> 0.19 | H18: ='AI Module Estimation'!C15 -> 78.947368 | I18: ='AI Module Estimation'!C16 -> 1.01 | J18: ='AI Module Estimation'!C19 -> 91.697368 | K18: ='AI Module Estimation'!D21 -> 87.1125 | L18: ='AI Module Estimation'!C21 -> 96.282237 | M18: =IF(AND(COUNTIFS('Story Mapping'!$H$9:$H$196,A18,'Story Mapping'!$L$9:$L$196,"Low")=C18,COUNTIFS('Story Mapping'!$H$9:$H$196,A18,'Story Mapping'!$L$9:$L$196,"Medium")=D18,COUNTIFS('Story Mapping'!$H$9:$H$196,A18,'Story Mapping'!$L$9:$L$196,"High")=E18),"OK","MISMATCH") -> OK
A19: CMMI Doc Estimation | B19: =C19+D19+E19 -> 3 | C19: =SUM('CMMI Doc Estimation'!D8:D9) -> 0 | D19: =SUM('CMMI Doc Estimation'!E8:E9) -> 0 | E19: =SUM('CMMI Doc Estimation'!F8:F9) -> 3 | F19: ='CMMI Doc Estimation'!G10 -> 15 | G19: ='CMMI Doc Estimation'!C14 -> 0.19 | H19: ='CMMI Doc Estimation'!C16 -> 78.947368 | I19: ='CMMI Doc Estimation'!C17 -> 1.01 | J19: ='CMMI Doc Estimation'!C20 -> 91.697368 | K19: ='CMMI Doc Estimation'!D22 -> 87.1125 | L19: ='CMMI Doc Estimation'!C22 -> 96.282237 | M19: =IF(AND(COUNTIFS('Story Mapping'!$H$9:$H$196,A19,'Story Mapping'!$L$9:$L$196,"Low")=C19,COUNTIFS('Story Mapping'!$H$9:$H$196,A19,'Story Mapping'!$L$9:$L$196,"Medium")=D19,COUNTIFS('Story Mapping'!$H$9:$H$196,A19,'Story Mapping'!$L$9:$L$196,"High")=E19),"OK","MISMATCH") -> OK
A20: e-Sign CDAC Estimation | B20: =C20+D20+E20 -> 5 | C20: =SUM('e-Sign CDAC Estimation'!D8:D9) -> 0 | D20: =SUM('e-Sign CDAC Estimation'!E8:E9) -> 2 | E20: =SUM('e-Sign CDAC Estimation'!F8:F9) -> 3 | F20: ='e-Sign CDAC Estimation'!G10 -> 21 | G20: ='e-Sign CDAC Estimation'!C14 -> 0.19 | H20: ='e-Sign CDAC Estimation'!C16 -> 110.52632 | I20: ='e-Sign CDAC Estimation'!C17 -> 1.01 | J20: ='e-Sign CDAC Estimation'!C20 -> 128.37632 | K20: ='e-Sign CDAC Estimation'!D22 -> 121.9575 | L20: ='e-Sign CDAC Estimation'!C22 -> 134.79513 | M20: =IF(AND(COUNTIFS('Story Mapping'!$H$9:$H$196,A20,'Story Mapping'!$L$9:$L$196,"Low")=C20,COUNTIFS('Story Mapping'!$H$9:$H$196,A20,'Story Mapping'!$L$9:$L$196,"Medium")=D20,COUNTIFS('Story Mapping'!$H$9:$H$196,A20,'Story Mapping'!$L$9:$L$196,"High")=E20),"OK","MISMATCH") -> OK
A21: BISAC-BISAG Estimation | B21: =C21+D21+E21 -> 5 | C21: =SUM('BISAC-BISAG Estimation'!D8:D9) -> 0 | D21: =SUM('BISAC-BISAG Estimation'!E8:E9) -> 2 | E21: =SUM('BISAC-BISAG Estimation'!F8:F9) -> 3 | F21: ='BISAC-BISAG Estimation'!G10 -> 21 | G21: ='BISAC-BISAG Estimation'!C14 -> 0.19 | H21: ='BISAC-BISAG Estimation'!C16 -> 110.52632 | I21: ='BISAC-BISAG Estimation'!C17 -> 1.01 | J21: ='BISAC-BISAG Estimation'!C20 -> 128.37632 | K21: ='BISAC-BISAG Estimation'!D22 -> 121.9575 | L21: ='BISAC-BISAG Estimation'!C22 -> 134.79513 | M21: =IF(AND(COUNTIFS('Story Mapping'!$H$9:$H$196,A21,'Story Mapping'!$L$9:$L$196,"Low")=C21,COUNTIFS('Story Mapping'!$H$9:$H$196,A21,'Story Mapping'!$L$9:$L$196,"Medium")=D21,COUNTIFS('Story Mapping'!$H$9:$H$196,A21,'Story Mapping'!$L$9:$L$196,"High")=E21),"OK","MISMATCH") -> OK
A22: Other Modules Estimation | B22: =C22+D22+E22 -> 16 | C22: =SUM('Other Modules Estimation'!D8:D15) -> 2 | D22: =SUM('Other Modules Estimation'!E8:E15) -> 9 | E22: =SUM('Other Modules Estimation'!F8:F15) -> 5 | F22: ='Other Modules Estimation'!G16 -> 54 | G22: ='Other Modules Estimation'!C20 -> 0.19 | H22: ='Other Modules Estimation'!C22 -> 284.21053 | I22: ='Other Modules Estimation'!C23 -> 1.01 | J22: ='Other Modules Estimation'!C26 -> 330.11053 | K22: ='Other Modules Estimation'!D28 -> 313.605 | L22: ='Other Modules Estimation'!C28 -> 346.61605 | M22: =IF(AND(COUNTIFS('Story Mapping'!$H$9:$H$196,A22,'Story Mapping'!$L$9:$L$196,"Low")=C22,COUNTIFS('Story Mapping'!$H$9:$H$196,A22,'Story Mapping'!$L$9:$L$196,"Medium")=D22,COUNTIFS('Story Mapping'!$H$9:$H$196,A22,'Story Mapping'!$L$9:$L$196,"High")=E22),"OK","MISMATCH") -> OK
A23: TOTAL - CYCLE 5 (JUN-SEP 2026) | B23: =SUM(B5:B22) -> 163 | C23: =SUM(C5:C22) -> 46 | D23: =SUM(D5:D22) -> 78 | E23: =SUM(E5:E22) -> 39 | F23: =SUM(F5:F22) -> 475 | G23: ='Baseline Productivity '!C4 -> 0.19 | H23: =SUM(H5:H22) -> 2500 | J23: =SUM(J5:J22) -> 2903.75 | K23: =SUM(K5:K22) -> 2758.5625 | L23: =SUM(L5:L22) -> 3048.9375 | M23: =IF(COUNTIF(M5:M22,"OK")=ROWS(M5:M22),"OK","MISMATCH") -> OK
A25: Reference - hours actually logged (Date-Wise Time Sheet, Jun-Sep 2026)
A26: Jun 2026 (Sprint 17) | B26: 889
A27: Jul 2026 (Sprint 18) | B27: 1133
A28: Aug 2026 (Sprint 19) | B28: 690
A29: Sep 2026 (Sprint 20) | B29: 730
A30: Total hours logged (all activity incl. meetings, adhoc, CMMI) | B30: =SUM(B26:B29) -> 3442
A31: Planned effort / hours logged | B31: =J23/B30 -> 0.84362289
A32: Source: Date_Wise_Time_Sheet (Jun-Sep 2026), hours by entry month. Blue = hardcoded input from the timesheet. The September PSR reports 706.0 hrs against 730.0 hrs in the timesheet file; August matches the PSR (690.0).

Sheet O&M Estimation
B1: Type Of work | C1: Development | D1: New Development
B2: Project Name | C2: Jal Rekha
B3: Remark | C3: O&M Billing Module - Cycle 5 (Jun-Sep 2026)
D5: Volume/Count of elements | H5: Guidelines
A6: Module + sub Module | B6: Functionality ( Sub Module) | C6: Elements (Refer Guidelines and Put here for reference) | D6: Low Complexity | E6: Medium compexity | F6: High Complexity | G6: Size | H6: Low Complexity | I6: Medium compexity | J6: High Complexity
D7: 1 | E7: 3 | F7: 5
A8: O&M Billing - Abstract, Bill PDF & Review | B8: Abstract report, contractor-mistake correction, all-records view, merged bill PDF, landscape fix (Jun-Jul) | C8: US-OM-C5-001 - O&M Billing – Abstract Report Generation [H] US-OM-C5-002 - O&M Billing – Contractor Mistake Correction by SQC/TL → GM [M] US-OM-C5-003 - O&M Billing – Show All Records on All IDs (GM, SQC) [M] US-OM-C5-004 - O&M Billing – Merge PDF of All O&M Bill Documents [M] US-OM-C5-011 - O&M Billing – GM (PIU) Login: Bill PDF (19–20 Docs) & 3-Month Consolidation [M] US-OM-C5-012 - O&M Billing – Sahbhagita Generate Abstract: Select RA Bill & Tag All [M] US-OM-C5-013 - O&M Billing – Landscape Issue Fix in O&M Bill Layout [L] Status: 7 Done | D8: 1 | E8: 5 | F8: 1 | G8: =D8*$D$7+E8*$E$7+F8*$F$7 -> 21
A9: O&M Billing - Power, Construction Bill & Complaints | B9: Power consumption, construction-phase bill columns/villages, pump transformer deduction, residual pressure & complaint redressal (Jun-Jul) | C9: US-OM-C5-005 - O&M Billing – Power Consumption: Contractor & GM Side Changes [H] US-OM-C5-006 - O&M Billing – Two New Columns in Water Supply During Construction Bill [M] US-OM-C5-007 - O&M Billing – O&M Villages: Construction Approval Status [M] US-OM-C5-009 - O&M Billing – GM: Pump Transformer 10% Deduction Logic [M] US-OM-C5-015 - O&M Billing - Residual Pressure & Complaint Redressal Report Format [M] US-OM-C5-016 - O&M Billing - Complaint Redressal: 48-Hour Flag & Penalty Relaxation [L] Status: 4 In Progress, 2 Done | D9: 1 | E9: 4 | F9: 1 | G9: =D9*$D$7+E9*$E$7+F9*$F$7 -> 18
A10: O&M Billing - Dispute, LGD & GST | B10: Contractor dispute window on Dhara data, LGD code integration, GST number (Jun-Jul; also covers Aug restatements AUG-15/16/17) | C10: US-OM-C5-008 - O&M Billing – Aaklan Contractor Dispute: Dhara Data Discrepancy Window [M] US-OM-C5-014 - O&M Billing – LGD Code Integration: LG Directory → MPSQC [M] US-OM-C5-017 - O&M Billing - GST Number Integration [M] Status: 2 In Progress, 1 Open | D10: 0 | E10: 3 | F10: 0 | G10: =D10*$D$7+E10*$E$7+F10*$F$7 -> 9
A11: O&M Billing - WSDCP Phase 1 | B11: New WSDCP tab: payment details, banked-units power sheet, monthly bill sheet, UFW report, pilot UAT (Aug) | C11: US-AUG-01 - O&M Billing — WSDCP - New WSDCP tab and Bill Generation status tracking [H] US-AUG-02 - O&M Billing — WSDCP - WSDCP Payment Details tab [H] US-AUG-03 - O&M Billing — WSDCP - WSDCP Power Consumption Sheet — Banked Units logic [H] US-AUG-04 - O&M Billing — WSDCP - WSDCP Monthly Bill Sheet — Functional HSC and deductions [H] US-AUG-05 - O&M Billing — WSDCP - WSDCP UFW Report (no penalty) [L] US-AUG-06 - O&M Billing — WSDCP - WSDCP User Acceptance Testing on pilot scheme [M] Status: 5 In Progress, 1 Done | D11: 1 | E11: 1 | F11: 4 | G11: =D11*$D$7+E11*$E$7+F11*$F$7 -> 24
A12: O&M Billing - Multi-role Workflow | B12: Forward/backward routing, GM/SQC edit rights with remark, SQC-unavailable fallback, higher-officials chain (Aug) | C12: US-AUG-07 - O&M Billing — Workflow - Full multi-role forward/backward billing workflow [H] US-AUG-08 - O&M Billing — Workflow - GM/SQC edit rights on bill data with mandatory remark [H] US-AUG-09 - O&M Billing — Workflow - SQC-not-available fallback — GM confirms directly [M] US-AUG-10 - O&M Billing — Workflow - Higher Officials approval chain (GM O&M → MD) [H] Status: 4 In Progress | D12: 0 | E12: 1 | F12: 3 | G12: =D12*$D$7+E12*$E$7+F12*$F$7 -> 18
A13: O&M Billing - Data Integrity & Adjustments | B13: Census denominator fix, pending-bills UI, net payable add/deduct, complaint category coding, Aakalan add/deduct (Aug) | C13: US-AUG-11 - O&M Billing — Data Integrity - Census Population / village denominator fix [M] US-AUG-12 - O&M Billing — UI/Workflow - 'Pending Bills for Review' rename and scheme filter [L] US-AUG-13 - O&M Billing — Net Payable - Net Payable Bill — Add More Deduction / Any Other Addition [M] US-AUG-14 - O&M Billing — Complaint Handling - Complaint category coding and extended deductions [M] US-AUG-18 - O&M Billing — Aakalan - Aakalan Addition/Deduction feature (TL SQC / GM PIU) [M] Status: 4 In Progress, 1 Done | D13: 1 | E13: 4 | F13: 0 | G13: =D13*$D$7+E13*$E$7+F13*$F$7 -> 13
A14: O&M Billing / Aaklan - Controls & Tracking | B14: Withheld add/deduct, edit lock, TRP gate, phase tabs, audit trail, role-scoped visibility, validations, user management, complaint carry-forward (Sep) | C14: US-SEP-02 - O&M Billing / Aaklan - Withheld Addition/Deduction amounts shown at End-of-Month [M] US-SEP-03 - O&M Billing / Aaklan - Fix: bill remains editable after Contractor submission [L] US-SEP-04 - O&M Billing / Aaklan - TRP gate controlling O&M Phase availability [L] US-SEP-05 - O&M Billing / Aaklan - Scheme-based SQC/TL list cleanup [L] US-SEP-06 - O&M Billing / Aaklan - WSDCP / TRP / O&M Phase tabs with staged Abstract pages [M] US-SEP-07 - O&M Billing / Aaklan - Full audit trail on Contractor Bill edits [M] US-SEP-08 - O&M Billing / Aaklan - PMC / Deputy O&M role-scoped scheme visibility [M] US-SEP-09 - O&M Billing / Aaklan - Gross Payable Bill — minimum value validation [L] US-SEP-10 - O&M Billing / Aaklan - Census Population verification before Generate Bill [L] US-SEP-11 - O&M Billing / Aaklan - User Management — PIU-wise ID search with Tenure and Agency columns [M] US-SEP-12 - O&M Billing / Aaklan - TL ID conflict resolution (Bhopal / Sehore) [L] US-SEP-13 - O&M Billing / Aaklan - Save-as-Draft confirmation popup on Bulk bill actions [L] US-SEP-14 - O&M Billing — Complaint Redressal - Carry-forward of unresolved complaints with 48-hour flag [M] Status: 6 In Progress, 2 Done, 5 Open | D14: 7 | E14: 6 | F14: 0 | G14: =D14*$D$7+E14*$E$7+F14*$F$7 -> 25
A15: O&M Billing - Contractor/GM UI | B15: Bill Tracking page overhaul, Abstract Bill UI, responsive layout, GM Abstract PDF UI fixes (Sep, PSR/timesheet-sourced) | C15: PSR-SEP-02 - O&M Billing Contractor - Bill Tracking page UI overhaul, Abstract Bill UI, responsive layout [H] PSR-SEP-03 - O&M Billing GM - Abstract Report PDF UI fixes [M] Status: 1 In Progress, 1 Done | D15: 0 | E15: 1 | F15: 1 | G15: =D15*$D$7+E15*$E$7+F15*$F$7 -> 8
A16: TOTAL O&M ESTIMATION (CYCLE 5) | G16: =SUM(G8:G15) -> 136
J17: Value added factors
B18: Total Count | G18: =G16 -> 136 | J18: Factor | L18: Rating
J19: Data Communications | L19: 0
B20: Productivity | C20: ='Baseline Productivity '!$C$4 -> 0.19 | J20: Distributed Data Processing | L20: 0
B21: Size | C21: =G16 -> 136 | D21: Point
B22: Effort | C22: =C21/C20 -> 715.78947 | D22: Man hours | J22: Performance | L22: 0
B23: VAF | C23: =0.65+0.01*$L$35 -> 1.01 | J23: Heavily used Configuration | L23: 3
B24: Risk contingency | C24: 0.05 | J24: Transaction Rate | L24: 4
B25: Project Management | C25: 0.1
B26: Total Planned effort | C26: =C22*C23*(1+C24+C25) -> 831.38947 | D26: Man hours | J26: Online Data Entry | L26: 3
J27: End-User Efficiency | L27: 2
B28: Permissible Range(Man hours) | C28: =C26*1.05 -> 872.95895 | D28: =C26*0.95 -> 789.82 | J28: Online Update | L28: 1
J29: Complex Processing | L29: 3
J30: Reusability | L30: 4
J31: Installation Ease | L31: 4
J32: Operational Ease | L32: 4
J33: Multiple Sites | L33: 4
J34: Facilitate Change | L34: 4
J35: Total | L35: =SUM(L19:L34) -> 36

Sheet Sahbhagita Estimation
B1: Type Of work | C1: Development | D1: New Development
B2: Project Name | C2: Jal Rekha
B3: Remark | C3: Sahbhagita Module - Cycle 5 (Jun-Sep 2026)
D5: Volume/Count of elements | H5: Guidelines
A6: Module + sub Module | B6: Functionality ( Sub Module) | C6: Elements (Refer Guidelines and Put here for reference) | D6: Low Complexity | E6: Medium compexity | F6: High Complexity | G6: Size | H6: Low Complexity | I6: Medium compexity | J6: High Complexity
D7: 1 | E7: 3 | F7: 5
A8: Sahbhagita - RA Bill, Abstract & Reports | B8: RA Bill for ISA, village-wise/combined report, master activity list, RA(1)-RA(12) withhold bills, customised ISA report (Jun) | C8: US-SAH-C5-001 - Sahbhagita – RA Bill for ISA (replacing CP Manager) [M] US-SAH-C5-002 - Sahbhagita – Village-wise & Combined Activity Report [M] US-SAH-C5-003 - Sahbhagita – Master Activity List Update (22 Combined + 32 Village-wise) [M] US-SAH-C5-006 - Sahbhagita – RA Bill: RA(1) till RA(12) Withhold Bills [M] US-SAH-C5-007 - Sahbhagita – Customised Report (ISA – Mainly Contractor Convention) [M] Status: 5 Done | D8: 0 | E8: 5 | F8: 0 | G8: =D8*$D$7+E8*$E$7+F8*$F$7 -> 15
A9: Sahbhagita - UI, Access & Mobile | B9: Hyperlinked document preview, mobile save-as-draft, pagination, FE-to-ISA scoping, ISA password reset (Jun) | C9: US-SAH-C5-005 - Sahbhagita – Hyperlink: Village Name → Village Activity → Document Preview [M] US-SAH-C5-008 - Sahbhagita – Save as Draft for Video, Image & Document (Mobile CR) [M] US-SAH-C5-009 - Sahbhagita - Pagination on Approval Pages [L] US-SAH-C5-010 - Sahbhagita - FE Visibility Scoped to Assigned ISA [L] US-SAH-C5-011 - Sahbhagita - Self-Service Password Reset for ISA Login [L] Status: 5 Done | D9: 3 | E9: 2 | F9: 0 | G9: =D9*$D$7+E9*$E$7+F9*$F$7 -> 9
A10: Sahbhagita - AI Photo Scan | B10: AI face/background detection on activity photos for CP Manager (Jul) | C10: US-SAH-C5-004 - Sahbhagita – Photo Scan AI: Face & Background Detection (CP Manager Review) [H] Status: 1 In Progress | D10: 0 | E10: 0 | F10: 1 | G10: =D10*$D$7+E10*$E$7+F10*$F$7 -> 5
A11: Sahbhagita - Abstract of RA Bill Release | B11: UAT defects DEF-01 to DEF-04, PIU/scheme binding, production release (Aug) | C11: US-AUG-26 - Sahbhagita - Sahbhagita Abstract of RA Bill — production release [L] Status: 1 In Progress | D11: 1 | E11: 0 | F11: 0 | G11: =D11*$D$7+E11*$E$7+F11*$F$7 -> 1
A12: TOTAL SAHBHAGITA ESTIMATION (CYCLE 5) | G12: =SUM(G8:G11) -> 30
J13: Value added factors
B14: Total Count | G14: =G12 -> 30 | J14: Factor | L14: Rating
J15: Data Communications | L15: 0
B16: Productivity | C16: ='Baseline Productivity '!$C$4 -> 0.19 | J16: Distributed Data Processing | L16: 0
B17: Size | C17: =G12 -> 30 | D17: Point
B18: Effort | C18: =C17/C16 -> 157.89474 | D18: Man hours | J18: Performance | L18: 0
B19: VAF | C19: =0.65+0.01*$L$31 -> 1.01 | J19: Heavily used Configuration | L19: 3
B20: Risk contingency | C20: 0.05 | J20: Transaction Rate | L20: 4
B21: Project Management | C21: 0.1
B22: Total Planned effort | C22: =C18*C19*(1+C20+C21) -> 183.39474 | D22: Man hours | J22: Online Data Entry | L22: 3
J23: End-User Efficiency | L23: 2
B24: Permissible Range(Man hours) | C24: =C22*1.05 -> 192.56447 | D24: =C22*0.95 -> 174.225 | J24: Online Update | L24: 1
J25: Complex Processing | L25: 3
J26: Reusability | L26: 4
J27: Installation Ease | L27: 4
J28: Operational Ease | L28: 4
J29: Multiple Sites | L29: 4
J30: Facilitate Change | L30: 4
J31: Total | L31: =SUM(L15:L30) -> 36

Sheet Dhara Estimation
B1: Type Of work | C1: Development | D1: New Development
B2: Project Name | C2: Jal Rekha
B3: Remark | C3: Dhara Module - Cycle 5 (Jun-Sep 2026)
D5: Volume/Count of elements | H5: Guidelines
A6: Module + sub Module | B6: Functionality ( Sub Module) | C6: Elements (Refer Guidelines and Put here for reference) | D6: Low Complexity | E6: Medium compexity | F6: High Complexity | G6: Size | H6: Low Complexity | I6: Medium compexity | J6: High Complexity
D7: 1 | E7: 3 | F7: 5
A8: Dhara - Reports & Approved Data | B8: Report corrections, 27-May format, contractor dispute window, new reports on all logins, base-capacity columns, approved-data correction (Jun-Jul) | C8: US-DHR-C5-001 - Dhara – Report Corrections (Approved Village MWSR, DWSR, OHT) [M] US-DHR-C5-002 - Dhara – Report Format Standardisation (27 May 2026 Format) [M] US-DHR-C5-003 - Dhara – Approved Reports & Contractor Dispute Window [M] US-DHR-C5-004 - Dhara – New Dhara Reports Visible on All Jal Rekha Logins [M] US-DHR-C5-006 - Dhara – OHT/WTP/Intake Base Capacity Column in Report [M] US-DHR-C5-007 - Dhara - Approved Report Data Correction (Agreed with Kapil Sir) [M] Status: 4 Done, 2 In Progress | D8: 0 | E8: 6 | F8: 0 | G8: =D8*$D$7+E8*$E$7+F8*$F$7 -> 18
A9: Dhara - Entry Lock & Optional Fields | B9: Approved entry lock; non-mandatory remark/photo/forward/backward (Jun) | C9: US-DHR-C5-005 - Dhara – Dhara Entry Lock (Approved Data Should Not Change) [M] US-DHR-C5-008 - Dhara - Non-Mandatory Remark, Photo Upload, Forward & Backward Options [L] Status: 2 Done | D9: 1 | E9: 1 | F9: 0 | G9: =D9*$D$7+E9*$E$7+F9*$F$7 -> 4
A10: Dhara - Meter Logic & Sequential Approval | B10: FE/Dhara meter functional logic, sequential month-wise approval lock (Aug-Sep) | C10: US-AUG-22 - SVS / Dhara Meter Logic - FE/Dhara Meter Functional logic and sequential approval [M] US-SEP-15 - Dhara - Dhara sequential reading approval lock [M] Status: 2 In Progress | D10: 0 | E10: 2 | F10: 0 | G10: =D10*$D$7+E10*$E$7+F10*$F$7 -> 6
A11: Dhara - Edit Rules, Survey Report & MPEB API | B11: Reading edit rules by meter status, survey report column restructuring, MPEB smart-meter API (Sep) | C11: US-SEP-16 - Dhara - Dhara reading edit rules by meter status (GM / SQC-TL login) [H] US-SEP-17 - Dhara - Dhara Survey Report column restructuring [M] US-SEP-18 - Dhara - Dhara Electricity Meter Bill — MPEB Smart Meter API integration [H] Status: 3 Open | D11: 0 | E11: 1 | F11: 2 | G11: =D11*$D$7+E11*$E$7+F11*$F$7 -> 13
A12: Dhara & Nirmal - Panchayat Monitoring | B12: Panchayat-level dashboards for Dhara and Nirmal; 5-step MVS-to-local-body handover (Aug) | C12: US-AUG-34 - Dhara & Nirmal Panchayat Monitoring - Panchayat-level dashboard and MVS-to-local-body handover [H] Status: 1 In Progress | D12: 0 | E12: 0 | F12: 1 | G12: =D12*$D$7+E12*$E$7+F12*$F$7 -> 5
A13: TOTAL DHARA ESTIMATION (CYCLE 5) | G13: =SUM(G8:G12) -> 46
J14: Value added factors
B15: Total Count | G15: =G13 -> 46 | J15: Factor | L15: Rating
J16: Data Communications | L16: 0
B17: Productivity | C17: ='Baseline Productivity '!$C$4 -> 0.19 | J17: Distributed Data Processing | L17: 0
B18: Size | C18: =G13 -> 46 | D18: Point
B19: Effort | C19: =C18/C17 -> 242.10526 | D19: Man hours | J19: Performance | L19: 0
B20: VAF | C20: =0.65+0.01*$L$32 -> 1.01 | J20: Heavily used Configuration | L20: 3
B21: Risk contingency | C21: 0.05 | J21: Transaction Rate | L21: 4
B22: Project Management | C22: 0.1
B23: Total Planned effort | C23: =C19*C20*(1+C21+C22) -> 281.20526 | D23: Man hours | J23: Online Data Entry | L23: 3
J24: End-User Efficiency | L24: 2
B25: Permissible Range(Man hours) | C25: =C23*1.05 -> 295.26553 | D25: =C23*0.95 -> 267.145 | J25: Online Update | L25: 1
J26: Complex Processing | L26: 3
J27: Reusability | L27: 4
J28: Installation Ease | L28: 4
J29: Operational Ease | L29: 4
J30: Multiple Sites | L30: 4
J31: Facilitate Change | L31: 4
J32: Total | L32: =SUM(L16:L31) -> 36

Sheet Master Estimation
B1: Type Of work | C1: Development | D1: New Development
B2: Project Name | C2: Jal Rekha
B3: Remark | C3: Master / Vistrit Module - Cycle 5 (Jun-Sep 2026)
D5: Volume/Count of elements | H5: Guidelines
A6: Module + sub Module | B6: Functionality ( Sub Module) | C6: Elements (Refer Guidelines and Put here for reference) | D6: Low Complexity | E6: Medium compexity | F6: High Complexity | G6: Size | H6: Low Complexity | I6: Medium compexity | J6: High Complexity
D7: 1 | E7: 3 | F7: 5
A8: Vistrit - Mapping, OTP & Validation | B8: WTP meter mapping columns, OTP on GM edit/delete, field validation, OHT deactivate fix, meter naming, duplicate-village validation (Jun) | C8: US-VST-C5-001 - Vistrit – WTP Meter Mapping: New Columns (Date, Scheme, PIU, Meter Name) [M] US-VST-C5-002 - Vistrit – OTP Verification for GM Edit/Delete on Scheme, OHT, Bulk Master [M] US-VST-C5-003 - Vistrit – Scheme Village Mapping: Testing/Permitted Field Validation & Census Population [L] US-VST-C5-004 - Vistrit – OHT Deactivate Bug Fix (OHT Not Visible in FE Login) [M] US-VST-C5-005 - Vistrit – WTP Meter Naming Convention Standardisation [L] US-VST-OTP-C5-002 - Vistrit – Scheme Village Mapping: Duplicate Village Validation [L] Status: 6 Done | D8: 3 | E8: 3 | F8: 0 | G8: =D8*$D$7+E8*$E$7+F8*$F$7 -> 12
A9: Master - Lock & Data Integrity | B9: Lock Scheme/Village/OHT master on live link (CR MSTR-JUN-2026-006), Dhara mapped summary search fix, village deletion restriction (Jun-Jul) | C9: US-MSTR-C5-001 - Master - Lock Scheme/Village/OHT Master Once Linked to Live Transactions [M] US-MSTR-C5-002 - Master - Dhara Mapped Summary Report Search Debugging & Enhancement [M] US-MSTR-C5-003 - Master - Village Deletion Restriction & Database Validation Message [L] Status: 1 Open, 2 Done | D9: 1 | E9: 2 | F9: 0 | G9: =D9*$D$7+E9*$E$7+F9*$F$7 -> 7
A10: Vistrit - Survey Intake/WTP/OHT Master | B10: Three new master sub-modules with Add/Update action (Sep) | C10: US-SEP-25 - Vistrit (Master) - Survey Intake, WTP and OHT Master sub-modules [M] Status: 1 In Progress | D10: 0 | E10: 1 | F10: 0 | G10: =D10*$D$7+E10*$E$7+F10*$F$7 -> 3
A11: TOTAL MASTER ESTIMATION (CYCLE 5) | G11: =SUM(G8:G10) -> 22
J12: Value added factors
B13: Total Count | G13: =G11 -> 22 | J13: Factor | L13: Rating
J14: Data Communications | L14: 0
B15: Productivity | C15: ='Baseline Productivity '!$C$4 -> 0.19 | J15: Distributed Data Processing | L15: 0
B16: Size | C16: =G11 -> 22 | D16: Point
B17: Effort | C17: =C16/C15 -> 115.78947 | D17: Man hours | J17: Performance | L17: 0
B18: VAF | C18: =0.65+0.01*$L$30 -> 1.01 | J18: Heavily used Configuration | L18: 3
B19: Risk contingency | C19: 0.05 | J19: Transaction Rate | L19: 4
B20: Project Management | C20: 0.1
B21: Total Planned effort | C21: =C17*C18*(1+C19+C20) -> 134.48947 | D21: Man hours | J21: Online Data Entry | L21: 3
J22: End-User Efficiency | L22: 2
B23: Permissible Range(Man hours) | C23: =C21*1.05 -> 141.21395 | D23: =C21*0.95 -> 127.765 | J23: Online Update | L23: 1
J24: Complex Processing | L24: 3
J25: Reusability | L25: 4
J26: Installation Ease | L26: 4
J27: Operational Ease | L27: 4
J28: Multiple Sites | L28: 4
J29: Facilitate Change | L29: 4
J30: Total | L30: =SUM(L14:L29) -> 36

Sheet FHTC Estimation
B1: Type Of work | C1: Development | D1: New Development
B2: Project Name | C2: Jal Rekha
B3: Remark | C3: FHTC / Parinam Module - Cycle 5 (Jun-Sep 2026)
D5: Volume/Count of elements | H5: Guidelines
A6: Module + sub Module | B6: Functionality ( Sub Module) | C6: Elements (Refer Guidelines and Put here for reference) | D6: Low Complexity | E6: Medium compexity | F6: High Complexity | G6: Size | H6: Low Complexity | I6: Medium compexity | J6: High Complexity
D7: 1 | E7: 3 | F7: 5
A8: FHTC Parinam - Nasamajh, Samagra & Surveys | B8: Nasamajh family head ID, Samagra API integration, multiple surveys per Samagra ID (Jun-Jul) | C8: US-FHTC-C5-001 - FHTC Parinam – Nasamajh Family Head ID & Add Connection [M] US-FHTC-C5-004 - FHTC Parinam – Samagra API Integration for Household Data [H] US-FHTC-C5-005 - FHTC Parinam - Multiple Surveys per Samagra ID [M] Status: 2 In Progress, 1 Done | D8: 0 | E8: 2 | F8: 1 | G8: =D8*$D$7+E8*$E$7+F8*$F$7 -> 11
A9: FHTC Parinam - Reports & Search | B9: FE name in reports, contractor search option (Jun) | C9: US-FHTC-C5-002 - FHTC Parinam – FE Name Shown in Reports [L] US-FHTC-C5-003 - FHTC Parinam – Contractor Search Option [L] Status: 2 Done | D9: 2 | E9: 0 | F9: 0 | G9: =D9*$D$7+E9*$E$7+F9*$F$7 -> 2
A10: FHTC Parinam - Dashboard | B10: Parinam Dashboard tab on HSC Survey screen; FE dashboard and FE-login reports in mobile APK (Aug-Sep) | C10: US-AUG-27 - FHTC / Parinam - Parinam Dashboard tab on HSC Survey screen [L] US-SEP-26 - Parinam - FE dashboard, FE-login reports, and multi-survey support confirmed stable [L] Status: 2 Done | D10: 2 | E10: 0 | F10: 0 | G10: =D10*$D$7+E10*$E$7+F10*$F$7 -> 2
A11: TOTAL FHTC ESTIMATION (CYCLE 5) | G11: =SUM(G8:G10) -> 15
J12: Value added factors
B13: Total Count | G13: =G11 -> 15 | J13: Factor | L13: Rating
J14: Data Communications | L14: 0
B15: Productivity | C15: ='Baseline Productivity '!$C$4 -> 0.19 | J15: Distributed Data Processing | L15: 0
B16: Size | C16: =G11 -> 15 | D16: Point
B17: Effort | C17: =C16/C15 -> 78.947368 | D17: Man hours | J17: Performance | L17: 0
B18: VAF | C18: =0.65+0.01*$L$30 -> 1.01 | J18: Heavily used Configuration | L18: 3
B19: Risk contingency | C19: 0.05 | J19: Transaction Rate | L19: 4
B20: Project Management | C20: 0.1
B21: Total Planned effort | C21: =C17*C18*(1+C19+C20) -> 91.697368 | D21: Man hours | J21: Online Data Entry | L21: 3
J22: End-User Efficiency | L22: 2
B23: Permissible Range(Man hours) | C23: =C21*1.05 -> 96.282237 | D23: =C21*0.95 -> 87.1125 | J23: Online Update | L23: 1
J24: Complex Processing | L24: 3
J25: Reusability | L25: 4
J26: Installation Ease | L26: 4
J27: Operational Ease | L27: 4
J28: Multiple Sites | L28: 4
J29: Facilitate Change | L29: 4
J30: Total | L30: =SUM(L14:L29) -> 36

Sheet Cube Testing Estimation
B1: Type Of work | C1: Development | D1: New Development
B2: Project Name | C2: Jal Rekha
B3: Remark | C3: Cube Testing Module - Cycle 5 (Jun-Sep 2026)
D5: Volume/Count of elements | H5: Guidelines
A6: Module + sub Module | B6: Functionality ( Sub Module) | C6: Elements (Refer Guidelines and Put here for reference) | D6: Low Complexity | E6: Medium compexity | F6: High Complexity | G6: Size | H6: Low Complexity | I6: Medium compexity | J6: High Complexity
D7: 1 | E7: 3 | F7: 5
A8: Cube Testing - Contractor Visibility & ID | B8: Rejected data to contractor, Cube ID before image upload, Filter Bed sub-component (Jun) | C8: US-CUBE-C5-001 - Cube Testing – Show Rejected Data to Contractor [L] US-CUBE-C5-002 - Cube Testing – Cube ID Generated Before Image Upload [L] US-CUBE-C5-003 - Cube Testing – Filter Bed Sub-Component Under WTP [L] Status: 3 Done | D8: 3 | E8: 0 | F8: 0 | G8: =D8*$D$7+E8*$E$7+F8*$F$7 -> 3
A9: Cube Testing - Re-Inspection Loop | B9: 2nd-loop re-inspection after GM rejection; optional image on 2nd RFI loop (Jul) | C9: US-CUBE-C5-004 - Cube Testing - Re-Inspection Loop (2nd Loop after GM Rejection) [M] US-CUBE-C5-005 - Cube Testing - Optional Image Upload on Second RFI Loop [L] Status: 2 Done | D9: 1 | E9: 1 | F9: 0 | G9: =D9*$D$7+E9*$E$7+F9*$F$7 -> 4
A10: Cube Testing - Re-Inspection Status | B10: Cube RFI Id display; colour flag and separate re-inspection status (Sep) | C10: US-SEP-20 - Cube Testing - Cube RFI Id display [L] US-SEP-21 - Cube Testing - Cube Reinspection — colour flag and separate status [L] Status: 1 Open, 1 In Progress | D10: 2 | E10: 0 | F10: 0 | G10: =D10*$D$7+E10*$E$7+F10*$F$7 -> 2
A11: TOTAL CUBE TESTING ESTIMATION (CYCLE 5) | G11: =SUM(G8:G10) -> 9
J12: Value added factors
B13: Total Count | G13: =G11 -> 9 | J13: Factor | L13: Rating
J14: Data Communications | L14: 0
B15: Productivity | C15: ='Baseline Productivity '!$C$4 -> 0.19 | J15: Distributed Data Processing | L15: 0
B16: Size | C16: =G11 -> 9 | D16: Point
B17: Effort | C17: =C16/C15 -> 47.368421 | D17: Man hours | J17: Performance | L17: 0
B18: VAF | C18: =0.65+0.01*$L$30 -> 1.01 | J18: Heavily used Configuration | L18: 3
B19: Risk contingency | C19: 0.05 | J19: Transaction Rate | L19: 4
B20: Project Management | C20: 0.1
B21: Total Planned effort | C21: =C17*C18*(1+C19+C20) -> 55.018421 | D21: Man hours | J21: Online Data Entry | L21: 3
J22: End-User Efficiency | L22: 2
B23: Permissible Range(Man hours) | C23: =C21*1.05 -> 57.769342 | D23: =C21*0.95 -> 52.2675 | J23: Online Update | L23: 1
J24: Complex Processing | L24: 3
J25: Reusability | L25: 4
J26: Installation Ease | L26: 4
J27: Operational Ease | L27: 4
J28: Multiple Sites | L28: 4
J29: Facilitate Change | L29: 4
J30: Total | L30: =SUM(L14:L29) -> 36

Sheet Material Testing Estimation
B1: Type Of work | C1: Development | D1: New Development
B2: Project Name | C2: Jal Rekha
B3: Remark | C3: Material Testing - Cycle 5 (Jun-Sep 2026)
D5: Volume/Count of elements | H5: Guidelines
A6: Module + sub Module | B6: Functionality ( Sub Module) | C6: Elements (Refer Guidelines and Put here for reference) | D6: Low Complexity | E6: Medium compexity | F6: High Complexity | G6: Size | H6: Low Complexity | I6: Medium compexity | J6: High Complexity
D7: 1 | E7: 3 | F7: 5
A8: Material Testing - Re-Inspection Loop | B8: 2nd-loop re-inspection and optional image on 2nd RFI loop (Jul-Aug; the AUG-25 production deployment is covered by these stories) | C8: US-MAT-C5-001 - Material Testing - Re-Inspection Loop (2nd Loop after GM Rejection) [M] US-MAT-C5-002 - Material Testing - Optional Image Upload on Second RFI Loop [L] Status: 1 In Progress, 1 Open | D8: 1 | E8: 1 | F8: 0 | G8: =D8*$D$7+E8*$E$7+F8*$F$7 -> 4
A9: Material Testing - GM/Contractor DB & API | B9: Database functions and API enhancements for re-inspection (Jul) | C9: US-MAT-C5-003 - Material Testing - GM/Contractor Login Database & API Enhancements [H] Status: 1 In Progress | D9: 0 | E9: 0 | F9: 1 | G9: =D9*$D$7+E9*$E$7+F9*$F$7 -> 5
A10: Material Testing - Re-Inspection Id Flag | B10: Separate flag status for Material Reinspection Id (Sep) | C10: US-SEP-22 - Material Testing - Material Reinspection Id — separate flag status [L] Status: 1 In Progress | D10: 1 | E10: 0 | F10: 0 | G10: =D10*$D$7+E10*$E$7+F10*$F$7 -> 1
A11: TOTAL MATERIAL TESTING ESTIMATION (CYCLE 5) | G11: =SUM(G8:G10) -> 10
J12: Value added factors
B13: Total Count | G13: =G11 -> 10 | J13: Factor | L13: Rating
J14: Data Communications | L14: 0
B15: Productivity | C15: ='Baseline Productivity '!$C$4 -> 0.19 | J15: Distributed Data Processing | L15: 0
B16: Size | C16: =G11 -> 10 | D16: Point
B17: Effort | C17: =C16/C15 -> 52.631579 | D17: Man hours | J17: Performance | L17: 0
B18: VAF | C18: =0.65+0.01*$L$30 -> 1.01 | J18: Heavily used Configuration | L18: 3
B19: Risk contingency | C19: 0.05 | J19: Transaction Rate | L19: 4
B20: Project Management | C20: 0.1
B21: Total Planned effort | C21: =C17*C18*(1+C19+C20) -> 61.131579 | D21: Man hours | J21: Online Data Entry | L21: 3
J22: End-User Efficiency | L22: 2
B23: Permissible Range(Man hours) | C23: =C21*1.05 -> 64.188158 | D23: =C21*0.95 -> 58.075 | J23: Online Update | L23: 1
J24: Complex Processing | L24: 3
J25: Reusability | L25: 4
J26: Installation Ease | L26: 4
J27: Operational Ease | L27: 4
J28: Multiple Sites | L28: 4
J29: Facilitate Change | L29: 4
J30: Total | L30: =SUM(L14:L29) -> 36

Sheet Nirmal Estimation
B1: Type Of work | C1: Development | D1: New Development
B2: Project Name | C2: Jal Rekha
B3: Remark | C3: Nirmal Module - Cycle 5 (Jun-Sep 2026)
D5: Volume/Count of elements | H5: Guidelines
A6: Module + sub Module | B6: Functionality ( Sub Module) | C6: Elements (Refer Guidelines and Put here for reference) | D6: Low Complexity | E6: Medium compexity | F6: High Complexity | G6: Size | H6: Low Complexity | I6: Medium compexity | J6: High Complexity
D7: 1 | E7: 3 | F7: 5
A8: Nirmal - Reports & Bug Fixes | B8: Beneficiary report fix, contractor counting bug, FE mobile reports, test scenarios/cases (Jun) | C8: US-NRM-C5-001 - Nirmal - Beneficiary Report Issue Fix [M] US-NRM-C5-002 - Nirmal - Contractor Login Report Counting Bug Fix [L] US-NRM-C5-003 - Nirmal - FE Mobile Reports Validation & Bug Fixes [M] US-NRM-C5-004 - Nirmal - Test Scenario and Test Case Creation [L] Status: 4 Done | D8: 2 | E8: 2 | F8: 0 | G8: =D8*$D$7+E8*$E$7+F8*$F$7 -> 8
A9: Nirmal / SVS PHE - Water Testing | B9: SVS PHE status labelling and approval lock; water-testing entry form with pass/fail logic (Aug) | C9: US-AUG-23 - Nirmal / SVS PHE - Nirmal/SVS PHE integration logic and status labelling [M] US-AUG-24 - Nirmal / SVS PHE - Nirmal/SVS PHE water-testing entry form [H] Status: 2 In Progress | D9: 0 | E9: 1 | F9: 1 | G9: =D9*$D$7+E9*$E$7+F9*$F$7 -> 8
A10: TOTAL NIRMAL ESTIMATION (CYCLE 5) | G10: =SUM(G8:G9) -> 16
J11: Value added factors
B12: Total Count | G12: =G10 -> 16 | J12: Factor | L12: Rating
J13: Data Communications | L13: 0
B14: Productivity | C14: ='Baseline Productivity '!$C$4 -> 0.19 | J14: Distributed Data Processing | L14: 0
B15: Size | C15: =G10 -> 16 | D15: Point
B16: Effort | C16: =C15/C14 -> 84.210526 | D16: Man hours | J16: Performance | L16: 0
B17: VAF | C17: =0.65+0.01*$L$29 -> 1.01 | J17: Heavily used Configuration | L17: 3
B18: Risk contingency | C18: 0.05 | J18: Transaction Rate | L18: 4
B19: Project Management | C19: 0.1
B20: Total Planned effort | C20: =C16*C17*(1+C18+C19) -> 97.810526 | D20: Man hours | J20: Online Data Entry | L20: 3
J21: End-User Efficiency | L21: 2
B22: Permissible Range(Man hours) | C22: =C20*1.05 -> 102.70105 | D22: =C20*0.95 -> 92.92 | J22: Online Update | L22: 1
J23: Complex Processing | L23: 3
J24: Reusability | L24: 4
J25: Installation Ease | L25: 4
J26: Operational Ease | L26: 4
J27: Multiple Sites | L27: 4
J28: Facilitate Change | L28: 4
J29: Total | L29: =SUM(L13:L28) -> 36

Sheet SVS Estimation
B1: Type Of work | C1: Development | D1: New Development
B2: Project Name | C2: Jal Rekha
B3: Remark | C3: SVS Water Supply Monitoring - Cycle 5 (Jun-Sep 2026)
D5: Volume/Count of elements | H5: Guidelines
A6: Module + sub Module | B6: Functionality ( Sub Module) | C6: Elements (Refer Guidelines and Put here for reference) | D6: Low Complexity | E6: Medium compexity | F6: High Complexity | G6: Size | H6: Low Complexity | I6: Medium compexity | J6: High Complexity
D7: 1 | E7: 3 | F7: 5
A8: SVS - Daily Water Supply Entry | B8: Bilingual conversion, login-scoped District/Block/GP, additional No-Supply reason, JJM ID removal (Jun) | C8: US-SVS-C5-001 - SVS – Bilingual Conversion (Hindi/English) for Water Supply Entry Page [M] US-SVS-C5-002 - SVS – Login-Specific District, Block, GP Auto-Selection [L] US-SVS-C5-003 - SVS – Additional Reason for NO Supply & Spelling Correction [L] US-SVS-C5-004 - SVS – Remove JJM ID and Village Status Fields [L] Status: 4 Done | D8: 3 | E8: 1 | F8: 0 | G8: =D8*$D$7+E8*$E$7+F8*$F$7 -> 6
A9: SVS - Dashboard V2 & Drill-down | B9: KPI cards with colour coding; Gram Sachiv and CEO/CO Block drill-down (Aug) | C9: US-AUG-19 - SVS Water Supply Dashboard - SVS Water Supply Status Dashboard V2 — KPI cards and colour coding [H] US-AUG-20 - SVS Water Supply Dashboard - SVS dashboard drill-down — Gram Sachiv and CEO/CO Block [H] Status: 2 In Progress | D9: 0 | E9: 0 | F9: 2 | G9: =D9*$D$7+E9*$E$7+F9*$F$7 -> 10
A10: SVS / MVS - Master | B10: SVS master wireframe and MVS Master for 600+ schemes (Aug) | C10: US-AUG-21 - SVS / MVS Master - SVS master wireframe and MVS Master (600+ entries) [M] Status: 1 In Progress | D10: 0 | E10: 1 | F10: 0 | G10: =D10*$D$7+E10*$E$7+F10*$F$7 -> 3
A11: SVS Nirmal - FTK Kit | B11: FTK kit report and SVS Nirmal wireframe (Sep) | C11: US-SEP-28 - SVS Nirmal - FTK kit report and SVS Nirmal wireframe [L] Status: 1 Done | D11: 1 | E11: 0 | F11: 0 | G11: =D11*$D$7+E11*$E$7+F11*$F$7 -> 1
A12: TOTAL SVS ESTIMATION (CYCLE 5) | G12: =SUM(G8:G11) -> 20
J13: Value added factors
B14: Total Count | G14: =G12 -> 20 | J14: Factor | L14: Rating
J15: Data Communications | L15: 0
B16: Productivity | C16: ='Baseline Productivity '!$C$4 -> 0.19 | J16: Distributed Data Processing | L16: 0
B17: Size | C17: =G12 -> 20 | D17: Point
B18: Effort | C18: =C17/C16 -> 105.26316 | D18: Man hours | J18: Performance | L18: 0
B19: VAF | C19: =0.65+0.01*$L$31 -> 1.01 | J19: Heavily used Configuration | L19: 3
B20: Risk contingency | C20: 0.05 | J20: Transaction Rate | L20: 4
B21: Project Management | C21: 0.1
B22: Total Planned effort | C22: =C18*C19*(1+C20+C21) -> 122.26316 | D22: Man hours | J22: Online Data Entry | L22: 3
J23: End-User Efficiency | L23: 2
B24: Permissible Range(Man hours) | C24: =C22*1.05 -> 128.37632 | D24: =C22*0.95 -> 116.15 | J24: Online Update | L24: 1
J25: Complex Processing | L25: 3
J26: Reusability | L26: 4
J27: Installation Ease | L27: 4
J28: Operational Ease | L28: 4
J29: Multiple Sites | L29: 4
J30: Facilitate Change | L30: 4
J31: Total | L31: =SUM(L15:L30) -> 36

Sheet SVS Anusharavan GP Estimation
B1: Type Of work | C1: Development | D1: New Development
B2: Project Name | C2: Jal Rekha
B3: Remark | C3: SVS Anusharavan GP Module - Cycle 5 (Aug-Sep 2026)
D5: Volume/Count of elements | H5: Guidelines
A6: Module + sub Module | B6: Functionality ( Sub Module) | C6: Elements (Refer Guidelines and Put here for reference) | D6: Low Complexity | E6: Medium compexity | F6: High Complexity | G6: Size | H6: Low Complexity | I6: Medium compexity | J6: High Complexity
D7: 1 | E7: 3 | F7: 5
A8: SVS Anusharavan GP - Master & Wireframe | B8: GP Master, Anusharavan GP wireframe, user management; funds-source and work-type masters (Sep) | C8: US-SEP-29 - SVS Anusharavan GP - GP Master and Anusharavan GP wireframe and user management [M] US-SEP-34 - GP Master Data - Gram Panchayat Funds-Source and Nirman Karya work-type masters [M] Status: 1 Done, 1 Open | D8: 0 | E8: 2 | F8: 0 | G8: =D8*$D$7+E8*$E$7+F8*$F$7 -> 6
A9: SVS Anusharavan GP - Mobile & RFI Workflow | B9: Simplified RFI, GP mobile screen for FE, GP RFI raise and Sub-Engineer review (Aug-Sep) | C9: US-AUG-35 - RFI / Anusharavan (SVS-GP) - Simplified RFI system and GP–FE review workflow [H] US-SEP-30 - SVS Anusharavan GP - GP Anusharavan Mobile Screen for FE [M] US-SEP-31 - Anusharavan SVS — RFI - Gram Panchayat RFI raise and Sub-Engineer review workflow [H] Status: 1 Not Started, 1 In Progress, 1 Open | D9: 0 | E9: 1 | F9: 2 | G9: =D9*$D$7+E9*$E$7+F9*$F$7 -> 13
A10: SVS Anusharavan GP - SIPRI Integration | B10: SIPRI/NREGA/Yuktdhara integration; AE block-wise login and Panchayat ID whitelisting (Sep) | C10: US-SEP-32 - Anusharavan SVS — SIPRI Integration - SIPRI / NREGA / Yuktdhara integration for GP works planning [H] US-SEP-33 - Anusharavan SVS — SIPRI Integration - SIPRI AE block-wise login and Panchayat ID whitelisting [M] Status: 2 Open | D10: 0 | E10: 1 | F10: 1 | G10: =D10*$D$7+E10*$E$7+F10*$F$7 -> 8
A11: TOTAL SVS ANUSHARAVAN GP ESTIMATION (CYCLE 5) | G11: =SUM(G8:G10) -> 27
J12: Value added factors
B13: Total Count | G13: =G11 -> 27 | J13: Factor | L13: Rating
J14: Data Communications | L14: 0
B15: Productivity | C15: ='Baseline Productivity '!$C$4 -> 0.19 | J15: Distributed Data Processing | L15: 0
B16: Size | C16: =G11 -> 27 | D16: Point
B17: Effort | C17: =C16/C15 -> 142.10526 | D17: Man hours | J17: Performance | L17: 0
B18: VAF | C18: =0.65+0.01*$L$30 -> 1.01 | J18: Heavily used Configuration | L18: 3
B19: Risk contingency | C19: 0.05 | J19: Transaction Rate | L19: 4
B20: Project Management | C20: 0.1
B21: Total Planned effort | C21: =C17*C18*(1+C19+C20) -> 165.05526 | D21: Man hours | J21: Online Data Entry | L21: 3
J22: End-User Efficiency | L22: 2
B23: Permissible Range(Man hours) | C23: =C21*1.05 -> 173.30803 | D23: =C21*0.95 -> 156.8025 | J23: Online Update | L23: 1
J24: Complex Processing | L24: 3
J25: Reusability | L25: 4
J26: Installation Ease | L26: 4
J27: Operational Ease | L27: 4
J28: Multiple Sites | L28: 4
J29: Facilitate Change | L29: 4
J30: Total | L30: =SUM(L14:L29) -> 36

Sheet Anusharavan Estimation
B1: Type Of work | C1: Development | D1: New Development
B2: Project Name | C2: Jal Rekha
B3: Remark | C3: Anusharavan Module - Cycle 5 (Jun-Sep 2026)
D5: Volume/Count of elements | H5: Guidelines
A6: Module + sub Module | B6: Functionality ( Sub Module) | C6: Elements (Refer Guidelines and Put here for reference) | D6: Low Complexity | E6: Medium compexity | F6: High Complexity | G6: Size | H6: Low Complexity | I6: Medium compexity | J6: High Complexity
D7: 1 | E7: 3 | F7: 5
A8: Anusharavan - RFI Reports & Search | B8: Multi-date in report, OHT search during RFI, optional GPS/village for Intake/WTP/MBR/RWPM (Jun) | C8: US-ANS-C5-001 - Anusharavan – Multi-Date in Report: FE RFI Submission Date & Block Name [M] US-ANS-C5-002 - Anusharavan – OHT Search Option During RFI [L] US-ANS-C5-003 - Anusharavan – Remove Mandatory GPS/Village for Intake, WTP, MBR, RWPM, CWPM [L] Status: 3 Done | D8: 2 | E8: 1 | F8: 0 | G8: =D8*$D$7+E8*$E$7+F8*$F$7 -> 5
A9: Anusharavan - Survey Fix | B9: Fix multiple survey submission by SQC/TL (Sep) | C9: US-SEP-24 - Anusharavan - Fix: multiple survey submission by SQC/TL [L] Status: 1 In Progress | D9: 1 | E9: 0 | F9: 0 | G9: =D9*$D$7+E9*$E$7+F9*$F$7 -> 1
A10: TOTAL ANUSHARAVAN ESTIMATION (CYCLE 5) | G10: =SUM(G8:G9) -> 6
J11: Value added factors
B12: Total Count | G12: =G10 -> 6 | J12: Factor | L12: Rating
J13: Data Communications | L13: 0
B14: Productivity | C14: ='Baseline Productivity '!$C$4 -> 0.19 | J14: Distributed Data Processing | L14: 0
B15: Size | C15: =G10 -> 6 | D15: Point
B16: Effort | C16: =C15/C14 -> 31.578947 | D16: Man hours | J16: Performance | L16: 0
B17: VAF | C17: =0.65+0.01*$L$29 -> 1.01 | J17: Heavily used Configuration | L17: 3
B18: Risk contingency | C18: 0.05 | J18: Transaction Rate | L18: 4
B19: Project Management | C19: 0.1
B20: Total Planned effort | C20: =C16*C17*(1+C18+C19) -> 36.678947 | D20: Man hours | J20: Online Data Entry | L20: 3
J21: End-User Efficiency | L21: 2
B22: Permissible Range(Man hours) | C22: =C20*1.05 -> 38.512895 | D22: =C20*0.95 -> 34.845 | J22: Online Update | L22: 1
J23: Complex Processing | L23: 3
J24: Reusability | L24: 4
J25: Installation Ease | L25: 4
J26: Operational Ease | L26: 4
J27: Multiple Sites | L27: 4
J28: Facilitate Change | L28: 4
J29: Total | L29: =SUM(L13:L28) -> 36

Sheet Asset Mapping Estimation
B1: Type Of work | C1: Development | D1: New Development
B2: Project Name | C2: Jal Rekha
B3: Remark | C3: Asset Mapping Module - Cycle 5 (Jun-Sep 2026)
D5: Volume/Count of elements | H5: Guidelines
A6: Module + sub Module | B6: Functionality ( Sub Module) | C6: Elements (Refer Guidelines and Put here for reference) | D6: Low Complexity | E6: Medium compexity | F6: High Complexity | G6: Size | H6: Low Complexity | I6: Medium compexity | J6: High Complexity
D7: 1 | E7: 3 | F7: 5
A8: Asset Mapping - SQC/TPIA/Contractor | B8: SQC/TPIA/Contractor asset data and report on web; API integration and frontend fixes (Jun) | C8: US-AST-C5-001 - Asset Mapping - SQC/TPIA Contractor Data & Report on Web [M] US-AST-C5-002 - Asset Mapping - API Integration & Frontend Bug Fixes [M] Status: 2 Done | D8: 0 | E8: 2 | F8: 0 | G8: =D8*$D$7+E8*$E$7+F8*$F$7 -> 6
A9: Asset Mapping - Report Cleanup | B9: OHT Id cleanup in reports (Sep) | C9: US-SEP-19 - Dhara / Asset Mapping - Asset Mapping — OHT Id cleanup in reports [L] Status: 1 Open | D9: 1 | E9: 0 | F9: 0 | G9: =D9*$D$7+E9*$E$7+F9*$F$7 -> 1
A10: TOTAL ASSET MAPPING ESTIMATION (CYCLE 5) | G10: =SUM(G8:G9) -> 7
